Workbook
Name MPlayerNo: Methuselahs!$A$7:$A$206

Sheet Instructions
A1: The Archon (v1.5k)
A2: The official tournament tracking system for "Vampire: The Eternal Struggle" | E2: originally from the V:TES Rulemonger Website (http://www.geocities.com/vtesrep), updated with genetic results: http://www.vekn.net/forum/generic-v-tes-discussion/77200-optimal-seatings-the-return-of-the-mutant?start=0
A4: The Archon was written by Stephen "The Evil One" Buonocore, and maintained by L. Scott Johnson.
A5: The Archon is currently maintained by Vincent Ripoll.
A6: With updates by Robert Goudie and Pascal Bertrand.
A8: The latest version of The Archon is available for download at
A9: http://www.vekn.net/downloads
A11: What's New:
B12: V1.5k | C12: Added Grand Prix level
B13: V1.5j | C13: Improved seating charts for 3R+F 9-57 players (thanks to Lionel Panhaleux).
B14: V1.5i | C14: Fixed error in 3R+F for 19 players (players 13 and 14 were inverted during R1) and 2R+F for 44 players (the seating introduced in v1.5h was worse).
B15: V1.5h | C15: Fixed unoptimal seatings for 3R+F for 49 players to 200 players, and added seatings for 201-220 players. Reverted to optimal seating for 17 players. Fixed unoptimal seatings for 2R+F for 21 players to 50 players, and added seatings for 51-1210 players.
B16: V1.5g | C16: Fixed unoptimal seatings for 2R+F and 3R+F
B17: V1.5f | C17: Fixed unoptimal seatings introduced in V1.5e due to a flaw in the validation of the new results and some mistakes when reporting the results.
B18: V1.5e | C18: The Archon is now available in xslx (Microsoft Excel) and ods (Libroffice) formats. The old xls format must not be used anymore. Updated the urls. Fixed reversed predator-prey relationships that are authorized by rules 1 and 6, but that should be more important than rule 8 for instance. This applies to the following 3R+F seatings: 17, 19, 20, 21, 23, 27, 31 players
B19: V1.5d | C19: Now using the optimised seatings computed by Vincent (calculations ongoing, current date: 28/06/2015)
B20: V1.5c | C20: Increased the max number of players for 2R+F events, fixed a bug in the 3rd round page in 2R+F events. (Vincent Ripoll). Upgraded the seating for 21-25 players in 2R+F events (Pascal Bertrand) (currently working on the remaining)
B21: V1.5b | C21: Fixed a bug in the chart that made Optimal Seating charts fail to update in OpenOffice.org or LibreOffice. (Jussi Hattara)
B22: V1.5a | C22: Tournament Info sheet made more similar to the Event Registration page of the vekn.net website, where the Event should be registered. Added coefficient for National Qualifiers (0).
B23: V1.4c | C23: Fixed minor issue with seating for 19 players (13 and 14 got switched), and changed the National Event coeff to 0.25 (it was 0.5) (Thanks to Pascal)
... B35: v1.1 | C35: Use Game Wins per the January 2002 update of the V:EKN rules. Enhanced support of optimal seating charts. Corrected 18-player chart.
A38: Instructions for use:
A40: General Instructions
B41: 1 | C41: Welcome to The Archon, the official tournament tracking system for "Vampire: The Eternal Struggle" ("V:TES"). When your tournament is completed and all information within The Archon has been entered, you should immediately send this entire completed workbook to the V:EKN (the "Vampire: Elder Kindred Network"), which is the Official International Players' Organization for V:TES. By sending this to the V:EKN, your players' official V:TES ratings will be updated. See the "Post-Tournament Procedures" below for submitting the results.
C43: Please visit the VEKN web site for all the official information about V:TES and the V:EKN:
C44: http://www.vekn.net
C46: For information on how to run an officially sanctioned V:TES tournament, including the "Request for Sanctioning", "Request for Prize Support", and all other relevant information, please visit the V:TES website, and go to this page:
C47: http://www.vekn.net/how-to-run-a-v-tes-tournament
C49: Officially sanctioned V:TES Tournaments are run according to the V:EKN Tournament Rules. Also, all current V:TES Rules, Rulings, Errata, and Clarifications must be followed. These can be found on the VEKN website on these pages:
C50: http://www.vekn.net/tournament-rules
C51: http://www.vekn.net/rulebook
C52: http://www.vekn.net/general-rulings
C53: http://www.vekn.net/card-rulings
B55: =B41+1 -> 2 | C55: The archon is available in XSLX and ODS format. If you use Microsoft Excel, use the XSLX format; otherwise use the ODS format. Do not save it under another format (eg. If you use the XSLX format, save it only in that format).
B57: =B55+1 -> 3 | C57: Helpful instructions have been embedded in some cells of this spreadsheet, so that you do not have to refer back to this page often. Please point the cursor to the "little red triangle" in the upper-right corner of some cells for help. To see how this works, point to the triangle to the left of this paragraph.
B59: =B57+1 -> 4 | C59: You should save this spreadsheet file under a new name (like the name of your tournament) before beginning to use it. By doing so, you can use this blank spreadsheet again for future tournaments. Use the Menu Bar selection, FILE, then select SAVE AS and enter a new name. After doing this, you can continue to use this spreadsheet to track your V:TES tournament.
B61: =B59+1 -> 5 | C61: This system implements the V:EKN Sanctioned Tournament Rules, and therefore makes certain assumptions (e.g. all tables will have 4 or (optimally) 5 players). Use V:EKN Tournament Rules when utilizing this system.
A64: Setting up and Tracking Your Tournament
B65: =B61+1 -> 6 | C65: Enter the tournament information into the "Tournament Info" sheet.
B66: - | C66: This is freeform text, but is used in other sheets, so please be accurate. The VEKN numbers of the organizer and judges are used for qualification.
...

Sheet Tournament Info
A1: =IF(ISBLANK(B3),"Vampire: The Eternal Struggle Tournament",B3) -> German Nationals 2024
A3: Event Name: | B3: German Nationals 2024
A4: Event Date (DD-MON-YY): | B4: 45542
A5: Date Report due at V:EKN: | B5: =IF(B4="","",B4+8) -> 45550
A6: Organizer: | B6: Rudolf Scholz | C6: 5810002
A7: City: | B7: Darmstadt
A8: Format (Constructed/Limited): | B8: Constructed | D8: Constructed | E8: Limited
A9: Level (Normal/Qualifier/Championship/Nationals) | B9: National Championship | D9: Standard Constructed | E9: National Qualifier | F9: National Championship | G9: Continental Qualifier | H9: Continental Championship | I9: Grand Prix | J9: Storyline | K9: Limited | L9: Demo | M9: Unsanctioned Tournament
A10: Number of Players: | B10: =Methuselahs!$A$4 -> 32 | D10: 0 | E10: 0 | F10: 0.25 | G10: 0.25 | H10: 1 | I10: 0 | J10: 0 | K10: 0 | L10: 0 | M10: 0
A11: Number of Rounds (including final): | B11: 4 | D11: 3 | E11: 4
A12: Number of Event Matches: | B12: =MAX('Round 1'!D7:D206)+MAX('Round 2'!D7:D206)+MAX('Round 3'!D7:D206)+1 -> 22
A13: Number of New Members:
A14: Number of Warnings Issued:
A15: Number of Disqualifications:
A16: Multi-Judge System Used? | B16: No
A17: Head Judge: | B17: Ralf Weppner | C17: 1005687
A18: Assistant Judges: | C18: =IF(ISBLANK(B18),"","VEKN id")
C19: =IF(ISBLANK(B19),"","VEKN id")
C20: =IF(ISBLANK(B20),"","VEKN id")
C21: =IF(ISBLANK(B21),"","VEKN id")
C22: =IF(ISBLANK(B22),"","VEKN id")
C23: =IF(ISBLANK(B23),"","VEKN id")
C24: =IF(ISBLANK(B24),"","VEKN id")
C25: =IF(ISBLANK(B25),"","VEKN id")
C26: =IF(ISBLANK(B26),"","VEKN id")

Sheet Methuselahs
A1: =IF(ISBLANK('Tournament Info'!B3),"Vampire: The Eternal Struggle Tournament",'Tournament Info'!B3) -> German Nationals 2024 | Z1: =HLOOKUP('Tournament Info'!$B$9,'Tournament Info'!$D$9:$M$10,2,0) -> 0.25 | AA1: 90
P2: champ | Q2: nat | R2: norm | S2: qual | T2: reg | Y2: Coef: | Z2: =LOG(MAX($A$4*$A$4,1),15)-1+$Z$1 -> 1.8095802 | AA2: 30
A3: Player Information | O3: 0 | P3: 1 | Q3: 0.25 | R3: 0 | S3: 0.25 | T3: 0 | AA3: 30
A4: =COUNT($A$7:$A$206) -> 32 | B4: players entered | AA4: 30
A5: Player | B5: Player | C5: Player | D5: Player | E5: V:EKN | G5: DQ | H5: Results - Rnds 1, 2, 3 | L5: Status | M5: Coin | N5: Adjusted | O5: VP | P5: TP | Q5: Coin | R5: Real | S5: Flag | T5: Player | U5: Final | V5: CurRank | W5: P# ties | X5: Distinct | Y5: Player | Z5: Final | AA5: 30 | AB5: Rating
A6: Num. | B6: First Name | C6: Last Name | D6: City | E6: Num. | F6: # rnds | G6: Flag | H6: GWs | I6: VPs | J6: TPs | K6: Rank | L6: for Final | M6: Ranking | N6: Rank | O6: =IF(ISERR(MAX($I$7:$I$206)),1,MAX($I$7:$I$206)+1) -> 11 | P6: =IF(ISERR(MAX($J$7:$J$206)),1,MAX($J$7:$J$206)+1) -> 181 | Q6: =IF(ISERR(MAX($M$7:$M$206)),1,MAX($M$7:$M$206)+1) -> 1 | R6: Rank | S6: Ties | T6: Num | U6: Rank | V6: =IF(ISERR(MAX($V$7:$V$206)),1,MAX($V$7:$V$206)+1) -> 33 | W6: =MAX(MPlayerNo)+1 -> 33 | X6: Rank | Y6: Num | Z6: Rank | AA6: Bonus | AB6: Points
A7: 32 | E7: 2616620129 | F7: =IF(ISBLANK($A7),"",SUM(IF(ISNA(IF(VLOOKUP($A7,'Round 1'!$A$7:$J$206,COLUMN('Round 1'!$H$7),0),1,NA())),0,1),IF(ISNA(IF(VLOOKUP($A7,'Round 2'!$A$7:$J$206,COLUMN('Round 1'!$H$7),0),1,NA())),0,1),IF(ISNA(IF(VLOOKUP($A7,'Round 3'!$A$7:$J$206,COLUMN('Round 1'!$H$7),0),1,NA())),0,1),IF(ISNA(IF(VLOOKUP($A7,'Final Round'!$A$14:$K$18,1,0),1,NA())),0,1))) -> 4 | H7: =IF(ISBLANK($A7),"",IF(ISERROR(VLOOKUP($A7,'Round 1'!$A$7:$I$206,COLUMN('Round 1'!$G$7),0)),0,VLOOKUP($A7,'Round 1'!$A$7:$I$206,COLUMN('Round 1'!$G$7),0))+IF(ISERROR(VLOOKUP($A7,'Round 2'!$A$7:$I$206,COLUMN('Round 2'!$G$7),0)),0,VLOOKUP($A7,'Round 2'!$A$7:$I$206,COLUMN('Round 2'!$G$7),0))+IF(ISERROR(VLOOKUP($A7,'Round 3'!$A$7:$I$206,COLUMN('Round 3'!$G$7),0)),0,VLOOKUP($A7,'Round 3'!$A$7:$I$206,COLUMN('Round 3'!$G$7),0))) -> 2 | I7: =IF(ISBLANK($A7),"",IF(ISERROR(VLOOKUP($A7,'Round 1'!$A$7:$I$206,COLUMN('Round 1'!$F$7),0)),0,VLOOKUP($A7,'Round 1'!$A$7:$I$206,COLUMN('Round 1'!$F$7),0))+IF(ISERROR(VLOOKUP($A7,'Round 2'!$A$7:$I$206,COLUMN('Round 2'!$F$7),0)),0,VLOOKUP($A7,'Round 2'!$A$7:$I$206,COLUMN('Round 2'!$F$7),0))+IF(ISERROR(VLOOKUP($A7,'Round 3'!$A$7:$I$206,COLUMN('Round 3'!$F$7),0)),0,VLOOKUP($A7,'Round 3'!$A$7:$I$206,COLUMN('Round 3'!$F$7),0))) -> 7 | J7: =IF(ISBLANK($A7),"",IF(ISERROR(VLOOKUP($A7,'Round 1'!$A$7:$I$206,COLUMN('Round 1'!$H$7),0)),0,VLOOKUP($A7,'Round 1'!$A$7:$I$206,COLUMN('Round 1'!$H$7),0))+IF(ISERROR(VLOOKUP($A7,'Round 2'!$A$7:$I$206,COLUMN('Round 2'!$H$7),0)),0,VLOOKUP($A7,'Round 2'!$A$7:$I$206,COLUMN('Round 2'!$H$7),0))+IF(ISERROR(VLOOKUP($A7,'Round 3'!$A$7:$I$206,COLUMN('Round 3'!$H$7),0)),0,VLOOKUP($A7,'Round 3'!$A$7:$I$206,COLUMN('Round 3'!$H$7),0))) -> 162 | K7: =IF(ISBLANK(A7),"",RANK(P7,$P$7:$P$206)) -> 4 | L7: =IF(ISBLANK($G7),IF($K7>5,"",IF(AND(ISNA(MATCH(K7+1,$K$7:$K$206,0)),$K7<$A$4),"TIE","")),"DQ") | N7: =IF(ISBLANK($G7),$R7,"DQ") -> 4 | O7: =IF(ISBLANK(A7),"",$H7*$O$6+$I7) -> 29 | P7: =IF(ISBLANK(A7),"",$O7*10*$P$6+$J7) -> 52652 | Q7: =IF(ISBLANK($G7),IF(ISBLANK($A7),-10,$P7*$Q$6+IF($M7>0,$Q$6-1-$M7,0)),-1) -> 52652 | R7: =IF(ISBLANK($A7),"",RANK($Q7,$Q$7:$Q$206)) -> 4 | S7: =IF(ISNA(MATCH($R7+1,$R$7:$R$206,0)),IF($R7=MAX($A$7:$A$206),$R7,-1),$R7) -> 4 | T7: =$A7 -> 32 | U7: =IF(N('Final Round'!$J$14)>0,IF(ISBLANK($A7),"",IF($N7>5,$N7,VLOOKUP($A7,'Final Round'!$A$14:$K$18,COLUMN('Final Round'!$J$1),0))),"") -> 2 | V7: =IF(ISNUMBER($U7),$U7,$R7) -> 2 | W7: =IF(ISBLANK($A7),"",($V$6-$V7)*$W$6+$W$6-$A7) -> 1024 | X7: =IF(ISBLANK($A7),"",RANK($W7,$W$7:$W$206)) -> 5 | Y7: =$A7 -> 32 | Z7: =IF($U7="",$N7,$U7) -> 2 | AA7: =IF($U7<6,INDEX($AA$1:$AA$5,$Z7)*$Z$2,0) -> 54.287407 | AB7: =IF(ISBLANK($A7),"",5+4*(I7+IF(AA7=0,0,VLOOKUP($A7,'Final Round'!$A$14:$K$18,COLUMN('Final Round'!$G$1),0)))+8*(H7+IF(AA7=0,0,IF(VLOOKUP($A7,'Final Round'!$A$14:$K$18,COLUMN('Final Round'!$J$1),0)=1,1,0)))+$AA7) -> 111.28741
A8: 20 | F8: =IF(ISBLANK($A8),"",SUM(IF(ISNA(IF(VLOOKUP($A8,'Round 1'!$A$7:$J$206,COLUMN('Round 1'!$H$7),0),1,NA())),0,1),IF(ISNA(IF(VLOOKUP($A8,'Round 2'!$A$7:$J$206,COLUMN('Round 1'!$H$7),0),1,NA())),0,1),IF(ISNA(IF(VLOOKUP($A8,'Round 3'!$A$7:$J$206,COLUMN('Round 1'!$H$7),0),1,NA())),0,1),IF(ISNA(IF(VLOOKUP($A8,'Final Round'!$A$14:$K$18,1,0),1,NA())),0,1))) -> 3 | H8: =IF(ISBLANK($A8),"",IF(ISERROR(VLOOKUP($A8,'Round 1'!$A$7:$I$206,COLUMN('Round 1'!$G$7),0)),0,VLOOKUP($A8,'Round 1'!$A$7:$I$206,COLUMN('Round 1'!$G$7),0))+IF(ISERROR(VLOOKUP($A8,'Round 2'!$A$7:$I$206,COLUMN('Round 2'!$G$7),0)),0,VLOOKUP($A8,'Round 2'!$A$7:$I$206,COLUMN('Round 2'!$G$7),0))+IF(ISERROR(VLOOKUP($A8,'Round 3'!$A$7:$I$206,COLUMN('Round 3'!$G$7),0)),0,VLOOKUP($A8,'Round 3'!$A$7:$I$206,COLUMN('Round 3'!$G$7),0))) -> 0 | I8: =IF(ISBLANK($A8),"",IF(ISERROR(VLOOKUP($A8,'Round 1'!$A$7:$I$206,COLUMN('Round 1'!$F$7),0)),0,VLOOKUP($A8,'Round 1'!$A$7:$I$206,COLUMN('Round 1'!$F$7),0))+IF(ISERROR(VLOOKUP($A8,'Round 2'!$A$7:$I$206,COLUMN('Round 2'!$F$7),0)),0,VLOOKUP($A8,'Round 2'!$A$7:$I$206,COLUMN('Round 2'!$F$7),0))+IF(ISERROR(VLOOKUP($A8,'Round 3'!$A$7:$I$206,COLUMN('Round 3'!$F$7),0)),0,VLOOKUP($A8,'Round 3'!$A$7:$I$206,COLUMN('Round 3'!$F$7),0))) -> 3 | J8: =IF(ISBLANK($A8),"",IF(ISERROR(VLOOKUP($A8,'Round 1'!$A$7:$I$206,COLUMN('Round 1'!$H$7),0)),0,VLOOKUP($A8,'Round 1'!$A$7:$I$206,COLUMN('Round 1'!$H$7),0))+IF(ISERROR(VLOOKUP($A8,'Round 2'!$A$7:$I$206,COLUMN('Round 2'!$H$7),0)),0,VLOOKUP($A8,'Round 2'!$A$7:$I$206,COLUMN('Round 2'!$H$7),0))+IF(ISERROR(VLOOKUP($A8,'Round 3'!$A$7:$I$206,COLUMN('Round 3'!$H$7),0)),0,VLOOKUP($A8,'Round 3'!$A$7:$I$206,COLUMN('Round 3'!$H$7),0))) -> 132 | K8: =IF(ISBLANK(A8),"",RANK(P8,$P$7:$P$206)) -> 13 | L8: =IF(ISBLANK($G8),IF($K8>5,"",IF(AND(ISNA(MATCH(K8+1,$K$7:$K$206,0)),$K8<$A$4),"TIE","")),"DQ") | N8: =IF(ISBLANK($G8),$R8,"DQ") -> 13 | O8: =IF(ISBLANK(A8),"",$H8*$O$6+$I8) -> 3 | P8: =IF(ISBLANK(A8),"",$O8*10*$P$6+$J8) -> 5562 | Q8: =IF(ISBLANK($G8),IF(ISBLANK($A8),-10,$P8*$Q$6+IF($M8>0,$Q$6-1-$M8,0)),-1) -> 5562 | R8: =IF(ISBLANK($A8),"",RANK($Q8,$Q$7:$Q$206)) -> 13 | S8: =IF(ISNA(MATCH($R8+1,$R$7:$R$206,0)),IF($R8=MAX($A$7:$A$206),$R8,-1),$R8) -> 13 | T8: =$A8 -> 20 | U8: =IF(N('Final Round'!$J$14)>0,IF(ISBLANK($A8),"",IF($N8>5,$N8,VLOOKUP($A8,'Final Round'!$A$14:$K$18,COLUMN('Final Round'!$J$1),0))),"") -> 13 | V8: =IF(ISNUMBER($U8),$U8,$R8) -> 13 | W8: =IF(ISBLANK($A8),"",($V$6-$V8)*$W$6+$W$6-$A8) -> 673 | X8: =IF(ISBLANK($A8),"",RANK($W8,$W$7:$W$206)) -> 13 | Y8: =$A8 -> 20 | Z8: =IF($U8="",$N8,$U8) -> 13 | AA8: =IF($U8<6,INDEX($AA$1:$AA$5,$Z8)*$Z$2,0) -> 0 | AB8: =IF(ISBLANK($A8),"",5+4*(I8+IF(AA8=0,0,VLOOKUP($A8,'Final Round'!$A$14:$K$18,COLUMN('Final Round'!$G$1),0)))+8*(H8+IF(AA8=0,0,IF(VLOOKUP($A8,'Final Round'!$A$14:$K$18,COLUMN('Final Round'!$J$1),0)=1,1,0)))+$AA8) -> 17
A9: 31 | E9: 4082837118 | F9: =IF(ISBLANK($A9),"",SUM(IF(ISNA(IF(VLOOKUP($A9,'Round 1'!$A$7:$J$206,COLUMN('Round 1'!$H$7),0),1,NA())),0,1),IF(ISNA(IF(VLOOKUP($A9,'Round 2'!$A$7:$J$206,COLUMN('Round 1'!$H$7),0),1,NA())),0,1),IF(ISNA(IF(VLOOKUP($A9,'Round 3'!$A$7:$J$206,COLUMN('Round 1'!$H$7),0),1,NA())),0,1),IF(ISNA(IF(VLOOKUP($A9,'Final Round'!$A$14:$K$18,1,0),1,NA())),0,1))) -> 3 | H9: =IF(ISBLANK($A9),"",IF(ISERROR(VLOOKUP($A9,'Round 1'!$A$7:$I$206,COLUMN('Round 1'!$G$7),0)),0,VLOOKUP($A9,'Round 1'!$A$7:$I$206,COLUMN('Round 1'!$G$7),0))+IF(ISERROR(VLOOKUP($A9,'Round 2'!$A$7:$I$206,COLUMN('Round 2'!$G$7),0)),0,VLOOKUP($A9,'Round 2'!$A$7:$I$206,COLUMN('Round 2'!$G$7),0))+IF(ISERROR(VLOOKUP($A9,'Round 3'!$A$7:$I$206,COLUMN('Round 3'!$G$7),0)),0,VLOOKUP($A9,'Round 3'!$A$7:$I$206,COLUMN('Round 3'!$G$7),0))) -> 1 | I9: =IF(ISBLANK($A9),"",IF(ISERROR(VLOOKUP($A9,'Round 1'!$A$7:$I$206,COLUMN('Round 1'!$F$7),0)),0,VLOOKUP($A9,'Round 1'!$A$7:$I$206,COLUMN('Round 1'!$F$7),0))+IF(ISERROR(VLOOKUP($A9,'Round 2'!$A$7:$I$206,COLUMN('Round 2'!$F$7),0)),0,VLOOKUP($A9,'Round 2'!$A$7:$I$206,COLUMN('Round 2'!$F$7),0))+IF(ISERROR(VLOOKUP($A9,'Round 3'!$A$7:$I$206,COLUMN('Round 3'!$F$7),0)),0,VLOOKUP($A9,'Round 3'!$A$7:$I$206,COLUMN('Round 3'!$F$7),0))) -> 3 | J9: =IF(ISBLANK($A9),"",IF(ISERROR(VLOOKUP($A9,'Round 1'!$A$7:$I$206,COLUMN('Round 1'!$H$7),0)),0,VLOOKUP($A9,'Round 1'!$A$7:$I$206,COLUMN('Round 1'!$H$7),0))+IF(ISERROR(VLOOKUP($A9,'Round 2'!$A$7:$I$206,COLUMN('Round 2'!$H$7),0)),0,VLOOKUP($A9,'Round 2'!$A$7:$I$206,COLUMN('Round 2'!$H$7),0))+IF(ISERROR(VLOOKUP($A9,'Round 3'!$A$7:$I$206,COLUMN('Round 3'!$H$7),0)),0,VLOOKUP($A9,'Round 3'!$A$7:$I$206,COLUMN('Round 3'!$H$7),0))) -> 102 | K9: =IF(ISBLANK(A9),"",RANK(P9,$P$7:$P$206)) -> 12 | L9: =IF(ISBLANK($G9),IF($K9>5,"",IF(AND(ISNA(MATCH(K9+1,$K$7:$K$206,0)),$K9<$A$4),"TIE","")),"DQ") | N9: =IF(ISBLANK($G9),$R9,"DQ") -> 12 | O9: =IF(ISBLANK(A9),"",$H9*$O$6+$I9) -> 14 | P9: =IF(ISBLANK(A9),"",$O9*10*$P$6+$J9) -> 25442 | Q9: =IF(ISBLANK($G9),IF(ISBLANK($A9),-10,$P9*$Q$6+IF($M9>0,$Q$6-1-$M9,0)),-1) -> 25442 | R9: =IF(ISBLANK($A9),"",RANK($Q9,$Q$7:$Q$206)) -> 12 | S9: =IF(ISNA(MATCH($R9+1,$R$7:$R$206,0)),IF($R9=MAX($A$7:$A$206),$R9,-1),$R9) -> 12 | T9: =$A9 -> 31 | U9: =IF(N('Final Round'!$J$14)>0,IF(ISBLANK($A9),"",IF($N9>5,$N9,VLOOKUP($A9,'Final Round'!$A$14:$K$18,COLUMN('Final Round'!$J$1),0))),"") -> 12 | V9: =IF(ISNUMBER($U9),$U9,$R9) -> 12 | W9: =IF(ISBLANK($A9),"",($V$6-$V9)*$W$6+$W$6-$A9) -> 695 | X9: =IF(ISBLANK($A9),"",RANK($W9,$W$7:$W$206)) -> 12 | Y9: =$A9 -> 31 | Z9: =IF($U9="",$N9,$U9) -> 12 | AA9: =IF($U9<6,INDEX($AA$1:$AA$5,$Z9)*$Z$2,0) -> 0 | AB9: =IF(ISBLANK($A9),"",5+4*(I9+IF(AA9=0,0,VLOOKUP($A9,'Final Round'!$A$14:$K$18,COLUMN('Final Round'!$G$1),0)))+8*(H9+IF(AA9=0,0,IF(VLOOKUP($A9,'Final Round'!$A$14:$K$18,COLUMN('Final Round'!$J$1),0)=1,1,0)))+$AA9) -> 25
A10: 12 | E10: 1432209241 | F10: =IF(ISBLANK($A10),"",SUM(IF(ISNA(IF(VLOOKUP($A10,'Round 1'!$A$7:$J$206,COLUMN('Round 1'!$H$7),0),1,NA())),0,1),IF(ISNA(IF(VLOOKUP($A10,'Round 2'!$A$7:$J$206,COLUMN('Round 1'!$H$7),0),1,NA())),0,1),IF(ISNA(IF(VLOOKUP($A10,'Round 3'!$A$7:$J$206,COLUMN('Round 1'!$H$7),0),1,NA())),0,1),IF(ISNA(IF(VLOOKUP($A10,'Final Round'!$A$14:$K$18,1,0),1,NA())),0,1))) -> 3 | H10: =IF(ISBLANK($A10),"",IF(ISERROR(VLOOKUP($A10,'Round 1'!$A$7:$I$206,COLUMN('Round 1'!$G$7),0)),0,VLOOKUP($A10,'Round 1'!$A$7:$I$206,COLUMN('Round 1'!$G$7),0))+IF(ISERROR(VLOOKUP($A10,'Round 2'!$A$7:$I$206,COLUMN('Round 2'!$G$7),0)),0,VLOOKUP($A10,'Round 2'!$A$7:$I$206,COLUMN('Round 2'!$G$7),0))+IF(ISERROR(VLOOKUP($A10,'Round 3'!$A$7:$I$206,COLUMN('Round 3'!$G$7),0)),0,VLOOKUP($A10,'Round 3'!$A$7:$I$206,COLUMN('Round 3'!$G$7),0))) -> 0 | I10: =IF(ISBLANK($A10),"",IF(ISERROR(VLOOKUP($A10,'Round 1'!$A$7:$I$206,COLUMN('Round 1'!$F$7),0)),0,VLOOKUP($A10,'Round 1'!$A$7:$I$206,COLUMN('Round 1'!$F$7),0))+IF(ISERROR(VLOOKUP($A10,'Round 2'!$A$7:$I$206,COLUMN('Round 2'!$F$7),0)),0,VLOOKUP($A10,'Round 2'!$A$7:$I$206,COLUMN('Round 2'!$F$7),0))+IF(ISERROR(VLOOKUP($A10,'Round 3'!$A$7:$I$206,COLUMN('Round 3'!$F$7),0)),0,VLOOKUP($A10,'Round 3'!$A$7:$I$206,COLUMN('Round 3'!$F$7),0))) -> 3 | J10: =IF(ISBLANK($A10),"",IF(ISERROR(VLOOKUP($A10,'Round 1'!$A$7:$I$206,COLUMN('Round 1'!$H$7),0)),0,VLOOKUP($A10,'Round 1'!$A$7:$I$206,COLUMN('Round 1'!$H$7),0))+IF(ISERROR(VLOOKUP($A10,'Round 2'!$A$7:$I$206,COLUMN('Round 2'!$H$7),0)),0,VLOOKUP($A10,'Round 2'!$A$7:$I$206,COLUMN('Round 2'!$H$7),0))+IF(ISERROR(VLOOKUP($A10,'Round 3'!$A$7:$I$206,COLUMN('Round 3'!$H$7),0)),0,VLOOKUP($A10,'Round 3'!$A$7:$I$206,COLUMN('Round 3'!$H$7),0))) -> 114 | K10: =IF(ISBLANK(A10),"",RANK(P10,$P$7:$P$206)) -> 15 | L10: =IF(ISBLANK($G10),IF($K10>5,"",IF(AND(ISNA(MATCH(K10+1,$K$7:$K$206,0)),$K10<$A$4),"TIE","")),"DQ") | N10: =IF(ISBLANK($G10),$R10,"DQ") -> 15 | O10: =IF(ISBLANK(A10),"",$H10*$O$6+$I10) -> 3 | P10: =IF(ISBLANK(A10),"",$O10*10*$P$6+$J10) -> 5544 | Q10: =IF(ISBLANK($G10),IF(ISBLANK($A10),-10,$P10*$Q$6+IF($M10>0,$Q$6-1-$M10,0)),-1) -> 5544 | R10: =IF(ISBLANK($A10),"",RANK($Q10,$Q$7:$Q$206)) -> 15 | S10: =IF(ISNA(MATCH($R10+1,$R$7:$R$206,0)),IF($R10=MAX($A$7:$A$206),$R10,-1),$R10) -> -1 | T10: =$A10 -> 12 | U10: =IF(N('Final Round'!$J$14)>0,IF(ISBLANK($A10),"",IF($N10>5,$N10,VLOOKUP($A10,'Final Round'!$A$14:$K$18,COLUMN('Final Round'!$J$1),0))),"") -> 15 | V10: =IF(ISNUMBER($U10),$U10,$R10) -> 15 | W10: =IF(ISBLANK($A10),"",($V$6-$V10)*$W$6+$W$6-$A10) -> 615 | X10: =IF(ISBLANK($A10),"",RANK($W10,$W$7:$W$206)) -> 15 | Y10: =$A10 -> 12 | Z10: =IF($U10="",$N10,$U10) -> 15 | AA10: =IF($U10<6,INDEX($AA$1:$AA$5,$Z10)*$Z$2,0) -> 0 | AB10: =IF(ISBLANK($A10),"",5+4*(I10+IF(AA10=0,0,VLOOKUP($A10,'Final Round'!$A$14:$K$18,COLUMN('Final Round'!$G$1),0)))+8*(H10+IF(AA10=0,0,IF(VLOOKUP($A10,'Final Round'!$A$14:$K$18,COLUMN('Final Round'!$J$1),0)=1,1,0)))+$AA10) -> 17
A11: 24 | E11: 1120048922 | F11: =IF(ISBLANK($A11),"",SUM(IF(ISNA(IF(VLOOKUP($A11,'Round 1'!$A$7:$J$206,COLUMN('Round 1'!$H$7),0),1,NA())),0,1),IF(ISNA(IF(VLOOKUP($A11,'Round 2'!$A$7:$J$206,COLUMN('Round 1'!$H$7),0),1,NA())),0,1),IF(ISNA(IF(VLOOKUP($A11,'Round 3'!$A$7:$J$206,COLUMN('Round 1'!$H$7),0),1,NA())),0,1),IF(ISNA(IF(VLOOKUP($A11,'Final Round'!$A$14:$K$18,1,0),1,NA())),0,1))) -> 3 | H11: =IF(ISBLANK($A11),"",IF(ISERROR(VLOOKUP($A11,'Round 1'!$A$7:$I$206,COLUMN('Round 1'!$G$7),0)),0,VLOOKUP($A11,'Round 1'!$A$7:$I$206,COLUMN('Round 1'!$G$7),0))+IF(ISERROR(VLOOKUP($A11,'Round 2'!$A$7:$I$206,COLUMN('Round 2'!$G$7),0)),0,VLOOKUP($A11,'Round 2'!$A$7:$I$206,COLUMN('Round 2'!$G$7),0))+IF(ISERROR(VLOOKUP($A11,'Round 3'!$A$7:$I$206,COLUMN('Round 3'!$G$7),0)),0,VLOOKUP($A11,'Round 3'!$A$7:$I$206,COLUMN('Round 3'!$G$7),0))) -> 1 | I11: =IF(ISBLANK($A11),"",IF(ISERROR(VLOOKUP($A11,'Round 1'!$A$7:$I$206,COLUMN('Round 1'!$F$7),0)),0,VLOOKUP($A11,'Round 1'!$A$7:$I$206,COLUMN('Round 1'!$F$7),0))+IF(ISERROR(VLOOKUP($A11,'Round 2'!$A$7:$I$206,COLUMN('Round 2'!$F$7),0)),0,VLOOKUP($A11,'Round 2'!$A$7:$I$206,COLUMN('Round 2'!$F$7),0))+IF(ISERROR(VLOOKUP($A11,'Round 3'!$A$7:$I$206,COLUMN('Round 3'!$F$7),0)),0,VLOOKUP($A11,'Round 3'!$A$7:$I$206,COLUMN('Round 3'!$F$7),0))) -> 4 | J11: =IF(ISBLANK($A11),"",IF(ISERROR(VLOOKUP($A11,'Round 1'!$A$7:$I$206,COLUMN('Round 1'!$H$7),0)),0,VLOOKUP($A11,'Round 1'!$A$7:$I$206,COLUMN('Round 1'!$H$7),0))+IF(ISERROR(VLOOKUP($A11,'Round 2'!$A$7:$I$206,COLUMN('Round 2'!$H$7),0)),0,VLOOKUP($A11,'Round 2'!$A$7:$I$206,COLUMN('Round 2'!$H$7),0))+IF(ISERROR(VLOOKUP($A11,'Round 3'!$A$7:$I$206,COLUMN('Round 3'!$H$7),0)),0,VLOOKUP($A11,'Round 3'!$A$7:$I$206,COLUMN('Round 3'!$H$7),0))) -> 96 | K11: =IF(ISBLANK(A11),"",RANK(P11,$P$7:$P$206)) -> 9 | L11: =IF(ISBLANK($G11),IF($K11>5,"",IF(AND(ISNA(MATCH(K11+1,$K$7:$K$206,0)),$K11<$A$4),"TIE","")),"DQ") | N11: =IF(ISBLANK($G11),$R11,"DQ") -> 9 | O11: =IF(ISBLANK(A11),"",$H11*$O$6+$I11) -> 15 | P11: =IF(ISBLANK(A11),"",$O11*10*$P$6+$J11) -> 27246 | Q11: =IF(ISBLANK($G11),IF(ISBLANK($A11),-10,$P11*$Q$6+IF($M11>0,$Q$6-1-$M11,0)),-1) -> 27246 | R11: =IF(ISBLANK($A11),"",RANK($Q11,$Q$7:$Q$206)) -> 9 | S11: =IF(ISNA(MATCH($R11+1,$R$7:$R$206,0)),IF($R11=MAX($A$7:$A$206),$R11,-1),$R11) -> 9 | T11: =$A11 -> 24 | U11: =IF(N('Final Round'!$J$14)>0,IF(ISBLANK($A11),"",IF($N11>5,$N11,VLOOKUP($A11,'Final Round'!$A$14:$K$18,COLUMN('Final Round'!$J$1),0))),"") -> 9 | V11: =IF(ISNUMBER($U11),$U11,$R11) -> 9 | W11: =IF(ISBLANK($A11),"",($V$6-$V11)*$W$6+$W$6-$A11) -> 801 | X11: =IF(ISBLANK($A11),"",RANK($W11,$W$7:$W$206)) -> 9 | Y11: =$A11 -> 24 | Z11: =IF($U11="",$N11,$U11) -> 9 | AA11: =IF($U11<6,INDEX($AA$1:$AA$5,$Z11)*$Z$2,0) -> 0 | AB11: =IF(ISBLANK($A11),"",5+4*(I11+IF(AA11=0,0,VLOOKUP($A11,'Final Round'!$A$14:$K$18,COLUMN('Final Round'!$G$1),0)))+8*(H11+IF(AA11=0,0,IF(VLOOKUP($A11,'Final Round'!$A$14:$K$18,COLUMN('Final Round'!$J$1),0)=1,1,0)))+$AA11) -> 29
A12: 11 | E12: 2306635701 | F12: =IF(ISBLANK($A12),"",SUM(IF(ISNA(IF(VLOOKUP($A12,'Round 1'!$A$7:$J$206,COLUMN('Round 1'!$H$7),0),1,NA())),0,1),IF(ISNA(IF(VLOOKUP($A12,'Round 2'!$A$7:$J$206,COLUMN('Round 1'!$H$7),0),1,NA())),0,1),IF(ISNA(IF(VLOOKUP($A12,'Round 3'!$A$7:$J$206,COLUMN('Round 1'!$H$7),0),1,NA())),0,1),IF(ISNA(IF(VLOOKUP($A12,'Final Round'!$A$14:$K$18,1,0),1,NA())),0,1))) -> 3 | H12: =IF(ISBLANK($A12),"",IF(ISERROR(VLOOKUP($A12,'Round 1'!$A$7:$I$206,COLUMN('Round 1'!$G$7),0)),0,VLOOKUP($A12,'Round 1'!$A$7:$I$206,COLUMN('Round 1'!$G$7),0))+IF(ISERROR(VLOOKUP($A12,'Round 2'!$A$7:$I$206,COLUMN('Round 2'!$G$7),0)),0,VLOOKUP($A12,'Round 2'!$A$7:$I$206,COLUMN('Round 2'!$G$7),0))+IF(ISERROR(VLOOKUP($A12,'Round 3'!$A$7:$I$206,COLUMN('Round 3'!$G$7),0)),0,VLOOKUP($A12,'Round 3'!$A$7:$I$206,COLUMN('Round 3'!$G$7),0))) -> 1 | I12: =IF(ISBLANK($A12),"",IF(ISERROR(VLOOKUP($A12,'Round 1'!$A$7:$I$206,COLUMN('Round 1'!$F$7),0)),0,VLOOKUP($A12,'Round 1'!$A$7:$I$206,COLUMN('Round 1'!$F$7),0))+IF(ISERROR(VLOOKUP($A12,'Round 2'!$A$7:$I$206,COLUMN('Round 2'!$F$7),0)),0,VLOOKUP($A12,'Round 2'!$A$7:$I$206,COLUMN('Round 2'!$F$7),0))+IF(ISERROR(VLOOKUP($A12,'Round 3'!$A$7:$I$206,COLUMN('Round 3'!$F$7),0)),0,VLOOKUP($A12,'Round 3'!$A$7:$I$206,COLUMN('Round 3'!$F$7),0))) -> 3 | J12: =IF(ISBLANK($A12),"",IF(ISERROR(VLOOKUP($A12,'Round 1'!$A$7:$I$206,COLUMN('Round 1'!$H$7),0)),0,VLOOKUP($A12,'Round 1'!$A$7:$I$206,COLUMN('Round 1'!$H$7),0))+IF(ISERROR(VLOOKUP($A12,'Round 2'!$A$7:$I$206,COLUMN('Round 2'!$H$7),0)),0,VLOOKUP($A12,'Round 2'!$A$7:$I$206,COLUMN('Round 2'!$H$7),0))+IF(ISERROR(VLOOKUP($A12,'Round 3'!$A$7:$I$206,COLUMN('Round 3'!$H$7),0)),0,VLOOKUP($A12,'Round 3'!$A$7:$I$206,COLUMN('Round 3'!$H$7),0))) -> 114 | K12: =IF(ISBLANK(A12),"",RANK(P12,$P$7:$P$206)) -> 11 | L12: =IF(ISBLANK($G12),IF($K12>5,"",IF(AND(ISNA(MATCH(K12+1,$K$7:$K$206,0)),$K12<$A$4),"TIE","")),"DQ") | N12: =IF(ISBLANK($G12),$R12,"DQ") -> 11 | O12: =IF(ISBLANK(A12),"",$H12*$O$6+$I12) -> 14 | P12: =IF(ISBLANK(A12),"",$O12*10*$P$6+$J12) -> 25454 | Q12: =IF(ISBLANK($G12),IF(ISBLANK($A12),-10,$P12*$Q$6+IF($M12>0,$Q$6-1-$M12,0)),-1) -> 25454 | R12: =IF(ISBLANK($A12),"",RANK($Q12,$Q$7:$Q$206)) -> 11 | S12: =IF(ISNA(MATCH($R12+1,$R$7:$R$206,0)),IF($R12=MAX($A$7:$A$206),$R12,-1),$R12) -> 11 | T12: =$A12 -> 11 | U12: =IF(N('Final Round'!$J$14)>0,IF(ISBLANK($A12),"",IF($N12>5,$N12,VLOOKUP($A12,'Final Round'!$A$14:$K$18,COLUMN('Final Round'!$J$1),0))),"") -> 11 | V12: =IF(ISNUMBER($U12),$U12,$R12) -> 11 | W12: =IF(ISBLANK($A12),"",($V$6-$V12)*$W$6+$W$6-$A12) -> 748 | X12: =IF(ISBLANK($A12),"",RANK($W12,$W$7:$W$206)) -> 11 | Y12: =$A12 -> 11 | Z12: =IF($U12="",$N12,$U12) -> 11 | AA12: =IF($U12<6,INDEX($AA$1:$AA$5,$Z12)*$Z$2,0) -> 0 | AB12: =IF(ISBLANK($A12),"",5+4*(I12+IF(AA12=0,0,VLOOKUP($A12,'Final Round'!$A$14:$K$18,COLUMN('Final Round'!$G$1),0)))+8*(H12+IF(AA12=0,0,IF(VLOOKUP($A12,'Final Round'!$A$14:$K$18,COLUMN('Final Round'!$J$1),0)=1,1,0)))+$AA12) -> 25
A13: 25 | E13: 1245916115 | F13: =IF(ISBLANK($A13),"",SUM(IF(ISNA(IF(VLOOKUP($A13,'Round 1'!$A$7:$J$206,COLUMN('Round 1'!$H$7),0),1,NA())),0,1),IF(ISNA(IF(VLOOKUP($A13,'Round 2'!$A$7:$J$206,COLUMN('Round 1'!$H$7),0),1,NA())),0,1),IF(ISNA(IF(VLOOKUP($A13,'Round 3'!$A$7:$J$206,COLUMN('Round 1'!$H$7),0),1,NA())),0,1),IF(ISNA(IF(VLOOKUP($A13,'Final Round'!$A$14:$K$18,1,0),1,NA())),0,1))) -> 3 | H13: =IF(ISBLANK($A13),"",IF(ISERROR(VLOOKUP($A13,'Round 1'!$A$7:$I$206,COLUMN('Round 1'!$G$7),0)),0,VLOOKUP($A13,'Round 1'!$A$7:$I$206,COLUMN('Round 1'!$G$7),0))+IF(ISERROR(VLOOKUP($A13,'Round 2'!$A$7:$I$206,COLUMN('Round 2'!$G$7),0)),0,VLOOKUP($A13,'Round 2'!$A$7:$I$206,COLUMN('Round 2'!$G$7),0))+IF(ISERROR(VLOOKUP($A13,'Round 3'!$A$7:$I$206,COLUMN('Round 3'!$G$7),0)),0,VLOOKUP($A13,'Round 3'!$A$7:$I$206,COLUMN('Round 3'!$G$7),0))) -> 0 | I13: =IF(ISBLANK($A13),"",IF(ISERROR(VLOOKUP($A13,'Round 1'!$A$7:$I$206,COLUMN('Round 1'!$F$7),0)),0,VLOOKUP($A13,'Round 1'!$A$7:$I$206,COLUMN('Round 1'!$F$7),0))+IF(ISERROR(VLOOKUP($A13,'Round 2'!$A$7:$I$206,COLUMN('Round 2'!$F$7),0)),0,VLOOKUP($A13,'Round 2'!$A$7:$I$206,COLUMN('Round 2'!$F$7),0))+IF(ISERROR(VLOOKUP($A13,'Round 3'!$A$7:$I$206,COLUMN('Round 3'!$F$7),0)),0,VLOOKUP($A13,'Round 3'!$A$7:$I$206,COLUMN('Round 3'!$F$7),0))) -> 0.5 | J13: =IF(ISBLANK($A13),"",IF(ISERROR(VLOOKUP($A13,'Round 1'!$A$7:$I$206,COLUMN('Round 1'!$H$7),0)),0,VLOOKUP($A13,'Round 1'!$A$7:$I$206,COLUMN('Round 1'!$H$7),0))+IF(ISERROR(VLOOKUP($A13,'Round 2'!$A$7:$I$206,COLUMN('Round 2'!$H$7),0)),0,VLOOKUP($A13,'Round 2'!$A$7:$I$206,COLUMN('Round 2'!$H$7),0))+IF(ISERROR(VLOOKUP($A13,'Round 3'!$A$7:$I$206,COLUMN('Round 3'!$H$7),0)),0,VLOOKUP($A13,'Round 3'!$A$7:$I$206,COLUMN('Round 3'!$H$7),0))) -> 96 | K13: =IF(ISBLANK(A13),"",RANK(P13,$P$7:$P$206)) -> 24 | L13: =IF(ISBLANK($G13),IF($K13>5,"",IF(AND(ISNA(MATCH(K13+1,$K$7:$K$206,0)),$K13<$A$4),"TIE","")),"DQ") | N13: =IF(ISBLANK($G13),$R13,"DQ") -> 24 | O13: =IF(ISBLANK(A13),"",$H13*$O$6+$I13) -> 0.5 | P13: =IF(ISBLANK(A13),"",$O13*10*$P$6+$J13) -> 1001 | Q13: =IF(ISBLANK($G13),IF(ISBLANK($A13),-10,$P13*$Q$6+IF($M13>0,$Q$6-1-$M13,0)),-1) -> 1001 | R13: =IF(ISBLANK($A13),"",RANK($Q13,$Q$7:$Q$206)) -> 24 | S13: =IF(ISNA(MATCH($R13+1,$R$7:$R$206,0)),IF($R13=MAX($A$7:$A$206),$R13,-1),$R13) -> 24 | T13: =$A13 -> 25 | U13: =IF(N('Final Round'!$J$14)>0,IF(ISBLANK($A13),"",IF($N13>5,$N13,VLOOKUP($A13,'Final Round'!$A$14:$K$18,COLUMN('Final Round'!$J$1),0))),"") -> 24 | V13: =IF(ISNUMBER($U13),$U13,$R13) -> 24 | W13: =IF(ISBLANK($A13),"",($V$6-$V13)*$W$6+$W$6-$A13) -> 305 | X13: =IF(ISBLANK($A13),"",RANK($W13,$W$7:$W$206)) -> 24 | Y13: =$A13 -> 25 | Z13: =IF($U13="",$N13,$U13) -> 24 | AA13: =IF($U13<6,INDEX($AA$1:$AA$5,$Z13)*$Z$2,0) -> 0 | AB13: =IF(ISBLANK($A13),"",5+4*(I13+IF(AA13=0,0,VLOOKUP($A13,'Final Round'!$A$14:$K$18,COLUMN('Final Round'!$G$1),0)))+8*(H13+IF(AA13=0,0,IF(VLOOKUP($A13,'Final Round'!$A$14:$K$18,COLUMN('Final Round'!$J$1),0)=1,1,0)))+$AA13) -> 7
A14: 19 | E14: 7569706323 | F14: =IF(ISBLANK($A14),"",SUM(IF(ISNA(IF(VLOOKUP($A14,'Round 1'!$A$7:$J$206,COLUMN('Round 1'!$H$7),0),1,NA())),0,1),IF(ISNA(IF(VLOOKUP($A14,'Round 2'!$A$7:$J$206,COLUMN('Round 1'!$H$7),0),1,NA())),0,1),IF(ISNA(IF(VLOOKUP($A14,'Round 3'!$A$7:$J$206,COLUMN('Round 1'!$H$7),0),1,NA())),0,1),IF(ISNA(IF(VLOOKUP($A14,'Final Round'!$A$14:$K$18,1,0),1,NA())),0,1))) -> 4 | H14: =IF(ISBLANK($A14),"",IF(ISERROR(VLOOKUP($A14,'Round 1'!$A$7:$I$206,COLUMN('Round 1'!$G$7),0)),0,VLOOKUP($A14,'Round 1'!$A$7:$I$206,COLUMN('Round 1'!$G$7),0))+IF(ISERROR(VLOOKUP($A14,'Round 2'!$A$7:$I$206,COLUMN('Round 2'!$G$7),0)),0,VLOOKUP($A14,'Round 2'!$A$7:$I$206,COLUMN('Round 2'!$G$7),0))+IF(ISERROR(VLOOKUP($A14,'Round 3'!$A$7:$I$206,COLUMN('Round 3'!$G$7),0)),0,VLOOKUP($A14,'Round 3'!$A$7:$I$206,COLUMN('Round 3'!$G$7),0))) -> 2 | I14: =IF(ISBLANK($A14),"",IF(ISERROR(VLOOKUP($A14,'Round 1'!$A$7:$I$206,COLUMN('Round 1'!$F$7),0)),0,VLOOKUP($A14,'Round 1'!$A$7:$I$206,COLUMN('Round 1'!$F$7),0))+IF(ISERROR(VLOOKUP($A14,'Round 2'!$A$7:$I$206,COLUMN('Round 2'!$F$7),0)),0,VLOOKUP($A14,'Round 2'!$A$7:$I$206,COLUMN('Round 2'!$F$7),0))+IF(ISERROR(VLOOKUP($A14,'Round 3'!$A$7:$I$206,COLUMN('Round 3'!$F$7),0)),0,VLOOKUP($A14,'Round 3'!$A$7:$I$206,COLUMN('Round 3'!$F$7),0))) -> 6 | J14: =IF(ISBLANK($A14),"",IF(ISERROR(VLOOKUP($A14,'Round 1'!$A$7:$I$206,COLUMN('Round 1'!$H$7),0)),0,VLOOKUP($A14,'Round 1'!$A$7:$I$206,COLUMN('Round 1'!$H$7),0))+IF(ISERROR(VLOOKUP($A14,'Round 2'!$A$7:$I$206,COLUMN('Round 2'!$H$7),0)),0,VLOOKUP($A14,'Round 2'!$A$7:$I$206,COLUMN('Round 2'!$H$7),0))+IF(ISERROR(VLOOKUP($A14,'Round 3'!$A$7:$I$206,COLUMN('Round 3'!$H$7),0)),0,VLOOKUP($A14,'Round 3'!$A$7:$I$206,COLUMN('Round 3'!$H$7),0))) -> 144 | K14: =IF(ISBLANK(A14),"",RANK(P14,$P$7:$P$206)) -> 5 | L14: =IF(ISBLANK($G14),IF($K14>5,"",IF(AND(ISNA(MATCH(K14+1,$K$7:$K$206,0)),$K14<$A$4),"TIE","")),"DQ") | N14: =IF(ISBLANK($G14),$R14,"DQ") -> 5 | O14: =IF(ISBLANK(A14),"",$H14*$O$6+$I14) -> 28 | P14: =IF(ISBLANK(A14),"",$O14*10*$P$6+$J14) -> 50824 | Q14: =IF(ISBLANK($G14),IF(ISBLANK($A14),-10,$P14*$Q$6+IF($M14>0,$Q$6-1-$M14,0)),-1) -> 50824 | R14: =IF(ISBLANK($A14),"",RANK($Q14,$Q$7:$Q$206)) -> 5 | S14: =IF(ISNA(MATCH($R14+1,$R$7:$R$206,0)),IF($R14=MAX($A$7:$A$206),$R14,-1),$R14) -> 5 | T14: =$A14 -> 19 | U14: =IF(N('Final Round'!$J$14)>0,IF(ISBLANK($A14),"",IF($N14>5,$N14,VLOOKUP($A14,'Final Round'!$A$14:$K$18,COLUMN('Final Round'!$J$1),0))),"") -> 2 | V14: =IF(ISNUMBER($U14),$U14,$R14) -> 2 | W14: =IF(ISBLANK($A14),"",($V$6-$V14)*$W$6+$W$6-$A14) -> 1037 | X14: =IF(ISBLANK($A14),"",RANK($W14,$W$7:$W$206)) -> 4 | Y14: =$A14 -> 19 | Z14: =IF($U14="",$N14,$U14) -> 2 | AA14: =IF($U14<6,INDEX($AA$1:$AA$5,$Z14)*$Z$2,0) -> 54.287407 | AB14: =IF(ISBLANK($A14),"",5+4*(I14+IF(AA14=0,0,VLOOKUP($A14,'Final Round'!$A$14:$K$18,COLUMN('Final Round'!$G$1),0)))+8*(H14+IF(AA14=0,0,IF(VLOOKUP($A14,'Final Round'!$A$14:$K$18,COLUMN('Final Round'!$J$1),0)=1,1,0)))+$AA14) -> 103.28741
A15: 17 | E15: 8259539714 | F15: =IF(ISBLANK($A15),"",SUM(IF(ISNA(IF(VLOOKUP($A15,'Round 1'!$A$7:$J$206,COLUMN('Round 1'!$H$7),0),1,NA())),0,1),IF(ISNA(IF(VLOOKUP($A15,'Round 2'!$A$7:$J$206,COLUMN('Round 1'!$H$7),0),1,NA())),0,1),IF(ISNA(IF(VLOOKUP($A15,'Round 3'!$A$7:$J$206,COLUMN('Round 1'!$H$7),0),1,NA())),0,1),IF(ISNA(IF(VLOOKUP($A15,'Final Round'!$A$14:$K$18,1,0),1,NA())),0,1))) -> 3 | H15: =IF(ISBLANK($A15),"",IF(ISERROR(VLOOKUP($A15,'Round 1'!$A$7:$I$206,COLUMN('Round 1'!$G$7),0)),0,VLOOKUP($A15,'Round 1'!$A$7:$I$206,COLUMN('Round 1'!$G$7),0))+IF(ISERROR(VLOOKUP($A15,'Round 2'!$A$7:$I$206,COLUMN('Round 2'!$G$7),0)),0,VLOOKUP($A15,'Round 2'!$A$7:$I$206,COLUMN('Round 2'!$G$7),0))+IF(ISERROR(VLOOKUP($A15,'Round 3'!$A$7:$I$206,COLUMN('Round 3'!$G$7),0)),0,VLOOKUP($A15,'Round 3'!$A$7:$I$206,COLUMN('Round 3'!$G$7),0))) -> 0 | I15: =IF(ISBLANK($A15),"",IF(ISERROR(VLOOKUP($A15,'Round 1'!$A$7:$I$206,COLUMN('Round 1'!$F$7),0)),0,VLOOKUP($A15,'Round 1'!$A$7:$I$206,COLUMN('Round 1'!$F$7),0))+IF(ISERROR(VLOOKUP($A15,'Round 2'!$A$7:$I$206,COLUMN('Round 2'!$F$7),0)),0,VLOOKUP($A15,'Round 2'!$A$7:$I$206,COLUMN('Round 2'!$F$7),0))+IF(ISERROR(VLOOKUP($A15,'Round 3'!$A$7:$I$206,COLUMN('Round 3'!$F$7),0)),0,VLOOKUP($A15,'Round 3'!$A$7:$I$206,COLUMN('Round 3'!$F$7),0))) -> 3 | J15: =IF(ISBLANK($A15),"",IF(ISERROR(VLOOKUP($A15,'Round 1'!$A$7:$I$206,COLUMN('Round 1'!$H$7),0)),0,VLOOKUP($A15,'Round 1'!$A$7:$I$206,COLUMN('Round 1'!$H$7),0))+IF(ISERROR(VLOOKUP($A15,'Round 2'!$A$7:$I$206,COLUMN('Round 2'!$H$7),0)),0,VLOOKUP($A15,'Round 2'!$A$7:$I$206,COLUMN('Round 2'!$H$7),0))+IF(ISERROR(VLOOKUP($A15,'Round 3'!$A$7:$I$206,COLUMN('Round 3'!$H$7),0)),0,VLOOKUP($A15,'Round 3'!$A$7:$I$206,COLUMN('Round 3'!$H$7),0))) -> 120 | K15: =IF(ISBLANK(A15),"",RANK(P15,$P$7:$P$206)) -> 14 | L15: =IF(ISBLANK($G15),IF($K15>5,"",IF(AND(ISNA(MATCH(K15+1,$K$7:$K$206,0)),$K15<$A$4),"TIE","")),"DQ") | N15: =IF(ISBLANK($G15),$R15,"DQ") -> 14 | O15: =IF(ISBLANK(A15),"",$H15*$O$6+$I15) -> 3 | P15: =IF(ISBLANK(A15),"",$O15*10*$P$6+$J15) -> 5550 | Q15: =IF(ISBLANK($G15),IF(ISBLANK($A15),-10,$P15*$Q$6+IF($M15>0,$Q$6-1-$M15,0)),-1) -> 5550 | R15: =IF(ISBLANK($A15),"",RANK($Q15,$Q$7:$Q$206)) -> 14 | S15: =IF(ISNA(MATCH($R15+1,$R$7:$R$206,0)),IF($R15=MAX($A$7:$A$206),$R15,-1),$R15) -> 14 | T15: =$A15 -> 17 | U15: =IF(N('Final Round'!$J$14)>0,IF(ISBLANK($A15),"",IF($N15>5,$N15,VLOOKUP($A15,'Final Round'!$A$14:$K$18,COLUMN('Final Round'!$J$1),0))),"") -> 14 | V15: =IF(ISNUMBER($U15),$U15,$R15) -> 14 | W15: =IF(ISBLANK($A15),"",($V$6-$V15)*$W$6+$W$6-$A15) -> 643 | X15: =IF(ISBLANK($A15),"",RANK($W15,$W$7:$W$206)) -> 14 | Y15: =$A15 -> 17 | Z15: =IF($U15="",$N15,$U15) -> 14 | AA15: =IF($U15<6,INDEX($AA$1:$AA$5,$Z15)*$Z$2,0) -> 0 | AB15: =IF(ISBLANK($A15),"",5+4*(I15+IF(AA15=0,0,VLOOKUP($A15,'Final Round'!$A$14:$K$18,COLUMN('Final Round'!$G$1),0)))+8*(H15+IF(AA15=0,0,IF(VLOOKUP($A15,'Final Round'!$A$14:$K$18,COLUMN('Final Round'!$J$1),0)=1,1,0)))+$AA15) -> 17
A16: 29 | E16: 2815044528 | F16: =IF(ISBLANK($A16),"",SUM(IF(ISNA(IF(VLOOKUP($A16,'Round 1'!$A$7:$J$206,COLUMN('Round 1'!$H$7),0),1,NA())),0,1),IF(ISNA(IF(VLOOKUP($A16,'Round 2'!$A$7:$J$206,COLUMN('Round 1'!$H$7),0),1,NA())),0,1),IF(ISNA(IF(VLOOKUP($A16,'Round 3'!$A$7:$J$206,COLUMN('Round 1'!$H$7),0),1,NA())),0,1),IF(ISNA(IF(VLOOKUP($A16,'Final Round'!$A$14:$K$18,1,0),1,NA())),0,1))) -> 3 | H16: =IF(ISBLANK($A16),"",IF(ISERROR(VLOOKUP($A16,'Round 1'!$A$7:$I$206,COLUMN('Round 1'!$G$7),0)),0,VLOOKUP($A16,'Round 1'!$A$7:$I$206,COLUMN('Round 1'!$G$7),0))+IF(ISERROR(VLOOKUP($A16,'Round 2'!$A$7:$I$206,COLUMN('Round 2'!$G$7),0)),0,VLOOKUP($A16,'Round 2'!$A$7:$I$206,COLUMN('Round 2'!$G$7),0))+IF(ISERROR(VLOOKUP($A16,'Round 3'!$A$7:$I$206,COLUMN('Round 3'!$G$7),0)),0,VLOOKUP($A16,'Round 3'!$A$7:$I$206,COLUMN('Round 3'!$G$7),0))) -> 0 | I16: =IF(ISBLANK($A16),"",IF(ISERROR(VLOOKUP($A16,'Round 1'!$A$7:$I$206,COLUMN('Round 1'!$F$7),0)),0,VLOOKUP($A16,'Round 1'!$A$7:$I$206,COLUMN('Round 1'!$F$7),0))+IF(ISERROR(VLOOKUP($A16,'Round 2'!$A$7:$I$206,COLUMN('Round 2'!$F$7),0)),0,VLOOKUP($A16,'Round 2'!$A$7:$I$206,COLUMN('Round 2'!$F$7),0))+IF(ISERROR(VLOOKUP($A16,'Round 3'!$A$7:$I$206,COLUMN('Round 3'!$F$7),0)),0,VLOOKUP($A16,'Round 3'!$A$7:$I$206,COLUMN('Round 3'!$F$7),0))) -> 0 | J16: =IF(ISBLANK($A16),"",IF(ISERROR(VLOOKUP($A16,'Round 1'!$A$7:$I$206,COLUMN('Round 1'!$H$7),0)),0,VLOOKUP($A16,'Round 1'!$A$7:$I$206,COLUMN('Round 1'!$H$7),0))+IF(ISERROR(VLOOKUP($A16,'Round 2'!$A$7:$I$206,COLUMN('Round 2'!$H$7),0)),0,VLOOKUP($A16,'Round 2'!$A$7:$I$206,COLUMN('Round 2'!$H$7),0))+IF(ISERROR(VLOOKUP($A16,'Round 3'!$A$7:$I$206,COLUMN('Round 3'!$H$7),0)),0,VLOOKUP($A16,'Round 3'!$A$7:$I$206,COLUMN('Round 3'!$H$7),0))) -> 66 | K16: =IF(ISBLANK(A16),"",RANK(P16,$P$7:$P$206)) -> 29 | L16: =IF(ISBLANK($G16),IF($K16>5,"",IF(AND(ISNA(MATCH(K16+1,$K$7:$K$206,0)),$K16<$A$4),"TIE","")),"DQ") | N16: =IF(ISBLANK($G16),$R16,"DQ") -> 29 | O16: =IF(ISBLANK(A16),"",$H16*$O$6+$I16) -> 0 | P16: =IF(ISBLANK(A16),"",$O16*10*$P$6+$J16) -> 66 | Q16: =IF(ISBLANK($G16),IF(ISBLANK($A16),-10,$P16*$Q$6+IF($M16>0,$Q$6-1-$M16,0)),-1) -> 66 | R16: =IF(ISBLANK($A16),"",RANK($Q16,$Q$7:$Q$206)) -> 29 | S16: =IF(ISNA(MATCH($R16+1,$R$7:$R$206,0)),IF($R16=MAX($A$7:$A$206),$R16,-1),$R16) -> -1 | T16: =$A16 -> 29 | U16: =IF(N('Final Round'!$J$14)>0,IF(ISBLANK($A16),"",IF($N16>5,$N16,VLOOKUP($A16,'Final Round'!$A$14:$K$18,COLUMN('Final Round'!$J$1),0))),"") -> 29 | V16: =IF(ISNUMBER($U16),$U16,$R16) -> 29 | W16: =IF(ISBLANK($A16),"",($V$6-$V16)*$W$6+$W$6-$A16) -> 136 | X16: =IF(ISBLANK($A16),"",RANK($W16,$W$7:$W$206)) -> 31 | Y16: =$A16 -> 29 | Z16: =IF($U16="",$N16,$U16) -> 29 | AA16: =IF($U16<6,INDEX($AA$1:$AA$5,$Z16)*$Z$2,0) -> 0 | AB16: =IF(ISBLANK($A16),"",5+4*(I16+IF(AA16=0,0,VLOOKUP($A16,'Final Round'!$A$14:$K$18,COLUMN('Final Round'!$G$1),0)))+8*(H16+IF(AA16=0,0,IF(VLOOKUP($A16,'Final Round'!$A$14:$K$18,COLUMN('Final Round'!$J$1),0)=1,1,0)))+$AA16) -> 5
A17: 28 | E17: 8638881481 | F17: =IF(ISBLANK($A17),"",SUM(IF(ISNA(IF(VLOOKUP($A17,'Round 1'!$A$7:$J$206,COLUMN('Round 1'!$H$7),0),1,NA())),0,1),IF(ISNA(IF(VLOOKUP($A17,'Round 2'!$A$7:$J$206,COLUMN('Round 1'!$H$7),0),1,NA())),0,1),IF(ISNA(IF(VLOOKUP($A17,'Round 3'!$A$7:$J$206,COLUMN('Round 1'!$H$7),0),1,NA())),0,1),IF(ISNA(IF(VLOOKUP($A17,'Final Round'!$A$14:$K$18,1,0),1,NA())),0,1))) -> 4 | H17: =IF(ISBLANK($A17),"",IF(ISERROR(VLOOKUP($A17,'Round 1'!$A$7:$I$206,COLUMN('Round 1'!$G$7),0)),0,VLOOKUP($A17,'Round 1'!$A$7:$I$206,COLUMN('Round 1'!$G$7),0))+IF(ISERROR(VLOOKUP($A17,'Round 2'!$A$7:$I$206,COLUMN('Round 2'!$G$7),0)),0,VLOOKUP($A17,'Round 2'!$A$7:$I$206,COLUMN('Round 2'!$G$7),0))+IF(ISERROR(VLOOKUP($A17,'Round 3'!$A$7:$I$206,COLUMN('Round 3'!$G$7),0)),0,VLOOKUP($A17,'Round 3'!$A$7:$I$206,COLUMN('Round 3'!$G$7),0))) -> 3 | I17: =IF(ISBLANK($A17),"",IF(ISERROR(VLOOKUP($A17,'Round 1'!$A$7:$I$206,COLUMN('Round 1'!$F$7),0)),0,VLOOKUP($A17,'Round 1'!$A$7:$I$206,COLUMN('Round 1'!$F$7),0))+IF(ISERROR(VLOOKUP($A17,'Round 2'!$A$7:$I$206,COLUMN('Round 2'!$F$7),0)),0,VLOOKUP($A17,'Round 2'!$A$7:$I$206,COLUMN('Round 2'!$F$7),0))+IF(ISERROR(VLOOKUP($A17,'Round 3'!$A$7:$I$206,COLUMN('Round 3'!$F$7),0)),0,VLOOKUP($A17,'Round 3'!$A$7:$I$206,COLUMN('Round 3'!$F$7),0))) -> 9 | J17: =IF(ISBLANK($A17),"",IF(ISERROR(VLOOKUP($A17,'Round 1'!$A$7:$I$206,COLUMN('Round 1'!$H$7),0)),0,VLOOKUP($A17,'Round 1'!$A$7:$I$206,COLUMN('Round 1'!$H$7),0))+IF(ISERROR(VLOOKUP($A17,'Round 2'!$A$7:$I$206,COLUMN('Round 2'!$H$7),0)),0,VLOOKUP($A17,'Round 2'!$A$7:$I$206,COLUMN('Round 2'!$H$7),0))+IF(ISERROR(VLOOKUP($A17,'Round 3'!$A$7:$I$206,COLUMN('Round 3'!$H$7),0)),0,VLOOKUP($A17,'Round 3'!$A$7:$I$206,COLUMN('Round 3'!$H$7),0))) -> 180 | K17: =IF(ISBLANK(A17),"",RANK(P17,$P$7:$P$206)) -> 1 | L17: =IF(ISBLANK($G17),IF($K17>5,"",IF(AND(ISNA(MATCH(K17+1,$K$7:$K$206,0)),$K17<$A$4),"TIE","")),"DQ") | N17: =IF(ISBLANK($G17),$R17,"DQ") -> 1 | O17: =IF(ISBLANK(A17),"",$H17*$O$6+$I17) -> 42 | P17: =IF(ISBLANK(A17),"",$O17*10*$P$6+$J17) -> 76200 | Q17: =IF(ISBLANK($G17),IF(ISBLANK($A17),-10,$P17*$Q$6+IF($M17>0,$Q$6-1-$M17,0)),-1) -> 76200 | R17: =IF(ISBLANK($A17),"",RANK($Q17,$Q$7:$Q$206)) -> 1 | S17: =IF(ISNA(MATCH($R17+1,$R$7:$R$206,0)),IF($R17=MAX($A$7:$A$206),$R17,-1),$R17) -> 1 | T17: =$A17 -> 28 | U17: =IF(N('Final Round'!$J$14)>0,IF(ISBLANK($A17),"",IF($N17>5,$N17,VLOOKUP($A17,'Final Round'!$A$14:$K$18,COLUMN('Final Round'!$J$1),0))),"") -> 1 | V17: =IF(ISNUMBER($U17),$U17,$R17) -> 1 | W17: =IF(ISBLANK($A17),"",($V$6-$V17)*$W$6+$W$6-$A17) -> 1061 | X17: =IF(ISBLANK($A17),"",RANK($W17,$W$7:$W$206)) -> 1 | Y17: =$A17 -> 28 | Z17: =IF($U17="",$N17,$U17) -> 1 | AA17: =IF($U17<6,INDEX($AA$1:$AA$5,$Z17)*$Z$2,0) -> 162.86222 | AB17: =IF(ISBLANK($A17),"",5+4*(I17+IF(AA17=0,0,VLOOKUP($A17,'Final Round'!$A$14:$K$18,COLUMN('Final Round'!$G$1),0)))+8*(H17+IF(AA17=0,0,IF(VLOOKUP($A17,'Final Round'!$A$14:$K$18,COLUMN('Final Round'!$J$1),0)=1,1,0)))+$AA17) -> 243.86222
A18: 6 | F18: =IF(ISBLANK($A18),"",SUM(IF(ISNA(IF(VLOOKUP($A18,'Round 1'!$A$7:$J$206,COLUMN('Round 1'!$H$7),0),1,NA())),0,1),IF(ISNA(IF(VLOOKUP($A18,'Round 2'!$A$7:$J$206,COLUMN('Round 1'!$H$7),0),1,NA())),0,1),IF(ISNA(IF(VLOOKUP($A18,'Round 3'!$A$7:$J$206,COLUMN('Round 1'!$H$7),0),1,NA())),0,1),IF(ISNA(IF(VLOOKUP($A18,'Final Round'!$A$14:$K$18,1,0),1,NA())),0,1))) -> 3 | H18: =IF(ISBLANK($A18),"",IF(ISERROR(VLOOKUP($A18,'Round 1'!$A$7:$I$206,COLUMN('Round 1'!$G$7),0)),0,VLOOKUP($A18,'Round 1'!$A$7:$I$206,COLUMN('Round 1'!$G$7),0))+IF(ISERROR(VLOOKUP($A18,'Round 2'!$A$7:$I$206,COLUMN('Round 2'!$G$7),0)),0,VLOOKUP($A18,'Round 2'!$A$7:$I$206,COLUMN('Round 2'!$G$7),0))+IF(ISERROR(VLOOKUP($A18,'Round 3'!$A$7:$I$206,COLUMN('Round 3'!$G$7),0)),0,VLOOKUP($A18,'Round 3'!$A$7:$I$206,COLUMN('Round 3'!$G$7),0))) -> 0 | I18: =IF(ISBLANK($A18),"",IF(ISERROR(VLOOKUP($A18,'Round 1'!$A$7:$I$206,COLUMN('Round 1'!$F$7),0)),0,VLOOKUP($A18,'Round 1'!$A$7:$I$206,COLUMN('Round 1'!$F$7),0))+IF(ISERROR(VLOOKUP($A18,'Round 2'!$A$7:$I$206,COLUMN('Round 2'!$F$7),0)),0,VLOOKUP($A18,'Round 2'!$A$7:$I$206,COLUMN('Round 2'!$F$7),0))+IF(ISERROR(VLOOKUP($A18,'Round 3'!$A$7:$I$206,COLUMN('Round 3'!$F$7),0)),0,VLOOKUP($A18,'Round 3'!$A$7:$I$206,COLUMN('Round 3'!$F$7),0))) -> 0 | J18: =IF(ISBLANK($A18),"",IF(ISERROR(VLOOKUP($A18,'Round 1'!$A$7:$I$206,COLUMN('Round 1'!$H$7),0)),0,VLOOKUP($A18,'Round 1'!$A$7:$I$206,COLUMN('Round 1'!$H$7),0))+IF(ISERROR(VLOOKUP($A18,'Round 2'!$A$7:$I$206,COLUMN('Round 2'!$H$7),0)),0,VLOOKUP($A18,'Round 2'!$A$7:$I$206,COLUMN('Round 2'!$H$7),0))+IF(ISERROR(VLOOKUP($A18,'Round 3'!$A$7:$I$206,COLUMN('Round 3'!$H$7),0)),0,VLOOKUP($A18,'Round 3'!$A$7:$I$206,COLUMN('Round 3'!$H$7),0))) -> 72 | K18: =IF(ISBLANK(A18),"",RANK(P18,$P$7:$P$206)) -> 27 | L18: =IF(ISBLANK($G18),IF($K18>5,"",IF(AND(ISNA(MATCH(K18+1,$K$7:$K$206,0)),$K18<$A$4),"TIE","")),"DQ") | N18: =IF(ISBLANK($G18),$R18,"DQ") -> 27 | O18: =IF(ISBLANK(A18),"",$H18*$O$6+$I18) -> 0 | P18: =IF(ISBLANK(A18),"",$O18*10*$P$6+$J18) -> 72 | Q18: =IF(ISBLANK($G18),IF(ISBLANK($A18),-10,$P18*$Q$6+IF($M18>0,$Q$6-1-$M18,0)),-1) -> 72 | R18: =IF(ISBLANK($A18),"",RANK($Q18,$Q$7:$Q$206)) -> 27 | S18: =IF(ISNA(MATCH($R18+1,$R$7:$R$206,0)),IF($R18=MAX($A$7:$A$206),$R18,-1),$R18) -> 27 | T18: =$A18 -> 6 | U18: =IF(N('Final Round'!$J$14)>0,IF(ISBLANK($A18),"",IF($N18>5,$N18,VLOOKUP($A18,'Final Round'!$A$14:$K$18,COLUMN('Final Round'!$J$1),0))),"") -> 27 | V18: =IF(ISNUMBER($U18),$U18,$R18) -> 27 | W18: =IF(ISBLANK($A18),"",($V$6-$V18)*$W$6+$W$6-$A18) -> 225 | X18: =IF(ISBLANK($A18),"",RANK($W18,$W$7:$W$206)) -> 27 | Y18: =$A18 -> 6 | Z18: =IF($U18="",$N18,$U18) -> 27 | AA18: =IF($U18<6,INDEX($AA$1:$AA$5,$Z18)*$Z$2,0) -> 0 | AB18: =IF(ISBLANK($A18),"",5+4*(I18+IF(AA18=0,0,VLOOKUP($A18,'Final Round'!$A$14:$K$18,COLUMN('Final Round'!$G$1),0)))+8*(H18+IF(AA18=0,0,IF(VLOOKUP($A18,'Final Round'!$A$14:$K$18,COLUMN('Final Round'!$J$1),0)=1,1,0)))+$AA18) -> 5
A19: 22 | F19: =IF(ISBLANK($A19),"",SUM(IF(ISNA(IF(VLOOKUP($A19,'Round 1'!$A$7:$J$206,COLUMN('Round 1'!$H$7),0),1,NA())),0,1),IF(ISNA(IF(VLOOKUP($A19,'Round 2'!$A$7:$J$206,COLUMN('Round 1'!$H$7),0),1,NA())),0,1),IF(ISNA(IF(VLOOKUP($A19,'Round 3'!$A$7:$J$206,COLUMN('Round 1'!$H$7),0),1,NA())),0,1),IF(ISNA(IF(VLOOKUP($A19,'Final Round'!$A$14:$K$18,1,0),1,NA())),0,1))) -> 3 | H19: =IF(ISBLANK($A19),"",IF(ISERROR(VLOOKUP($A19,'Round 1'!$A$7:$I$206,COLUMN('Round 1'!$G$7),0)),0,VLOOKUP($A19,'Round 1'!$A$7:$I$206,COLUMN('Round 1'!$G$7),0))+IF(ISERROR(VLOOKUP($A19,'Round 2'!$A$7:$I$206,COLUMN('Round 2'!$G$7),0)),0,VLOOKUP($A19,'Round 2'!$A$7:$I$206,COLUMN('Round 2'!$G$7),0))+IF(ISERROR(VLOOKUP($A19,'Round 3'!$A$7:$I$206,COLUMN('Round 3'!$G$7),0)),0,VLOOKUP($A19,'Round 3'!$A$7:$I$206,COLUMN('Round 3'!$G$7),0))) -> 0 | I19: =IF(ISBLANK($A19),"",IF(ISERROR(VLOOKUP($A19,'Round 1'!$A$7:$I$206,COLUMN('Round 1'!$F$7),0)),0,VLOOKUP($A19,'Round 1'!$A$7:$I$206,COLUMN('Round 1'!$F$7),0))+IF(ISERROR(VLOOKUP($A19,'Round 2'!$A$7:$I$206,COLUMN('Round 2'!$F$7),0)),0,VLOOKUP($A19,'Round 2'!$A$7:$I$206,COLUMN('Round 2'!$F$7),0))+IF(ISERROR(VLOOKUP($A19,'Round 3'!$A$7:$I$206,COLUMN('Round 3'!$F$7),0)),0,VLOOKUP($A19,'Round 3'!$A$7:$I$206,COLUMN('Round 3'!$F$7),0))) -> 0 | J19: =IF(ISBLANK($A19),"",IF(ISERROR(VLOOKUP($A19,'Round 1'!$A$7:$I$206,COLUMN('Round 1'!$H$7),0)),0,VLOOKUP($A19,'Round 1'!$A$7:$I$206,COLUMN('Round 1'!$H$7),0))+IF(ISERROR(VLOOKUP($A19,'Round 2'!$A$7:$I$206,COLUMN('Round 2'!$H$7),0)),0,VLOOKUP($A19,'Round 2'!$A$7:$I$206,COLUMN('Round 2'!$H$7),0))+IF(ISERROR(VLOOKUP($A19,'Round 3'!$A$7:$I$206,COLUMN('Round 3'!$H$7),0)),0,VLOOKUP($A19,'Round 3'!$A$7:$I$206,COLUMN('Round 3'!$H$7),0))) -> 82 | K19: =IF(ISBLANK(A19),"",RANK(P19,$P$7:$P$206)) -> 26 | L19: =IF(ISBLANK($G19),IF($K19>5,"",IF(AND(ISNA(MATCH(K19+1,$K$7:$K$206,0)),$K19<$A$4),"TIE","")),"DQ") | N19: =IF(ISBLANK($G19),$R19,"DQ") -> 26 | O19: =IF(ISBLANK(A19),"",$H19*$O$6+$I19) -> 0 | P19: =IF(ISBLANK(A19),"",$O19*10*$P$6+$J19) -> 82 | Q19: =IF(ISBLANK($G19),IF(ISBLANK($A19),-10,$P19*$Q$6+IF($M19>0,$Q$6-1-$M19,0)),-1) -> 82 | R19: =IF(ISBLANK($A19),"",RANK($Q19,$Q$7:$Q$206)) -> 26 | S19: =IF(ISNA(MATCH($R19+1,$R$7:$R$206,0)),IF($R19=MAX($A$7:$A$206),$R19,-1),$R19) -> 26 | T19: =$A19 -> 22 | U19: =IF(N('Final Round'!$J$14)>0,IF(ISBLANK($A19),"",IF($N19>5,$N19,VLOOKUP($A19,'Final Round'!$A$14:$K$18,COLUMN('Final Round'!$J$1),0))),"") -> 26 | V19: =IF(ISNUMBER($U19),$U19,$R19) -> 26 | W19: =IF(ISBLANK($A19),"",($V$6-$V19)*$W$6+$W$6-$A19) -> 242 | X19: =IF(ISBLANK($A19),"",RANK($W19,$W$7:$W$206)) -> 26 | Y19: =$A19 -> 22 | Z19: =IF($U19="",$N19,$U19) -> 26 | AA19: =IF($U19<6,INDEX($AA$1:$AA$5,$Z19)*$Z$2,0) -> 0 | AB19: =IF(ISBLANK($A19),"",5+4*(I19+IF(AA19=0,0,VLOOKUP($A19,'Final Round'!$A$14:$K$18,COLUMN('Final Round'!$G$1),0)))+8*(H19+IF(AA19=0,0,IF(VLOOKUP($A19,'Final Round'!$A$14:$K$18,COLUMN('Final Round'!$J$1),0)=1,1,0)))+$AA19) -> 5
A20: 15 | E20: 8638191794 | F20: =IF(ISBLANK($A20),"",SUM(IF(ISNA(IF(VLOOKUP($A20,'Round 1'!$A$7:$J$206,COLUMN('Round 1'!$H$7),0),1,NA())),0,1),IF(ISNA(IF(VLOOKUP($A20,'Round 2'!$A$7:$J$206,COLUMN('Round 1'!$H$7),0),1,NA())),0,1),IF(ISNA(IF(VLOOKUP($A20,'Round 3'!$A$7:$J$206,COLUMN('Round 1'!$H$7),0),1,NA())),0,1),IF(ISNA(IF(VLOOKUP($A20,'Final Round'!$A$14:$K$18,1,0),1,NA())),0,1))) -> 4 | H20: =IF(ISBLANK($A20),"",IF(ISERROR(VLOOKUP($A20,'Round 1'!$A$7:$I$206,COLUMN('Round 1'!$G$7),0)),0,VLOOKUP($A20,'Round 1'!$A$7:$I$206,COLUMN('Round 1'!$G$7),0))+IF(ISERROR(VLOOKUP($A20,'Round 2'!$A$7:$I$206,COLUMN('Round 2'!$G$7),0)),0,VLOOKUP($A20,'Round 2'!$A$7:$I$206,COLUMN('Round 2'!$G$7),0))+IF(ISERROR(VLOOKUP($A20,'Round 3'!$A$7:$I$206,COLUMN('Round 3'!$G$7),0)),0,VLOOKUP($A20,'Round 3'!$A$7:$I$206,COLUMN('Round 3'!$G$7),0))) -> 2 | I20: =IF(ISBLANK($A20),"",IF(ISERROR(VLOOKUP($A20,'Round 1'!$A$7:$I$206,COLUMN('Round 1'!$F$7),0)),0,VLOOKUP($A20,'Round 1'!$A$7:$I$206,COLUMN('Round 1'!$F$7),0))+IF(ISERROR(VLOOKUP($A20,'Round 2'!$A$7:$I$206,COLUMN('Round 2'!$F$7),0)),0,VLOOKUP($A20,'Round 2'!$A$7:$I$206,COLUMN('Round 2'!$F$7),0))+IF(ISERROR(VLOOKUP($A20,'Round 3'!$A$7:$I$206,COLUMN('Round 3'!$F$7),0)),0,VLOOKUP($A20,'Round 3'!$A$7:$I$206,COLUMN('Round 3'!$F$7),0))) -> 10 | J20: =IF(ISBLANK($A20),"",IF(ISERROR(VLOOKUP($A20,'Round 1'!$A$7:$I$206,COLUMN('Round 1'!$H$7),0)),0,VLOOKUP($A20,'Round 1'!$A$7:$I$206,COLUMN('Round 1'!$H$7),0))+IF(ISERROR(VLOOKUP($A20,'Round 2'!$A$7:$I$206,COLUMN('Round 2'!$H$7),0)),0,VLOOKUP($A20,'Round 2'!$A$7:$I$206,COLUMN('Round 2'!$H$7),0))+IF(ISERROR(VLOOKUP($A20,'Round 3'!$A$7:$I$206,COLUMN('Round 3'!$H$7),0)),0,VLOOKUP($A20,'Round 3'!$A$7:$I$206,COLUMN('Round 3'!$H$7),0))) -> 174 | K20: =IF(ISBLANK(A20),"",RANK(P20,$P$7:$P$206)) -> 2 | L20: =IF(ISBLANK($G20),IF($K20>5,"",IF(AND(ISNA(MATCH(K20+1,$K$7:$K$206,0)),$K20<$A$4),"TIE","")),"DQ") | N20: =IF(ISBLANK($G20),$R20,"DQ") -> 2 | O20: =IF(ISBLANK(A20),"",$H20*$O$6+$I20) -> 32 | P20: =IF(ISBLANK(A20),"",$O20*10*$P$6+$J20) -> 58094 | Q20: =IF(ISBLANK($G20),IF(ISBLANK($A20),-10,$P20*$Q$6+IF($M20>0,$Q$6-1-$M20,0)),-1) -> 58094 | R20: =IF(ISBLANK($A20),"",RANK($Q20,$Q$7:$Q$206)) -> 2 | S20: =IF(ISNA(MATCH($R20+1,$R$7:$R$206,0)),IF($R20=MAX($A$7:$A$206),$R20,-1),$R20) -> 2 | T20: =$A20 -> 15 | U20: =IF(N('Final Round'!$J$14)>0,IF(ISBLANK($A20),"",IF($N20>5,$N20,VLOOKUP($A20,'Final Round'!$A$14:$K$18,COLUMN('Final Round'!$J$1),0))),"") -> 2 | V20: =IF(ISNUMBER($U20),$U20,$R20) -> 2 | W20: =IF(ISBLANK($A20),"",($V$6-$V20)*$W$6+$W$6-$A20) -> 1041 | X20: =IF(ISBLANK($A20),"",RANK($W20,$W$7:$W$206)) -> 3 | Y20: =$A20 -> 15 | Z20: =IF($U20="",$N20,$U20) -> 2 | AA20: =IF($U20<6,INDEX($AA$1:$AA$5,$Z20)*$Z$2,0) -> 54.287407 | AB20: =IF(ISBLANK($A20),"",5+4*(I20+IF(AA20=0,0,VLOOKUP($A20,'Final Round'!$A$14:$K$18,COLUMN('Final Round'!$G$1),0)))+8*(H20+IF(AA20=0,0,IF(VLOOKUP($A20,'Final Round'!$A$14:$K$18,COLUMN('Final Round'!$J$1),0)=1,1,0)))+$AA20) -> 115.28741
A21: 30 | E21: 3152888133 | F21: =IF(ISBLANK($A21),"",SUM(IF(ISNA(IF(VLOOKUP($A21,'Round 1'!$A$7:$J$206,COLUMN('Round 1'!$H$7),0),1,NA())),0,1),IF(ISNA(IF(VLOOKUP($A21,'Round 2'!$A$7:$J$206,COLUMN('Round 1'!$H$7),0),1,NA())),0,1),IF(ISNA(IF(VLOOKUP($A21,'Round 3'!$A$7:$J$206,COLUMN('Round 1'!$H$7),0),1,NA())),0,1),IF(ISNA(IF(VLOOKUP($A21,'Final Round'!$A$14:$K$18,1,0),1,NA())),0,1))) -> 3 | H21: =IF(ISBLANK($A21),"",IF(ISERROR(VLOOKUP($A21,'Round 1'!$A$7:$I$206,COLUMN('Round 1'!$G$7),0)),0,VLOOKUP($A21,'Round 1'!$A$7:$I$206,COLUMN('Round 1'!$G$7),0))+IF(ISERROR(VLOOKUP($A21,'Round 2'!$A$7:$I$206,COLUMN('Round 2'!$G$7),0)),0,VLOOKUP($A21,'Round 2'!$A$7:$I$206,COLUMN('Round 2'!$G$7),0))+IF(ISERROR(VLOOKUP($A21,'Round 3'!$A$7:$I$206,COLUMN('Round 3'!$G$7),0)),0,VLOOKUP($A21,'Round 3'!$A$7:$I$206,COLUMN('Round 3'!$G$7),0))) -> 0 | I21: =IF(ISBLANK($A21),"",IF(ISERROR(VLOOKUP($A21,'Round 1'!$A$7:$I$206,COLUMN('Round 1'!$F$7),0)),0,VLOOKUP($A21,'Round 1'!$A$7:$I$206,COLUMN('Round 1'!$F$7),0))+IF(ISERROR(VLOOKUP($A21,'Round 2'!$A$7:$I$206,COLUMN('Round 2'!$F$7),0)),0,VLOOKUP($A21,'Round 2'!$A$7:$I$206,COLUMN('Round 2'!$F$7),0))+IF(ISERROR(VLOOKUP($A21,'Round 3'!$A$7:$I$206,COLUMN('Round 3'!$F$7),0)),0,VLOOKUP($A21,'Round 3'!$A$7:$I$206,COLUMN('Round 3'!$F$7),0))) -> 1 | J21: =IF(ISBLANK($A21),"",IF(ISERROR(VLOOKUP($A21,'Round 1'!$A$7:$I$206,COLUMN('Round 1'!$H$7),0)),0,VLOOKUP($A21,'Round 1'!$A$7:$I$206,COLUMN('Round 1'!$H$7),0))+IF(ISERROR(VLOOKUP($A21,'Round 2'!$A$7:$I$206,COLUMN('Round 2'!$H$7),0)),0,VLOOKUP($A21,'Round 2'!$A$7:$I$206,COLUMN('Round 2'!$H$7),0))+IF(ISERROR(VLOOKUP($A21,'Round 3'!$A$7:$I$206,COLUMN('Round 3'!$H$7),0)),0,VLOOKUP($A21,'Round 3'!$A$7:$I$206,COLUMN('Round 3'!$H$7),0))) -> 102 | K21: =IF(ISBLANK(A21),"",RANK(P21,$P$7:$P$206)) -> 20 | L21: =IF(ISBLANK($G21),IF($K21>5,"",IF(AND(ISNA(MATCH(K21+1,$K$7:$K$206,0)),$K21<$A$4),"TIE","")),"DQ") | N21: =IF(ISBLANK($G21),$R21,"DQ") -> 20 | O21: =IF(ISBLANK(A21),"",$H21*$O$6+$I21) -> 1 | P21: =IF(ISBLANK(A21),"",$O21*10*$P$6+$J21) -> 1912 | Q21: =IF(ISBLANK($G21),IF(ISBLANK($A21),-10,$P21*$Q$6+IF($M21>0,$Q$6-1-$M21,0)),-1) -> 1912 | R21: =IF(ISBLANK($A21),"",RANK($Q21,$Q$7:$Q$206)) -> 20 | S21: =IF(ISNA(MATCH($R21+1,$R$7:$R$206,0)),IF($R21=MAX($A$7:$A$206),$R21,-1),$R21) -> 20 | T21: =$A21 -> 30 | U21: =IF(N('Final Round'!$J$14)>0,IF(ISBLANK($A21),"",IF($N21>5,$N21,VLOOKUP($A21,'Final Round'!$A$14:$K$18,COLUMN('Final Round'!$J$1),0))),"") -> 20 | V21: =IF(ISNUMBER($U21),$U21,$R21) -> 20 | W21: =IF(ISBLANK($A21),"",($V$6-$V21)*$W$6+$W$6-$A21) -> 432 | X21: =IF(ISBLANK($A21),"",RANK($W21,$W$7:$W$206)) -> 20 | Y21: =$A21 -> 30 | Z21: =IF($U21="",$N21,$U21) -> 20 | AA21: =IF($U21<6,INDEX($AA$1:$AA$5,$Z21)*$Z$2,0) -> 0 | AB21: =IF(ISBLANK($A21),"",5+4*(I21+IF(AA21=0,0,VLOOKUP($A21,'Final Round'!$A$14:$K$18,COLUMN('Final Round'!$G$1),0)))+8*(H21+IF(AA21=0,0,IF(VLOOKUP($A21,'Final Round'!$A$14:$K$18,COLUMN('Final Round'!$J$1),0)=1,1,0)))+$AA21) -> 9
A22: 1 | E22: 8887487780 | F22: =IF(ISBLANK($A22),"",SUM(IF(ISNA(IF(VLOOKUP($A22,'Round 1'!$A$7:$J$206,COLUMN('Round 1'!$H$7),0),1,NA())),0,1),IF(ISNA(IF(VLOOKUP($A22,'Round 2'!$A$7:$J$206,COLUMN('Round 1'!$H$7),0),1,NA())),0,1),IF(ISNA(IF(VLOOKUP($A22,'Round 3'!$A$7:$J$206,COLUMN('Round 1'!$H$7),0),1,NA())),0,1),IF(ISNA(IF(VLOOKUP($A22,'Final Round'!$A$14:$K$18,1,0),1,NA())),0,1))) -> 3 | H22: =IF(ISBLANK($A22),"",IF(ISERROR(VLOOKUP($A22,'Round 1'!$A$7:$I$206,COLUMN('Round 1'!$G$7),0)),0,VLOOKUP($A22,'Round 1'!$A$7:$I$206,COLUMN('Round 1'!$G$7),0))+IF(ISERROR(VLOOKUP($A22,'Round 2'!$A$7:$I$206,COLUMN('Round 2'!$G$7),0)),0,VLOOKUP($A22,'Round 2'!$A$7:$I$206,COLUMN('Round 2'!$G$7),0))+IF(ISERROR(VLOOKUP($A22,'Round 3'!$A$7:$I$206,COLUMN('Round 3'!$G$7),0)),0,VLOOKUP($A22,'Round 3'!$A$7:$I$206,COLUMN('Round 3'!$G$7),0))) -> 0 | I22: =IF(ISBLANK($A22),"",IF(ISERROR(VLOOKUP($A22,'Round 1'!$A$7:$I$206,COLUMN('Round 1'!$F$7),0)),0,VLOOKUP($A22,'Round 1'!$A$7:$I$206,COLUMN('Round 1'!$F$7),0))+IF(ISERROR(VLOOKUP($A22,'Round 2'!$A$7:$I$206,COLUMN('Round 2'!$F$7),0)),0,VLOOKUP($A22,'Round 2'!$A$7:$I$206,COLUMN('Round 2'!$F$7),0))+IF(ISERROR(VLOOKUP($A22,'Round 3'!$A$7:$I$206,COLUMN('Round 3'!$F$7),0)),0,VLOOKUP($A22,'Round 3'!$A$7:$I$206,COLUMN('Round 3'!$F$7),0))) -> 0 | J22: =IF(ISBLANK($A22),"",IF(ISERROR(VLOOKUP($A22,'Round 1'!$A$7:$I$206,COLUMN('Round 1'!$H$7),0)),0,VLOOKUP($A22,'Round 1'!$A$7:$I$206,COLUMN('Round 1'!$H$7),0))+IF(ISERROR(VLOOKUP($A22,'Round 2'!$A$7:$I$206,COLUMN('Round 2'!$H$7),0)),0,VLOOKUP($A22,'Round 2'!$A$7:$I$206,COLUMN('Round 2'!$H$7),0))+IF(ISERROR(VLOOKUP($A22,'Round 3'!$A$7:$I$206,COLUMN('Round 3'!$H$7),0)),0,VLOOKUP($A22,'Round 3'!$A$7:$I$206,COLUMN('Round 3'!$H$7),0))) -> 66 | K22: =IF(ISBLANK(A22),"",RANK(P22,$P$7:$P$206)) -> 29 | L22: =IF(ISBLANK($G22),IF($K22>5,"",IF(AND(ISNA(MATCH(K22+1,$K$7:$K$206,0)),$K22<$A$4),"TIE","")),"DQ") | N22: =IF(ISBLANK($G22),$R22,"DQ") -> 29 | O22: =IF(ISBLANK(A22),"",$H22*$O$6+$I22) -> 0 | P22: =IF(ISBLANK(A22),"",$O22*10*$P$6+$J22) -> 66 | Q22: =IF(ISBLANK($G22),IF(ISBLANK($A22),-10,$P22*$Q$6+IF($M22>0,$Q$6-1-$M22,0)),-1) -> 66 | R22: =IF(ISBLANK($A22),"",RANK($Q22,$Q$7:$Q$206)) -> 29 | S22: =IF(ISNA(MATCH($R22+1,$R$7:$R$206,0)),IF($R22=MAX($A$7:$A$206),$R22,-1),$R22) -> -1 | T22: =$A22 -> 1 | U22: =IF(N('Final Round'!$J$14)>0,IF(ISBLANK($A22),"",IF($N22>5,$N22,VLOOKUP($A22,'Final Round'!$A$14:$K$18,COLUMN('Final Round'!$J$1),0))),"") -> 29 | V22: =IF(ISNUMBER($U22),$U22,$R22) -> 29 | W22: =IF(ISBLANK($A22),"",($V$6-$V22)*$W$6+$W$6-$A22) -> 164 | X22: =IF(ISBLANK($A22),"",RANK($W22,$W$7:$W$206)) -> 29 | Y22: =$A22 -> 1 | Z22: =IF($U22="",$N22,$U22) -> 29 | AA22: =IF($U22<6,INDEX($AA$1:$AA$5,$Z22)*$Z$2,0) -> 0 | AB22: =IF(ISBLANK($A22),"",5+4*(I22+IF(AA22=0,0,VLOOKUP($A22,'Final Round'!$A$14:$K$18,COLUMN('Final Round'!$G$1),0)))+8*(H22+IF(AA22=0,0,IF(VLOOKUP($A22,'Final Round'!$A$14:$K$18,COLUMN('Final Round'!$J$1),0)=1,1,0)))+$AA22) -> 5
A23: 5 | E23: 3216114793 | F23: =IF(ISBLANK($A23),"",SUM(IF(ISNA(IF(VLOOKUP($A23,'Round 1'!$A$7:$J$206,COLUMN('Round 1'!$H$7),0),1,NA())),0,1),IF(ISNA(IF(VLOOKUP($A23,'Round 2'!$A$7:$J$206,COLUMN('Round 1'!$H$7),0),1,NA())),0,1),IF(ISNA(IF(VLOOKUP($A23,'Round 3'!$A$7:$J$206,COLUMN('Round 1'!$H$7),0),1,NA())),0,1),IF(ISNA(IF(VLOOKUP($A23,'Final Round'!$A$14:$K$18,1,0),1,NA())),0,1))) -> 3 | H23: =IF(ISBLANK($A23),"",IF(ISERROR(VLOOKUP($A23,'Round 1'!$A$7:$I$206,COLUMN('Round 1'!$G$7),0)),0,VLOOKUP($A23,'Round 1'!$A$7:$I$206,COLUMN('Round 1'!$G$7),0))+IF(ISERROR(VLOOKUP($A23,'Round 2'!$A$7:$I$206,COLUMN('Round 2'!$G$7),0)),0,VLOOKUP($A23,'Round 2'!$A$7:$I$206,COLUMN('Round 2'!$G$7),0))+IF(ISERROR(VLOOKUP($A23,'Round 3'!$A$7:$I$206,COLUMN('Round 3'!$G$7),0)),0,VLOOKUP($A23,'Round 3'!$A$7:$I$206,COLUMN('Round 3'!$G$7),0))) -> 0 | I23: =IF(ISBLANK($A23),"",IF(ISERROR(VLOOKUP($A23,'Round 1'!$A$7:$I$206,COLUMN('Round 1'!$F$7),0)),0,VLOOKUP($A23,'Round 1'!$A$7:$I$206,COLUMN('Round 1'!$F$7),0))+IF(ISERROR(VLOOKUP($A23,'Round 2'!$A$7:$I$206,COLUMN('Round 2'!$F$7),0)),0,VLOOKUP($A23,'Round 2'!$A$7:$I$206,COLUMN('Round 2'!$F$7),0))+IF(ISERROR(VLOOKUP($A23,'Round 3'!$A$7:$I$206,COLUMN('Round 3'!$F$7),0)),0,VLOOKUP($A23,'Round 3'!$A$7:$I$206,COLUMN('Round 3'!$F$7),0))) -> 2.5 | J23: =IF(ISBLANK($A23),"",IF(ISERROR(VLOOKUP($A23,'Round 1'!$A$7:$I$206,COLUMN('Round 1'!$H$7),0)),0,VLOOKUP($A23,'Round 1'!$A$7:$I$206,COLUMN('Round 1'!$H$7),0))+IF(ISERROR(VLOOKUP($A23,'Round 2'!$A$7:$I$206,COLUMN('Round 2'!$H$7),0)),0,VLOOKUP($A23,'Round 2'!$A$7:$I$206,COLUMN('Round 2'!$H$7),0))+IF(ISERROR(VLOOKUP($A23,'Round 3'!$A$7:$I$206,COLUMN('Round 3'!$H$7),0)),0,VLOOKUP($A23,'Round 3'!$A$7:$I$206,COLUMN('Round 3'!$H$7),0))) -> 102 | K23: =IF(ISBLANK(A23),"",RANK(P23,$P$7:$P$206)) -> 17 | L23: =IF(ISBLANK($G23),IF($K23>5,"",IF(AND(ISNA(MATCH(K23+1,$K$7:$K$206,0)),$K23<$A$4),"TIE","")),"DQ") | N23: =IF(ISBLANK($G23),$R23,"DQ") -> 17 | O23: =IF(ISBLANK(A23),"",$H23*$O$6+$I23) -> 2.5 | P23: =IF(ISBLANK(A23),"",$O23*10*$P$6+$J23) -> 4627 | Q23: =IF(ISBLANK($G23),IF(ISBLANK($A23),-10,$P23*$Q$6+IF($M23>0,$Q$6-1-$M23,0)),-1) -> 4627 | R23: =IF(ISBLANK($A23),"",RANK($Q23,$Q$7:$Q$206)) -> 17 | S23: =IF(ISNA(MATCH($R23+1,$R$7:$R$206,0)),IF($R23=MAX($A$7:$A$206),$R23,-1),$R23) -> 17 | T23: =$A23 -> 5 | U23: =IF(N('Final Round'!$J$14)>0,IF(ISBLANK($A23),"",IF($N23>5,$N23,VLOOKUP($A23,'Final Round'!$A$14:$K$18,COLUMN('Final Round'!$J$1),0))),"") -> 17 | V23: =IF(ISNUMBER($U23),$U23,$R23) -> 17 | W23: =IF(ISBLANK($A23),"",($V$6-$V23)*$W$6+$W$6-$A23) -> 556 | X23: =IF(ISBLANK($A23),"",RANK($W23,$W$7:$W$206)) -> 17 | Y23: =$A23 -> 5 | Z23: =IF($U23="",$N23,$U23) -> 17 | AA23: =IF($U23<6,INDEX($AA$1:$AA$5,$Z23)*$Z$2,0) -> 0 | AB23: =IF(ISBLANK($A23),"",5+4*(I23+IF(AA23=0,0,VLOOKUP($A23,'Final Round'!$A$14:$K$18,COLUMN('Final Round'!$G$1),0)))+8*(H23+IF(AA23=0,0,IF(VLOOKUP($A23,'Final Round'!$A$14:$K$18,COLUMN('Final Round'!$J$1),0)=1,1,0)))+$AA23) -> 15
