Workbook
Name MPlayerNo: Methuselahs!$A$7:$A$206

Sheet Instructions
A1: The Archon (v1.5l)
A2: The official tournament tracking system for "Vampire: The Eternal Struggle" | E2: originally from the V:TES Rulemonger Website (http://www.geocities.com/vtesrep), updated with genetic results: https://www.vekn.net/forum/generic-v-tes-discussion/77200
A4: The Archon was written by Stephen "The Evil One" Buonocore, and maintained by L. Scott Johnson.
A5: The Archon is currently maintained by Vincent Ripoll.
A6: With updates by Robert Goudie and Pascal Bertrand. Additional seatings provided by Lionel Panhaleux.
A8: The latest version of The Archon is available for download at
A9: https://www.vekn.net/downloads
A11: What's New:
B12: V1.5l | C12: Fixed GW flag on the final round when there is a tie. Added seatings for 3R+F up to 300 players.
B13: V1.5k | C13: Added Grand Prix level
B14: V1.5j | C14: Improved seating charts for 3R+F 9-57 players (thanks to Lionel Panhaleux).
B15: V1.5i | C15: Fixed error in 3R+F for 19 players (players 13 and 14 were inverted during R1) and 2R+F for 44 players (the seating introduced in v1.5h was worse).
B16: V1.5h | C16: Fixed unoptimal seatings for 3R+F for 49 players to 200 players, and added seatings for 201-220 players. Reverted to optimal seating for 17 players. Fixed unoptimal seatings for 2R+F for 21 players to 50 players, and added seatings for 51-1210 players.
B17: V1.5g | C17: Fixed unoptimal seatings for 2R+F and 3R+F
B18: V1.5f | C18: Fixed unoptimal seatings introduced in V1.5e due to a flaw in the validation of the new results and some mistakes when reporting the results.
B19: V1.5e | C19: The Archon is now available in xslx (Microsoft Excel) and ods (Libroffice) formats. The old xls format must not be used anymore. Updated the urls. Fixed reversed predator-prey relationships that are authorized by rules 1 and 6, but that should be more important than rule 8 for instance. This applies to the following 3R+F seatings: 17, 19, 20, 21, 23, 27, 31 players
B20: V1.5d | C20: Now using the optimised seatings computed by Vincent (calculations ongoing, current date: 28/06/2015)
B21: V1.5c | C21: Increased the max number of players for 2R+F events, fixed a bug in the 3rd round page in 2R+F events. (Vincent Ripoll). Upgraded the seating for 21-25 players in 2R+F events (Pascal Bertrand) (currently working on the remaining)
B22: V1.5b | C22: Fixed a bug in the chart that made Optimal Seating charts fail to update in OpenOffice.org or LibreOffice. (Jussi Hattara)
B23: V1.5a | C23: Tournament Info sheet made more similar to the Event Registration page of the vekn.net website, where the Event should be registered. Added coefficient for National Qualifiers (0).
... B36: v1.1 | C36: Use Game Wins per the January 2002 update of the V:EKN rules. Enhanced support of optimal seating charts. Corrected 18-player chart.
A39: Instructions for use:
A41: General Instructions
B42: 1 | C42: Welcome to The Archon, the official tournament tracking system for "Vampire: The Eternal Struggle" ("V:TES"). When your tournament is completed and all information within The Archon has been entered, you should immediately send this entire completed workbook to the V:EKN (the "Vampire: Elder Kindred Network"), which is the Official International Players' Organization for V:TES. By sending this to the V:EKN, your players' official V:TES ratings will be updated. See the "Post-Tournament Procedures" below for submitting the results.
C44: Please visit the VEKN web site for all the official information about V:TES and the V:EKN:
C45: https://www.vekn.net/
C47: For information on how to run an officially sanctioned V:TES tournament, including the "Request for Sanctioning", "Request for Prize Support", and all other relevant information, please visit the V:TES website, and go to this page:
C48: https://www.vekn.net/how-to-run-a-v-tes-tournament
C50: Officially sanctioned V:TES Tournaments are run according to the V:EKN Tournament Rules. Also, all current V:TES Rules, Rulings, Errata, and Clarifications must be followed. These can be found on the VEKN website on these pages:
C51: https://www.vekn.net/tournament-rules
C52: https://www.vekn.net/rulebook
C53: https://www.vekn.net/general-rulings
C54: https://www.vekn.net/card-rulings
B56: =B42+1 -> 2 | C56: The archon is available in XSLX and ODS format. If you use Microsoft Excel, use the XSLX format; otherwise use the ODS format. Do not save it under another format (eg. If you use the XSLX format, save it only in that format).
B58: =B56+1 -> 3 | C58: Helpful instructions have been embedded in some cells of this spreadsheet, so that you do not have to refer back to this page often. Please point the cursor to the "little red triangle" in the upper-right corner of some cells for help. To see how this works, point to the triangle to the left of this paragraph.
B60: =B58+1 -> 4 | C60: You should save this spreadsheet file under a new name (like the name of your tournament) before beginning to use it. By doing so, you can use this blank spreadsheet again for future tournaments. Use the Menu Bar selection, FILE, then select SAVE AS and enter a new name. After doing this, you can continue to use this spreadsheet to track your V:TES tournament.
B62: =B60+1 -> 5 | C62: This system implements the V:EKN Sanctioned Tournament Rules, and therefore makes certain assumptions (e.g. all tables will have 4 or (optimally) 5 players). Use V:EKN Tournament Rules when utilizing this system.
A65: Setting up and Tracking Your Tournament
B66: =B62+1 -> 6 | C66: Enter the tournament information into the "Tournament Info" sheet.
B67: - | C67: This is freeform text, but is used in other sheets, so please be accurate. The VEKN numbers of the organizer and judges are used for qualification.
...

Sheet Tournament Info
A1: =IF(ISBLANK(B3),"Vampire: The Eternal Struggle Tournament",B3) -> VtES Finnish Nationals 2026
A3: Event Name: | B3: VtES Finnish Nationals 2026
A4: Event Date (DD-MON-YY): | B4: 46137
A5: Date Report due at V:EKN: | B5: =IF(B4="","",B4+8) -> 46145
A6: Organizer: | B6: Tommi Hakomaa | C6: 3530067
A7: City: | B7: Vantaa
A8: Format (Constructed/Limited): | B8: Constructed | D8: Constructed | E8: Limited
A9: Level (Normal/Qualifier/Championship/Nationals) | B9: National Championship | D9: Standard Constructed | E9: National Qualifier | F9: National Championship | G9: Continental Qualifier | H9: Continental Championship | I9: Grand Prix | J9: Storyline | K9: Limited | L9: Demo | M9: Unsanctioned Tournament
A10: Number of Players: | B10: =Methuselahs!$A$4 -> 41 | D10: 0 | E10: 0 | F10: 0.25 | G10: 0.25 | H10: 1 | I10: 0 | J10: 0 | K10: 0 | L10: 0 | M10: 0
A11: Number of Rounds (including final): | B11: 4 | D11: 3 | E11: 4
A12: Number of Event Matches: | B12: =MAX('Round 1'!D7:D206)+MAX('Round 2'!D7:D206)+MAX('Round 3'!D7:D206)+1 -> 28
A13: Number of New Members:
A14: Number of Warnings Issued:
A15: Number of Disqualifications:
A16: Multi-Judge System Used? | B16: Yes
A17: Head Judge: | B17: Teemu Sainomaa | C17: 3070069
A18: Assistant Judges: | B18: Tommi Hakomaa | C18: 3530067
B19: Akseli Jalava | C19: 3530057
B20: Jani Malmi | C20: 9350012
B21: Teemu Pulkkinen | C21: 4970005
B22: Michael Holmström | C22: 3382224
C23: =IF(ISBLANK(B23),"","VEKN id")
C24: =IF(ISBLANK(B24),"","VEKN id")
C25: =IF(ISBLANK(B25),"","VEKN id")
C26: =IF(ISBLANK(B26),"","VEKN id")

Sheet Methuselahs
A1: =IF(ISBLANK('Tournament Info'!B3),"Vampire: The Eternal Struggle Tournament",'Tournament Info'!B3) -> VtES Finnish Nationals 2026 | Z1: =HLOOKUP('Tournament Info'!$B$9,'Tournament Info'!$D$9:$M$10,2,FALSE) -> 0.25 | AA1: 90
P2: champ | Q2: nat | R2: norm | S2: qual | T2: reg | Y2: Coef: | Z2: =LOG(MAX($A$4*$A$4,1),15)-1+$Z$1 -> 1.9926169 | AA2: 30
A3: Player Information | O3: 0 | P3: 1 | Q3: 0.25 | R3: 0 | S3: 0.25 | T3: 0 | AA3: 30
A4: =COUNT($A$7:$A$306) -> 41 | B4: players entered | AA4: 30
A5: Player | B5: Player | C5: Player | D5: Player | E5: V:EKN | G5: DQ | H5: Results - Rnds 1, 2, 3 | L5: Status | M5: Coin | N5: Adjusted | O5: VP | P5: TP | Q5: Coin | R5: Real | S5: Flag | T5: Player | U5: Final | V5: CurRank | W5: P# ties | X5: Distinct | Y5: Player | Z5: Final | AA5: 30 | AB5: Rating
A6: Num. | B6: First Name | C6: Last Name | D6: City | E6: Num. | F6: # rnds | G6: Flag | H6: GWs | I6: VPs | J6: TPs | K6: Rank | L6: for Final | M6: Ranking | N6: Rank | O6: =IF(ISERR(MAX($I$7:$I$306)),1,MAX($I$7:$I$306)+1) -> 9.5 | P6: =IF(ISERR(MAX($J$7:$J$306)),1,MAX($J$7:$J$306)+1) -> 169 | Q6: =IF(ISERR(MAX($M$7:$M$306)),1,MAX($M$7:$M$306)+1) -> 3 | R6: Rank | S6: Ties | T6: Num | U6: Rank | V6: =IF(ISERR(MAX($V$7:$V$306)),1,MAX($V$7:$V$306)+1) -> 42 | W6: =MAX(MPlayerNo)+1 -> 42 | X6: Rank | Y6: Num | Z6: Rank | AA6: Bonus | AB6: Points
A7: 34 | B7: Aki | C7: Puolakka | E7: 120 | F7: =IF(ISBLANK($A7),"",SUM(IF(ISNA(IF(VLOOKUP($A7,'Round 1'!$A$7:$J$306,COLUMN('Round 1'!$H$7),FALSE),1,NA())),0,1),IF(ISNA(IF(VLOOKUP($A7,'Round 2'!$A$7:$J$306,COLUMN('Round 1'!$H$7),FALSE),1,NA())),0,1),IF(ISNA(IF(VLOOKUP($A7,'Round 3'!$A$7:$J$306,COLUMN('Round 1'!$H$7),FALSE),1,NA())),0,1),IF(ISNA(IF(VLOOKUP($A7,'Final Round'!$A$14:$K$18,1,FALSE),1,NA())),0,1))) -> 3 | H7: =IF(ISBLANK($A7),"",IF(ISERROR(VLOOKUP($A7,'Round 1'!$A$7:$I$306,COLUMN('Round 1'!$G$7),FALSE)),0,VLOOKUP($A7,'Round 1'!$A$7:$I$306,COLUMN('Round 1'!$G$7),FALSE))+IF(ISERROR(VLOOKUP($A7,'Round 2'!$A$7:$I$306,COLUMN('Round 2'!$G$7),FALSE)),0,VLOOKUP($A7,'Round 2'!$A$7:$I$306,COLUMN('Round 2'!$G$7),FALSE))+IF(ISERROR(VLOOKUP($A7,'Round 3'!$A$7:$I$306,COLUMN('Round 3'!$G$7),FALSE)),0,VLOOKUP($A7,'Round 3'!$A$7:$I$306,COLUMN('Round 3'!$G$7),FALSE))) -> 0 | I7: =IF(ISBLANK($A7),"",IF(ISERROR(VLOOKUP($A7,'Round 1'!$A$7:$I$306,COLUMN('Round 1'!$F$7),FALSE)),0,VLOOKUP($A7,'Round 1'!$A$7:$I$306,COLUMN('Round 1'!$F$7),FALSE))+IF(ISERROR(VLOOKUP($A7,'Round 2'!$A$7:$I$306,COLUMN('Round 2'!$F$7),FALSE)),0,VLOOKUP($A7,'Round 2'!$A$7:$I$306,COLUMN('Round 2'!$F$7),FALSE))+IF(ISERROR(VLOOKUP($A7,'Round 3'!$A$7:$I$306,COLUMN('Round 3'!$F$7),FALSE)),0,VLOOKUP($A7,'Round 3'!$A$7:$I$306,COLUMN('Round 3'!$F$7),FALSE))) -> 2.5 | J7: =IF(ISBLANK($A7),"",IF(ISERROR(VLOOKUP($A7,'Round 1'!$A$7:$I$306,COLUMN('Round 1'!$H$7),FALSE)),0,VLOOKUP($A7,'Round 1'!$A$7:$I$306,COLUMN('Round 1'!$H$7),FALSE))+IF(ISERROR(VLOOKUP($A7,'Round 2'!$A$7:$I$306,COLUMN('Round 2'!$H$7),FALSE)),0,VLOOKUP($A7,'Round 2'!$A$7:$I$306,COLUMN('Round 2'!$H$7),FALSE))+IF(ISERROR(VLOOKUP($A7,'Round 3'!$A$7:$I$306,COLUMN('Round 3'!$H$7),FALSE)),0,VLOOKUP($A7,'Round 3'!$A$7:$I$306,COLUMN('Round 3'!$H$7),FALSE))) -> 114 | K7: =IF(ISBLANK(A7),"",RANK(P7,$P$7:$P$306)) -> 20 | L7: =IF(ISBLANK($G7),IF($K7>5,"",IF(AND(ISNA(MATCH(K7+1,$K$7:$K$306,0)),$K7<$A$4),"TIE","")),"DQ") | N7: =IF(ISBLANK($G7),$R7,"DQ") -> 20 | O7: =IF(ISBLANK(A7),"",$H7*$O$6+$I7) -> 2.5 | P7: =IF(ISBLANK(A7),"",$O7*10*$P$6+$J7) -> 4339 | Q7: =IF(ISBLANK($G7),IF(ISBLANK($A7),-10,$P7*$Q$6+IF($M7>0,$Q$6-1-$M7,0)),-1) -> 13017 | R7: =IF(ISBLANK($A7),"",RANK($Q7,$Q$7:$Q$306)) -> 20 | S7: =IF(ISNA(MATCH($R7+1,$R$7:$R$306,0)),IF($R7=MAX($A$7:$A$306),$R7,-1),$R7) -> 20 | T7: =$A7 -> 34 | U7: =IF(N('Final Round'!$J$14)>0,IF(ISBLANK($A7),"",IF($N7>5,$N7,VLOOKUP($A7,'Final Round'!$A$14:$K$18,COLUMN('Final Round'!$J$1),FALSE))),"") -> 20 | V7: =IF(ISNUMBER($U7),$U7,$R7) -> 20 | W7: =IF(ISBLANK($A7),"",($V$6-$V7)*$W$6+$W$6-$A7) -> 932 | X7: =IF(ISBLANK($A7),"",RANK($W7,$W$7:$W$306)) -> 20 | Y7: =$A7 -> 34 | Z7: =IF($U7="",$N7,$U7) -> 20 | AA7: =IF($U7<6,INDEX($AA$1:$AA$5,$Z7)*$Z$2,0) -> 0 | AB7: =IF(ISBLANK($A7),"",5+4*(I7+IF(AA7=0,0,VLOOKUP($A7,'Final Round'!$A$14:$K$18,COLUMN('Final Round'!$G$1),FALSE)))+8*(H7+IF(AA7=0,0,IF(VLOOKUP($A7,'Final Round'!$A$14:$K$18,COLUMN('Final Round'!$J$1),FALSE)=1,1,0)))+$AA7) -> 15
A8: 25 | B8: Akseli | C8: Jalava | E8: 122 | F8: =IF(ISBLANK($A8),"",SUM(IF(ISNA(IF(VLOOKUP($A8,'Round 1'!$A$7:$J$306,COLUMN('Round 1'!$H$7),FALSE),1,NA())),0,1),IF(ISNA(IF(VLOOKUP($A8,'Round 2'!$A$7:$J$306,COLUMN('Round 1'!$H$7),FALSE),1,NA())),0,1),IF(ISNA(IF(VLOOKUP($A8,'Round 3'!$A$7:$J$306,COLUMN('Round 1'!$H$7),FALSE),1,NA())),0,1),IF(ISNA(IF(VLOOKUP($A8,'Final Round'!$A$14:$K$18,1,FALSE),1,NA())),0,1))) -> 3 | H8: =IF(ISBLANK($A8),"",IF(ISERROR(VLOOKUP($A8,'Round 1'!$A$7:$I$306,COLUMN('Round 1'!$G$7),FALSE)),0,VLOOKUP($A8,'Round 1'!$A$7:$I$306,COLUMN('Round 1'!$G$7),FALSE))+IF(ISERROR(VLOOKUP($A8,'Round 2'!$A$7:$I$306,COLUMN('Round 2'!$G$7),FALSE)),0,VLOOKUP($A8,'Round 2'!$A$7:$I$306,COLUMN('Round 2'!$G$7),FALSE))+IF(ISERROR(VLOOKUP($A8,'Round 3'!$A$7:$I$306,COLUMN('Round 3'!$G$7),FALSE)),0,VLOOKUP($A8,'Round 3'!$A$7:$I$306,COLUMN('Round 3'!$G$7),FALSE))) -> 0 | I8: =IF(ISBLANK($A8),"",IF(ISERROR(VLOOKUP($A8,'Round 1'!$A$7:$I$306,COLUMN('Round 1'!$F$7),FALSE)),0,VLOOKUP($A8,'Round 1'!$A$7:$I$306,COLUMN('Round 1'!$F$7),FALSE))+IF(ISERROR(VLOOKUP($A8,'Round 2'!$A$7:$I$306,COLUMN('Round 2'!$F$7),FALSE)),0,VLOOKUP($A8,'Round 2'!$A$7:$I$306,COLUMN('Round 2'!$F$7),FALSE))+IF(ISERROR(VLOOKUP($A8,'Round 3'!$A$7:$I$306,COLUMN('Round 3'!$F$7),FALSE)),0,VLOOKUP($A8,'Round 3'!$A$7:$I$306,COLUMN('Round 3'!$F$7),FALSE))) -> 2 | J8: =IF(ISBLANK($A8),"",IF(ISERROR(VLOOKUP($A8,'Round 1'!$A$7:$I$306,COLUMN('Round 1'!$H$7),FALSE)),0,VLOOKUP($A8,'Round 1'!$A$7:$I$306,COLUMN('Round 1'!$H$7),FALSE))+IF(ISERROR(VLOOKUP($A8,'Round 2'!$A$7:$I$306,COLUMN('Round 2'!$H$7),FALSE)),0,VLOOKUP($A8,'Round 2'!$A$7:$I$306,COLUMN('Round 2'!$H$7),FALSE))+IF(ISERROR(VLOOKUP($A8,'Round 3'!$A$7:$I$306,COLUMN('Round 3'!$H$7),FALSE)),0,VLOOKUP($A8,'Round 3'!$A$7:$I$306,COLUMN('Round 3'!$H$7),FALSE))) -> 114 | K8: =IF(ISBLANK(A8),"",RANK(P8,$P$7:$P$306)) -> 22 | L8: =IF(ISBLANK($G8),IF($K8>5,"",IF(AND(ISNA(MATCH(K8+1,$K$7:$K$306,0)),$K8<$A$4),"TIE","")),"DQ") | N8: =IF(ISBLANK($G8),$R8,"DQ") -> 22 | O8: =IF(ISBLANK(A8),"",$H8*$O$6+$I8) -> 2 | P8: =IF(ISBLANK(A8),"",$O8*10*$P$6+$J8) -> 3494 | Q8: =IF(ISBLANK($G8),IF(ISBLANK($A8),-10,$P8*$Q$6+IF($M8>0,$Q$6-1-$M8,0)),-1) -> 10482 | R8: =IF(ISBLANK($A8),"",RANK($Q8,$Q$7:$Q$306)) -> 22 | S8: =IF(ISNA(MATCH($R8+1,$R$7:$R$306,0)),IF($R8=MAX($A$7:$A$306),$R8,-1),$R8) -> 22 | T8: =$A8 -> 25 | U8: =IF(N('Final Round'!$J$14)>0,IF(ISBLANK($A8),"",IF($N8>5,$N8,VLOOKUP($A8,'Final Round'!$A$14:$K$18,COLUMN('Final Round'!$J$1),FALSE))),"") -> 22 | V8: =IF(ISNUMBER($U8),$U8,$R8) -> 22 | W8: =IF(ISBLANK($A8),"",($V$6-$V8)*$W$6+$W$6-$A8) -> 857 | X8: =IF(ISBLANK($A8),"",RANK($W8,$W$7:$W$306)) -> 22 | Y8: =$A8 -> 25 | Z8: =IF($U8="",$N8,$U8) -> 22 | AA8: =IF($U8<6,INDEX($AA$1:$AA$5,$Z8)*$Z$2,0) -> 0 | AB8: =IF(ISBLANK($A8),"",5+4*(I8+IF(AA8=0,0,VLOOKUP($A8,'Final Round'!$A$14:$K$18,COLUMN('Final Round'!$G$1),FALSE)))+8*(H8+IF(AA8=0,0,IF(VLOOKUP($A8,'Final Round'!$A$14:$K$18,COLUMN('Final Round'!$J$1),FALSE)=1,1,0)))+$AA8) -> 13
A9: 8 | B9: Aleksi | C9: Salonen | E9: 135 | F9: =IF(ISBLANK($A9),"",SUM(IF(ISNA(IF(VLOOKUP($A9,'Round 1'!$A$7:$J$306,COLUMN('Round 1'!$H$7),FALSE),1,NA())),0,1),IF(ISNA(IF(VLOOKUP($A9,'Round 2'!$A$7:$J$306,COLUMN('Round 1'!$H$7),FALSE),1,NA())),0,1),IF(ISNA(IF(VLOOKUP($A9,'Round 3'!$A$7:$J$306,COLUMN('Round 1'!$H$7),FALSE),1,NA())),0,1),IF(ISNA(IF(VLOOKUP($A9,'Final Round'!$A$14:$K$18,1,FALSE),1,NA())),0,1))) -> 3 | H9: =IF(ISBLANK($A9),"",IF(ISERROR(VLOOKUP($A9,'Round 1'!$A$7:$I$306,COLUMN('Round 1'!$G$7),FALSE)),0,VLOOKUP($A9,'Round 1'!$A$7:$I$306,COLUMN('Round 1'!$G$7),FALSE))+IF(ISERROR(VLOOKUP($A9,'Round 2'!$A$7:$I$306,COLUMN('Round 2'!$G$7),FALSE)),0,VLOOKUP($A9,'Round 2'!$A$7:$I$306,COLUMN('Round 2'!$G$7),FALSE))+IF(ISERROR(VLOOKUP($A9,'Round 3'!$A$7:$I$306,COLUMN('Round 3'!$G$7),FALSE)),0,VLOOKUP($A9,'Round 3'!$A$7:$I$306,COLUMN('Round 3'!$G$7),FALSE))) -> 0 | I9: =IF(ISBLANK($A9),"",IF(ISERROR(VLOOKUP($A9,'Round 1'!$A$7:$I$306,COLUMN('Round 1'!$F$7),FALSE)),0,VLOOKUP($A9,'Round 1'!$A$7:$I$306,COLUMN('Round 1'!$F$7),FALSE))+IF(ISERROR(VLOOKUP($A9,'Round 2'!$A$7:$I$306,COLUMN('Round 2'!$F$7),FALSE)),0,VLOOKUP($A9,'Round 2'!$A$7:$I$306,COLUMN('Round 2'!$F$7),FALSE))+IF(ISERROR(VLOOKUP($A9,'Round 3'!$A$7:$I$306,COLUMN('Round 3'!$F$7),FALSE)),0,VLOOKUP($A9,'Round 3'!$A$7:$I$306,COLUMN('Round 3'!$F$7),FALSE))) -> 0 | J9: =IF(ISBLANK($A9),"",IF(ISERROR(VLOOKUP($A9,'Round 1'!$A$7:$I$306,COLUMN('Round 1'!$H$7),FALSE)),0,VLOOKUP($A9,'Round 1'!$A$7:$I$306,COLUMN('Round 1'!$H$7),FALSE))+IF(ISERROR(VLOOKUP($A9,'Round 2'!$A$7:$I$306,COLUMN('Round 2'!$H$7),FALSE)),0,VLOOKUP($A9,'Round 2'!$A$7:$I$306,COLUMN('Round 2'!$H$7),FALSE))+IF(ISERROR(VLOOKUP($A9,'Round 3'!$A$7:$I$306,COLUMN('Round 3'!$H$7),FALSE)),0,VLOOKUP($A9,'Round 3'!$A$7:$I$306,COLUMN('Round 3'!$H$7),FALSE))) -> 66 | K9: =IF(ISBLANK(A9),"",RANK(P9,$P$7:$P$306)) -> 34 | L9: =IF(ISBLANK($G9),IF($K9>5,"",IF(AND(ISNA(MATCH(K9+1,$K$7:$K$306,0)),$K9<$A$4),"TIE","")),"DQ") | N9: =IF(ISBLANK($G9),$R9,"DQ") -> 34 | O9: =IF(ISBLANK(A9),"",$H9*$O$6+$I9) -> 0 | P9: =IF(ISBLANK(A9),"",$O9*10*$P$6+$J9) -> 66 | Q9: =IF(ISBLANK($G9),IF(ISBLANK($A9),-10,$P9*$Q$6+IF($M9>0,$Q$6-1-$M9,0)),-1) -> 198 | R9: =IF(ISBLANK($A9),"",RANK($Q9,$Q$7:$Q$306)) -> 34 | S9: =IF(ISNA(MATCH($R9+1,$R$7:$R$306,0)),IF($R9=MAX($A$7:$A$306),$R9,-1),$R9) -> -1 | T9: =$A9 -> 8 | U9: =IF(N('Final Round'!$J$14)>0,IF(ISBLANK($A9),"",IF($N9>5,$N9,VLOOKUP($A9,'Final Round'!$A$14:$K$18,COLUMN('Final Round'!$J$1),FALSE))),"") -> 34 | V9: =IF(ISNUMBER($U9),$U9,$R9) -> 34 | W9: =IF(ISBLANK($A9),"",($V$6-$V9)*$W$6+$W$6-$A9) -> 370 | X9: =IF(ISBLANK($A9),"",RANK($W9,$W$7:$W$306)) -> 35 | Y9: =$A9 -> 8 | Z9: =IF($U9="",$N9,$U9) -> 34 | AA9: =IF($U9<6,INDEX($AA$1:$AA$5,$Z9)*$Z$2,0) -> 0 | AB9: =IF(ISBLANK($A9),"",5+4*(I9+IF(AA9=0,0,VLOOKUP($A9,'Final Round'!$A$14:$K$18,COLUMN('Final Round'!$G$1),FALSE)))+8*(H9+IF(AA9=0,0,IF(VLOOKUP($A9,'Final Round'!$A$14:$K$18,COLUMN('Final Round'!$J$1),FALSE)=1,1,0)))+$AA9) -> 5
A10: 6 | B10: Antti | C10: Penttilä | E10: 106 | F10: =IF(ISBLANK($A10),"",SUM(IF(ISNA(IF(VLOOKUP($A10,'Round 1'!$A$7:$J$306,COLUMN('Round 1'!$H$7),FALSE),1,NA())),0,1),IF(ISNA(IF(VLOOKUP($A10,'Round 2'!$A$7:$J$306,COLUMN('Round 1'!$H$7),FALSE),1,NA())),0,1),IF(ISNA(IF(VLOOKUP($A10,'Round 3'!$A$7:$J$306,COLUMN('Round 1'!$H$7),FALSE),1,NA())),0,1),IF(ISNA(IF(VLOOKUP($A10,'Final Round'!$A$14:$K$18,1,FALSE),1,NA())),0,1))) -> 3 | H10: =IF(ISBLANK($A10),"",IF(ISERROR(VLOOKUP($A10,'Round 1'!$A$7:$I$306,COLUMN('Round 1'!$G$7),FALSE)),0,VLOOKUP($A10,'Round 1'!$A$7:$I$306,COLUMN('Round 1'!$G$7),FALSE))+IF(ISERROR(VLOOKUP($A10,'Round 2'!$A$7:$I$306,COLUMN('Round 2'!$G$7),FALSE)),0,VLOOKUP($A10,'Round 2'!$A$7:$I$306,COLUMN('Round 2'!$G$7),FALSE))+IF(ISERROR(VLOOKUP($A10,'Round 3'!$A$7:$I$306,COLUMN('Round 3'!$G$7),FALSE)),0,VLOOKUP($A10,'Round 3'!$A$7:$I$306,COLUMN('Round 3'!$G$7),FALSE))) -> 1 | I10: =IF(ISBLANK($A10),"",IF(ISERROR(VLOOKUP($A10,'Round 1'!$A$7:$I$306,COLUMN('Round 1'!$F$7),FALSE)),0,VLOOKUP($A10,'Round 1'!$A$7:$I$306,COLUMN('Round 1'!$F$7),FALSE))+IF(ISERROR(VLOOKUP($A10,'Round 2'!$A$7:$I$306,COLUMN('Round 2'!$F$7),FALSE)),0,VLOOKUP($A10,'Round 2'!$A$7:$I$306,COLUMN('Round 2'!$F$7),FALSE))+IF(ISERROR(VLOOKUP($A10,'Round 3'!$A$7:$I$306,COLUMN('Round 3'!$F$7),FALSE)),0,VLOOKUP($A10,'Round 3'!$A$7:$I$306,COLUMN('Round 3'!$F$7),FALSE))) -> 5.5 | J10: =IF(ISBLANK($A10),"",IF(ISERROR(VLOOKUP($A10,'Round 1'!$A$7:$I$306,COLUMN('Round 1'!$H$7),FALSE)),0,VLOOKUP($A10,'Round 1'!$A$7:$I$306,COLUMN('Round 1'!$H$7),FALSE))+IF(ISERROR(VLOOKUP($A10,'Round 2'!$A$7:$I$306,COLUMN('Round 2'!$H$7),FALSE)),0,VLOOKUP($A10,'Round 2'!$A$7:$I$306,COLUMN('Round 2'!$H$7),FALSE))+IF(ISERROR(VLOOKUP($A10,'Round 3'!$A$7:$I$306,COLUMN('Round 3'!$H$7),FALSE)),0,VLOOKUP($A10,'Round 3'!$A$7:$I$306,COLUMN('Round 3'!$H$7),FALSE))) -> 162 | K10: =IF(ISBLANK(A10),"",RANK(P10,$P$7:$P$306)) -> 6 | L10: =IF(ISBLANK($G10),IF($K10>5,"",IF(AND(ISNA(MATCH(K10+1,$K$7:$K$306,0)),$K10<$A$4),"TIE","")),"DQ") | N10: =IF(ISBLANK($G10),$R10,"DQ") -> 6 | O10: =IF(ISBLANK(A10),"",$H10*$O$6+$I10) -> 15 | P10: =IF(ISBLANK(A10),"",$O10*10*$P$6+$J10) -> 25512 | Q10: =IF(ISBLANK($G10),IF(ISBLANK($A10),-10,$P10*$Q$6+IF($M10>0,$Q$6-1-$M10,0)),-1) -> 76536 | R10: =IF(ISBLANK($A10),"",RANK($Q10,$Q$7:$Q$306)) -> 6 | S10: =IF(ISNA(MATCH($R10+1,$R$7:$R$306,0)),IF($R10=MAX($A$7:$A$306),$R10,-1),$R10) -> 6 | T10: =$A10 -> 6 | U10: =IF(N('Final Round'!$J$14)>0,IF(ISBLANK($A10),"",IF($N10>5,$N10,VLOOKUP($A10,'Final Round'!$A$14:$K$18,COLUMN('Final Round'!$J$1),FALSE))),"") -> 6 | V10: =IF(ISNUMBER($U10),$U10,$R10) -> 6 | W10: =IF(ISBLANK($A10),"",($V$6-$V10)*$W$6+$W$6-$A10) -> 1548 | X10: =IF(ISBLANK($A10),"",RANK($W10,$W$7:$W$306)) -> 6 | Y10: =$A10 -> 6 | Z10: =IF($U10="",$N10,$U10) -> 6 | AA10: =IF($U10<6,INDEX($AA$1:$AA$5,$Z10)*$Z$2,0) -> 0 | AB10: =IF(ISBLANK($A10),"",5+4*(I10+IF(AA10=0,0,VLOOKUP($A10,'Final Round'!$A$14:$K$18,COLUMN('Final Round'!$G$1),FALSE)))+8*(H10+IF(AA10=0,0,IF(VLOOKUP($A10,'Final Round'!$A$14:$K$18,COLUMN('Final Round'!$J$1),FALSE)=1,1,0)))+$AA10) -> 35
A11: 7 | B11: Antti | C11: Kauhanen | E11: 134 | F11: =IF(ISBLANK($A11),"",SUM(IF(ISNA(IF(VLOOKUP($A11,'Round 1'!$A$7:$J$306,COLUMN('Round 1'!$H$7),FALSE),1,NA())),0,1),IF(ISNA(IF(VLOOKUP($A11,'Round 2'!$A$7:$J$306,COLUMN('Round 1'!$H$7),FALSE),1,NA())),0,1),IF(ISNA(IF(VLOOKUP($A11,'Round 3'!$A$7:$J$306,COLUMN('Round 1'!$H$7),FALSE),1,NA())),0,1),IF(ISNA(IF(VLOOKUP($A11,'Final Round'!$A$14:$K$18,1,FALSE),1,NA())),0,1))) -> 3 | H11: =IF(ISBLANK($A11),"",IF(ISERROR(VLOOKUP($A11,'Round 1'!$A$7:$I$306,COLUMN('Round 1'!$G$7),FALSE)),0,VLOOKUP($A11,'Round 1'!$A$7:$I$306,COLUMN('Round 1'!$G$7),FALSE))+IF(ISERROR(VLOOKUP($A11,'Round 2'!$A$7:$I$306,COLUMN('Round 2'!$G$7),FALSE)),0,VLOOKUP($A11,'Round 2'!$A$7:$I$306,COLUMN('Round 2'!$G$7),FALSE))+IF(ISERROR(VLOOKUP($A11,'Round 3'!$A$7:$I$306,COLUMN('Round 3'!$G$7),FALSE)),0,VLOOKUP($A11,'Round 3'!$A$7:$I$306,COLUMN('Round 3'!$G$7),FALSE))) -> 0 | I11: =IF(ISBLANK($A11),"",IF(ISERROR(VLOOKUP($A11,'Round 1'!$A$7:$I$306,COLUMN('Round 1'!$F$7),FALSE)),0,VLOOKUP($A11,'Round 1'!$A$7:$I$306,COLUMN('Round 1'!$F$7),FALSE))+IF(ISERROR(VLOOKUP($A11,'Round 2'!$A$7:$I$306,COLUMN('Round 2'!$F$7),FALSE)),0,VLOOKUP($A11,'Round 2'!$A$7:$I$306,COLUMN('Round 2'!$F$7),FALSE))+IF(ISERROR(VLOOKUP($A11,'Round 3'!$A$7:$I$306,COLUMN('Round 3'!$F$7),FALSE)),0,VLOOKUP($A11,'Round 3'!$A$7:$I$306,COLUMN('Round 3'!$F$7),FALSE))) -> 0 | J11: =IF(ISBLANK($A11),"",IF(ISERROR(VLOOKUP($A11,'Round 1'!$A$7:$I$306,COLUMN('Round 1'!$H$7),FALSE)),0,VLOOKUP($A11,'Round 1'!$A$7:$I$306,COLUMN('Round 1'!$H$7),FALSE))+IF(ISERROR(VLOOKUP($A11,'Round 2'!$A$7:$I$306,COLUMN('Round 2'!$H$7),FALSE)),0,VLOOKUP($A11,'Round 2'!$A$7:$I$306,COLUMN('Round 2'!$H$7),FALSE))+IF(ISERROR(VLOOKUP($A11,'Round 3'!$A$7:$I$306,COLUMN('Round 3'!$H$7),FALSE)),0,VLOOKUP($A11,'Round 3'!$A$7:$I$306,COLUMN('Round 3'!$H$7),FALSE))) -> 66 | K11: =IF(ISBLANK(A11),"",RANK(P11,$P$7:$P$306)) -> 34 | L11: =IF(ISBLANK($G11),IF($K11>5,"",IF(AND(ISNA(MATCH(K11+1,$K$7:$K$306,0)),$K11<$A$4),"TIE","")),"DQ") | N11: =IF(ISBLANK($G11),$R11,"DQ") -> 34 | O11: =IF(ISBLANK(A11),"",$H11*$O$6+$I11) -> 0 | P11: =IF(ISBLANK(A11),"",$O11*10*$P$6+$J11) -> 66 | Q11: =IF(ISBLANK($G11),IF(ISBLANK($A11),-10,$P11*$Q$6+IF($M11>0,$Q$6-1-$M11,0)),-1) -> 198 | R11: =IF(ISBLANK($A11),"",RANK($Q11,$Q$7:$Q$306)) -> 34 | S11: =IF(ISNA(MATCH($R11+1,$R$7:$R$306,0)),IF($R11=MAX($A$7:$A$306),$R11,-1),$R11) -> -1 | T11: =$A11 -> 7 | U11: =IF(N('Final Round'!$J$14)>0,IF(ISBLANK($A11),"",IF($N11>5,$N11,VLOOKUP($A11,'Final Round'!$A$14:$K$18,COLUMN('Final Round'!$J$1),FALSE))),"") -> 34 | V11: =IF(ISNUMBER($U11),$U11,$R11) -> 34 | W11: =IF(ISBLANK($A11),"",($V$6-$V11)*$W$6+$W$6-$A11) -> 371 | X11: =IF(ISBLANK($A11),"",RANK($W11,$W$7:$W$306)) -> 34 | Y11: =$A11 -> 7 | Z11: =IF($U11="",$N11,$U11) -> 34 | AA11: =IF($U11<6,INDEX($AA$1:$AA$5,$Z11)*$Z$2,0) -> 0 | AB11: =IF(ISBLANK($A11),"",5+4*(I11+IF(AA11=0,0,VLOOKUP($A11,'Final Round'!$A$14:$K$18,COLUMN('Final Round'!$G$1),FALSE)))+8*(H11+IF(AA11=0,0,IF(VLOOKUP($A11,'Final Round'!$A$14:$K$18,COLUMN('Final Round'!$J$1),FALSE)=1,1,0)))+$AA11) -> 5
A12: 2 | B12: Christian | C12: Nislev | E12: 131 | F12: =IF(ISBLANK($A12),"",SUM(IF(ISNA(IF(VLOOKUP($A12,'Round 1'!$A$7:$J$306,COLUMN('Round 1'!$H$7),FALSE),1,NA())),0,1),IF(ISNA(IF(VLOOKUP($A12,'Round 2'!$A$7:$J$306,COLUMN('Round 1'!$H$7),FALSE),1,NA())),0,1),IF(ISNA(IF(VLOOKUP($A12,'Round 3'!$A$7:$J$306,COLUMN('Round 1'!$H$7),FALSE),1,NA())),0,1),IF(ISNA(IF(VLOOKUP($A12,'Final Round'!$A$14:$K$18,1,FALSE),1,NA())),0,1))) -> 3 | H12: =IF(ISBLANK($A12),"",IF(ISERROR(VLOOKUP($A12,'Round 1'!$A$7:$I$306,COLUMN('Round 1'!$G$7),FALSE)),0,VLOOKUP($A12,'Round 1'!$A$7:$I$306,COLUMN('Round 1'!$G$7),FALSE))+IF(ISERROR(VLOOKUP($A12,'Round 2'!$A$7:$I$306,COLUMN('Round 2'!$G$7),FALSE)),0,VLOOKUP($A12,'Round 2'!$A$7:$I$306,COLUMN('Round 2'!$G$7),FALSE))+IF(ISERROR(VLOOKUP($A12,'Round 3'!$A$7:$I$306,COLUMN('Round 3'!$G$7),FALSE)),0,VLOOKUP($A12,'Round 3'!$A$7:$I$306,COLUMN('Round 3'!$G$7),FALSE))) -> 0 | I12: =IF(ISBLANK($A12),"",IF(ISERROR(VLOOKUP($A12,'Round 1'!$A$7:$I$306,COLUMN('Round 1'!$F$7),FALSE)),0,VLOOKUP($A12,'Round 1'!$A$7:$I$306,COLUMN('Round 1'!$F$7),FALSE))+IF(ISERROR(VLOOKUP($A12,'Round 2'!$A$7:$I$306,COLUMN('Round 2'!$F$7),FALSE)),0,VLOOKUP($A12,'Round 2'!$A$7:$I$306,COLUMN('Round 2'!$F$7),FALSE))+IF(ISERROR(VLOOKUP($A12,'Round 3'!$A$7:$I$306,COLUMN('Round 3'!$F$7),FALSE)),0,VLOOKUP($A12,'Round 3'!$A$7:$I$306,COLUMN('Round 3'!$F$7),FALSE))) -> 0.5 | J12: =IF(ISBLANK($A12),"",IF(ISERROR(VLOOKUP($A12,'Round 1'!$A$7:$I$306,COLUMN('Round 1'!$H$7),FALSE)),0,VLOOKUP($A12,'Round 1'!$A$7:$I$306,COLUMN('Round 1'!$H$7),FALSE))+IF(ISERROR(VLOOKUP($A12,'Round 2'!$A$7:$I$306,COLUMN('Round 2'!$H$7),FALSE)),0,VLOOKUP($A12,'Round 2'!$A$7:$I$306,COLUMN('Round 2'!$H$7),FALSE))+IF(ISERROR(VLOOKUP($A12,'Round 3'!$A$7:$I$306,COLUMN('Round 3'!$H$7),FALSE)),0,VLOOKUP($A12,'Round 3'!$A$7:$I$306,COLUMN('Round 3'!$H$7),FALSE))) -> 72 | K12: =IF(ISBLANK(A12),"",RANK(P12,$P$7:$P$306)) -> 31 | L12: =IF(ISBLANK($G12),IF($K12>5,"",IF(AND(ISNA(MATCH(K12+1,$K$7:$K$306,0)),$K12<$A$4),"TIE","")),"DQ") | N12: =IF(ISBLANK($G12),$R12,"DQ") -> 31 | O12: =IF(ISBLANK(A12),"",$H12*$O$6+$I12) -> 0.5 | P12: =IF(ISBLANK(A12),"",$O12*10*$P$6+$J12) -> 917 | Q12: =IF(ISBLANK($G12),IF(ISBLANK($A12),-10,$P12*$Q$6+IF($M12>0,$Q$6-1-$M12,0)),-1) -> 2751 | R12: =IF(ISBLANK($A12),"",RANK($Q12,$Q$7:$Q$306)) -> 31 | S12: =IF(ISNA(MATCH($R12+1,$R$7:$R$306,0)),IF($R12=MAX($A$7:$A$306),$R12,-1),$R12) -> 31 | T12: =$A12 -> 2 | U12: =IF(N('Final Round'!$J$14)>0,IF(ISBLANK($A12),"",IF($N12>5,$N12,VLOOKUP($A12,'Final Round'!$A$14:$K$18,COLUMN('Final Round'!$J$1),FALSE))),"") -> 31 | V12: =IF(ISNUMBER($U12),$U12,$R12) -> 31 | W12: =IF(ISBLANK($A12),"",($V$6-$V12)*$W$6+$W$6-$A12) -> 502 | X12: =IF(ISBLANK($A12),"",RANK($W12,$W$7:$W$306)) -> 31 | Y12: =$A12 -> 2 | Z12: =IF($U12="",$N12,$U12) -> 31 | AA12: =IF($U12<6,INDEX($AA$1:$AA$5,$Z12)*$Z$2,0) -> 0 | AB12: =IF(ISBLANK($A12),"",5+4*(I12+IF(AA12=0,0,VLOOKUP($A12,'Final Round'!$A$14:$K$18,COLUMN('Final Round'!$G$1),FALSE)))+8*(H12+IF(AA12=0,0,IF(VLOOKUP($A12,'Final Round'!$A$14:$K$18,COLUMN('Final Round'!$J$1),FALSE)=1,1,0)))+$AA12) -> 7
A13: 26 | B13: Erik | C13: Wallgren | E13: 104 | F13: =IF(ISBLANK($A13),"",SUM(IF(ISNA(IF(VLOOKUP($A13,'Round 1'!$A$7:$J$306,COLUMN('Round 1'!$H$7),FALSE),1,NA())),0,1),IF(ISNA(IF(VLOOKUP($A13,'Round 2'!$A$7:$J$306,COLUMN('Round 1'!$H$7),FALSE),1,NA())),0,1),IF(ISNA(IF(VLOOKUP($A13,'Round 3'!$A$7:$J$306,COLUMN('Round 1'!$H$7),FALSE),1,NA())),0,1),IF(ISNA(IF(VLOOKUP($A13,'Final Round'!$A$14:$K$18,1,FALSE),1,NA())),0,1))) -> 4 | H13: =IF(ISBLANK($A13),"",IF(ISERROR(VLOOKUP($A13,'Round 1'!$A$7:$I$306,COLUMN('Round 1'!$G$7),FALSE)),0,VLOOKUP($A13,'Round 1'!$A$7:$I$306,COLUMN('Round 1'!$G$7),FALSE))+IF(ISERROR(VLOOKUP($A13,'Round 2'!$A$7:$I$306,COLUMN('Round 2'!$G$7),FALSE)),0,VLOOKUP($A13,'Round 2'!$A$7:$I$306,COLUMN('Round 2'!$G$7),FALSE))+IF(ISERROR(VLOOKUP($A13,'Round 3'!$A$7:$I$306,COLUMN('Round 3'!$G$7),FALSE)),0,VLOOKUP($A13,'Round 3'!$A$7:$I$306,COLUMN('Round 3'!$G$7),FALSE))) -> 1 | I13: =IF(ISBLANK($A13),"",IF(ISERROR(VLOOKUP($A13,'Round 1'!$A$7:$I$306,COLUMN('Round 1'!$F$7),FALSE)),0,VLOOKUP($A13,'Round 1'!$A$7:$I$306,COLUMN('Round 1'!$F$7),FALSE))+IF(ISERROR(VLOOKUP($A13,'Round 2'!$A$7:$I$306,COLUMN('Round 2'!$F$7),FALSE)),0,VLOOKUP($A13,'Round 2'!$A$7:$I$306,COLUMN('Round 2'!$F$7),FALSE))+IF(ISERROR(VLOOKUP($A13,'Round 3'!$A$7:$I$306,COLUMN('Round 3'!$F$7),FALSE)),0,VLOOKUP($A13,'Round 3'!$A$7:$I$306,COLUMN('Round 3'!$F$7),FALSE))) -> 6 | J13: =IF(ISBLANK($A13),"",IF(ISERROR(VLOOKUP($A13,'Round 1'!$A$7:$I$306,COLUMN('Round 1'!$H$7),FALSE)),0,VLOOKUP($A13,'Round 1'!$A$7:$I$306,COLUMN('Round 1'!$H$7),FALSE))+IF(ISERROR(VLOOKUP($A13,'Round 2'!$A$7:$I$306,COLUMN('Round 2'!$H$7),FALSE)),0,VLOOKUP($A13,'Round 2'!$A$7:$I$306,COLUMN('Round 2'!$H$7),FALSE))+IF(ISERROR(VLOOKUP($A13,'Round 3'!$A$7:$I$306,COLUMN('Round 3'!$H$7),FALSE)),0,VLOOKUP($A13,'Round 3'!$A$7:$I$306,COLUMN('Round 3'!$H$7),FALSE))) -> 156 | K13: =IF(ISBLANK(A13),"",RANK(P13,$P$7:$P$306)) -> 5 | L13: =IF(ISBLANK($G13),IF($K13>5,"",IF(AND(ISNA(MATCH(K13+1,$K$7:$K$306,0)),$K13<$A$4),"TIE","")),"DQ") | N13: =IF(ISBLANK($G13),$R13,"DQ") -> 5 | O13: =IF(ISBLANK(A13),"",$H13*$O$6+$I13) -> 15.5 | P13: =IF(ISBLANK(A13),"",$O13*10*$P$6+$J13) -> 26351 | Q13: =IF(ISBLANK($G13),IF(ISBLANK($A13),-10,$P13*$Q$6+IF($M13>0,$Q$6-1-$M13,0)),-1) -> 79053 | R13: =IF(ISBLANK($A13),"",RANK($Q13,$Q$7:$Q$306)) -> 5 | S13: =IF(ISNA(MATCH($R13+1,$R$7:$R$306,0)),IF($R13=MAX($A$7:$A$306),$R13,-1),$R13) -> 5 | T13: =$A13 -> 26 | U13: =IF(N('Final Round'!$J$14)>0,IF(ISBLANK($A13),"",IF($N13>5,$N13,VLOOKUP($A13,'Final Round'!$A$14:$K$18,COLUMN('Final Round'!$J$1),FALSE))),"") -> 2 | V13: =IF(ISNUMBER($U13),$U13,$R13) -> 2 | W13: =IF(ISBLANK($A13),"",($V$6-$V13)*$W$6+$W$6-$A13) -> 1696 | X13: =IF(ISBLANK($A13),"",RANK($W13,$W$7:$W$306)) -> 4 | Y13: =$A13 -> 26 | Z13: =IF($U13="",$N13,$U13) -> 2 | AA13: =IF($U13<6,INDEX($AA$1:$AA$5,$Z13)*$Z$2,0) -> 59.778506 | AB13: =IF(ISBLANK($A13),"",5+4*(I13+IF(AA13=0,0,VLOOKUP($A13,'Final Round'!$A$14:$K$18,COLUMN('Final Round'!$G$1),FALSE)))+8*(H13+IF(AA13=0,0,IF(VLOOKUP($A13,'Final Round'!$A$14:$K$18,COLUMN('Final Round'!$J$1),FALSE)=1,1,0)))+$AA13) -> 96.778506
A14: 39 | B14: Jani | C14: Malmi | E14: 126 | F14: =IF(ISBLANK($A14),"",SUM(IF(ISNA(IF(VLOOKUP($A14,'Round 1'!$A$7:$J$306,COLUMN('Round 1'!$H$7),FALSE),1,NA())),0,1),IF(ISNA(IF(VLOOKUP($A14,'Round 2'!$A$7:$J$306,COLUMN('Round 1'!$H$7),FALSE),1,NA())),0,1),IF(ISNA(IF(VLOOKUP($A14,'Round 3'!$A$7:$J$306,COLUMN('Round 1'!$H$7),FALSE),1,NA())),0,1),IF(ISNA(IF(VLOOKUP($A14,'Final Round'!$A$14:$K$18,1,FALSE),1,NA())),0,1))) -> 3 | H14: =IF(ISBLANK($A14),"",IF(ISERROR(VLOOKUP($A14,'Round 1'!$A$7:$I$306,COLUMN('Round 1'!$G$7),FALSE)),0,VLOOKUP($A14,'Round 1'!$A$7:$I$306,COLUMN('Round 1'!$G$7),FALSE))+IF(ISERROR(VLOOKUP($A14,'Round 2'!$A$7:$I$306,COLUMN('Round 2'!$G$7),FALSE)),0,VLOOKUP($A14,'Round 2'!$A$7:$I$306,COLUMN('Round 2'!$G$7),FALSE))+IF(ISERROR(VLOOKUP($A14,'Round 3'!$A$7:$I$306,COLUMN('Round 3'!$G$7),FALSE)),0,VLOOKUP($A14,'Round 3'!$A$7:$I$306,COLUMN('Round 3'!$G$7),FALSE))) -> 0 | I14: =IF(ISBLANK($A14),"",IF(ISERROR(VLOOKUP($A14,'Round 1'!$A$7:$I$306,COLUMN('Round 1'!$F$7),FALSE)),0,VLOOKUP($A14,'Round 1'!$A$7:$I$306,COLUMN('Round 1'!$F$7),FALSE))+IF(ISERROR(VLOOKUP($A14,'Round 2'!$A$7:$I$306,COLUMN('Round 2'!$F$7),FALSE)),0,VLOOKUP($A14,'Round 2'!$A$7:$I$306,COLUMN('Round 2'!$F$7),FALSE))+IF(ISERROR(VLOOKUP($A14,'Round 3'!$A$7:$I$306,COLUMN('Round 3'!$F$7),FALSE)),0,VLOOKUP($A14,'Round 3'!$A$7:$I$306,COLUMN('Round 3'!$F$7),FALSE))) -> 1.5 | J14: =IF(ISBLANK($A14),"",IF(ISERROR(VLOOKUP($A14,'Round 1'!$A$7:$I$306,COLUMN('Round 1'!$H$7),FALSE)),0,VLOOKUP($A14,'Round 1'!$A$7:$I$306,COLUMN('Round 1'!$H$7),FALSE))+IF(ISERROR(VLOOKUP($A14,'Round 2'!$A$7:$I$306,COLUMN('Round 2'!$H$7),FALSE)),0,VLOOKUP($A14,'Round 2'!$A$7:$I$306,COLUMN('Round 2'!$H$7),FALSE))+IF(ISERROR(VLOOKUP($A14,'Round 3'!$A$7:$I$306,COLUMN('Round 3'!$H$7),FALSE)),0,VLOOKUP($A14,'Round 3'!$A$7:$I$306,COLUMN('Round 3'!$H$7),FALSE))) -> 90 | K14: =IF(ISBLANK(A14),"",RANK(P14,$P$7:$P$306)) -> 26 | L14: =IF(ISBLANK($G14),IF($K14>5,"",IF(AND(ISNA(MATCH(K14+1,$K$7:$K$306,0)),$K14<$A$4),"TIE","")),"DQ") | N14: =IF(ISBLANK($G14),$R14,"DQ") -> 26 | O14: =IF(ISBLANK(A14),"",$H14*$O$6+$I14) -> 1.5 | P14: =IF(ISBLANK(A14),"",$O14*10*$P$6+$J14) -> 2625 | Q14: =IF(ISBLANK($G14),IF(ISBLANK($A14),-10,$P14*$Q$6+IF($M14>0,$Q$6-1-$M14,0)),-1) -> 7875 | R14: =IF(ISBLANK($A14),"",RANK($Q14,$Q$7:$Q$306)) -> 26 | S14: =IF(ISNA(MATCH($R14+1,$R$7:$R$306,0)),IF($R14=MAX($A$7:$A$306),$R14,-1),$R14) -> 26 | T14: =$A14 -> 39 | U14: =IF(N('Final Round'!$J$14)>0,IF(ISBLANK($A14),"",IF($N14>5,$N14,VLOOKUP($A14,'Final Round'!$A$14:$K$18,COLUMN('Final Round'!$J$1),FALSE))),"") -> 26 | V14: =IF(ISNUMBER($U14),$U14,$R14) -> 26 | W14: =IF(ISBLANK($A14),"",($V$6-$V14)*$W$6+$W$6-$A14) -> 675 | X14: =IF(ISBLANK($A14),"",RANK($W14,$W$7:$W$306)) -> 26 | Y14: =$A14 -> 39 | Z14: =IF($U14="",$N14,$U14) -> 26 | AA14: =IF($U14<6,INDEX($AA$1:$AA$5,$Z14)*$Z$2,0) -> 0 | AB14: =IF(ISBLANK($A14),"",5+4*(I14+IF(AA14=0,0,VLOOKUP($A14,'Final Round'!$A$14:$K$18,COLUMN('Final Round'!$G$1),FALSE)))+8*(H14+IF(AA14=0,0,IF(VLOOKUP($A14,'Final Round'!$A$14:$K$18,COLUMN('Final Round'!$J$1),FALSE)=1,1,0)))+$AA14) -> 11
A15: 10 | B15: Janne | C15: Lönnqvist | E15: 111 | F15: =IF(ISBLANK($A15),"",SUM(IF(ISNA(IF(VLOOKUP($A15,'Round 1'!$A$7:$J$306,COLUMN('Round 1'!$H$7),FALSE),1,NA())),0,1),IF(ISNA(IF(VLOOKUP($A15,'Round 2'!$A$7:$J$306,COLUMN('Round 1'!$H$7),FALSE),1,NA())),0,1),IF(ISNA(IF(VLOOKUP($A15,'Round 3'!$A$7:$J$306,COLUMN('Round 1'!$H$7),FALSE),1,NA())),0,1),IF(ISNA(IF(VLOOKUP($A15,'Final Round'!$A$14:$K$18,1,FALSE),1,NA())),0,1))) -> 3 | H15: =IF(ISBLANK($A15),"",IF(ISERROR(VLOOKUP($A15,'Round 1'!$A$7:$I$306,COLUMN('Round 1'!$G$7),FALSE)),0,VLOOKUP($A15,'Round 1'!$A$7:$I$306,COLUMN('Round 1'!$G$7),FALSE))+IF(ISERROR(VLOOKUP($A15,'Round 2'!$A$7:$I$306,COLUMN('Round 2'!$G$7),FALSE)),0,VLOOKUP($A15,'Round 2'!$A$7:$I$306,COLUMN('Round 2'!$G$7),FALSE))+IF(ISERROR(VLOOKUP($A15,'Round 3'!$A$7:$I$306,COLUMN('Round 3'!$G$7),FALSE)),0,VLOOKUP($A15,'Round 3'!$A$7:$I$306,COLUMN('Round 3'!$G$7),FALSE))) -> 1 | I15: =IF(ISBLANK($A15),"",IF(ISERROR(VLOOKUP($A15,'Round 1'!$A$7:$I$306,COLUMN('Round 1'!$F$7),FALSE)),0,VLOOKUP($A15,'Round 1'!$A$7:$I$306,COLUMN('Round 1'!$F$7),FALSE))+IF(ISERROR(VLOOKUP($A15,'Round 2'!$A$7:$I$306,COLUMN('Round 2'!$F$7),FALSE)),0,VLOOKUP($A15,'Round 2'!$A$7:$I$306,COLUMN('Round 2'!$F$7),FALSE))+IF(ISERROR(VLOOKUP($A15,'Round 3'!$A$7:$I$306,COLUMN('Round 3'!$F$7),FALSE)),0,VLOOKUP($A15,'Round 3'!$A$7:$I$306,COLUMN('Round 3'!$F$7),FALSE))) -> 4.5 | J15: =IF(ISBLANK($A15),"",IF(ISERROR(VLOOKUP($A15,'Round 1'!$A$7:$I$306,COLUMN('Round 1'!$H$7),FALSE)),0,VLOOKUP($A15,'Round 1'!$A$7:$I$306,COLUMN('Round 1'!$H$7),FALSE))+IF(ISERROR(VLOOKUP($A15,'Round 2'!$A$7:$I$306,COLUMN('Round 2'!$H$7),FALSE)),0,VLOOKUP($A15,'Round 2'!$A$7:$I$306,COLUMN('Round 2'!$H$7),FALSE))+IF(ISERROR(VLOOKUP($A15,'Round 3'!$A$7:$I$306,COLUMN('Round 3'!$H$7),FALSE)),0,VLOOKUP($A15,'Round 3'!$A$7:$I$306,COLUMN('Round 3'!$H$7),FALSE))) -> 120 | K15: =IF(ISBLANK(A15),"",RANK(P15,$P$7:$P$306)) -> 11 | L15: =IF(ISBLANK($G15),IF($K15>5,"",IF(AND(ISNA(MATCH(K15+1,$K$7:$K$306,0)),$K15<$A$4),"TIE","")),"DQ") | N15: =IF(ISBLANK($G15),$R15,"DQ") -> 11 | O15: =IF(ISBLANK(A15),"",$H15*$O$6+$I15) -> 14 | P15: =IF(ISBLANK(A15),"",$O15*10*$P$6+$J15) -> 23780 | Q15: =IF(ISBLANK($G15),IF(ISBLANK($A15),-10,$P15*$Q$6+IF($M15>0,$Q$6-1-$M15,0)),-1) -> 71340 | R15: =IF(ISBLANK($A15),"",RANK($Q15,$Q$7:$Q$306)) -> 11 | S15: =IF(ISNA(MATCH($R15+1,$R$7:$R$306,0)),IF($R15=MAX($A$7:$A$306),$R15,-1),$R15) -> 11 | T15: =$A15 -> 10 | U15: =IF(N('Final Round'!$J$14)>0,IF(ISBLANK($A15),"",IF($N15>5,$N15,VLOOKUP($A15,'Final Round'!$A$14:$K$18,COLUMN('Final Round'!$J$1),FALSE))),"") -> 11 | V15: =IF(ISNUMBER($U15),$U15,$R15) -> 11 | W15: =IF(ISBLANK($A15),"",($V$6-$V15)*$W$6+$W$6-$A15) -> 1334 | X15: =IF(ISBLANK($A15),"",RANK($W15,$W$7:$W$306)) -> 11 | Y15: =$A15 -> 10 | Z15: =IF($U15="",$N15,$U15) -> 11 | AA15: =IF($U15<6,INDEX($AA$1:$AA$5,$Z15)*$Z$2,0) -> 0 | AB15: =IF(ISBLANK($A15),"",5+4*(I15+IF(AA15=0,0,VLOOKUP($A15,'Final Round'!$A$14:$K$18,COLUMN('Final Round'!$G$1),FALSE)))+8*(H15+IF(AA15=0,0,IF(VLOOKUP($A15,'Final Round'!$A$14:$K$18,COLUMN('Final Round'!$J$1),FALSE)=1,1,0)))+$AA15) -> 31
A16: 21 | B16: Jere | C16: Laatunen | E16: 140 | F16: =IF(ISBLANK($A16),"",SUM(IF(ISNA(IF(VLOOKUP($A16,'Round 1'!$A$7:$J$306,COLUMN('Round 1'!$H$7),FALSE),1,NA())),0,1),IF(ISNA(IF(VLOOKUP($A16,'Round 2'!$A$7:$J$306,COLUMN('Round 1'!$H$7),FALSE),1,NA())),0,1),IF(ISNA(IF(VLOOKUP($A16,'Round 3'!$A$7:$J$306,COLUMN('Round 1'!$H$7),FALSE),1,NA())),0,1),IF(ISNA(IF(VLOOKUP($A16,'Final Round'!$A$14:$K$18,1,FALSE),1,NA())),0,1))) -> 3 | H16: =IF(ISBLANK($A16),"",IF(ISERROR(VLOOKUP($A16,'Round 1'!$A$7:$I$306,COLUMN('Round 1'!$G$7),FALSE)),0,VLOOKUP($A16,'Round 1'!$A$7:$I$306,COLUMN('Round 1'!$G$7),FALSE))+IF(ISERROR(VLOOKUP($A16,'Round 2'!$A$7:$I$306,COLUMN('Round 2'!$G$7),FALSE)),0,VLOOKUP($A16,'Round 2'!$A$7:$I$306,COLUMN('Round 2'!$G$7),FALSE))+IF(ISERROR(VLOOKUP($A16,'Round 3'!$A$7:$I$306,COLUMN('Round 3'!$G$7),FALSE)),0,VLOOKUP($A16,'Round 3'!$A$7:$I$306,COLUMN('Round 3'!$G$7),FALSE))) -> 0 | I16: =IF(ISBLANK($A16),"",IF(ISERROR(VLOOKUP($A16,'Round 1'!$A$7:$I$306,COLUMN('Round 1'!$F$7),FALSE)),0,VLOOKUP($A16,'Round 1'!$A$7:$I$306,COLUMN('Round 1'!$F$7),FALSE))+IF(ISERROR(VLOOKUP($A16,'Round 2'!$A$7:$I$306,COLUMN('Round 2'!$F$7),FALSE)),0,VLOOKUP($A16,'Round 2'!$A$7:$I$306,COLUMN('Round 2'!$F$7),FALSE))+IF(ISERROR(VLOOKUP($A16,'Round 3'!$A$7:$I$306,COLUMN('Round 3'!$F$7),FALSE)),0,VLOOKUP($A16,'Round 3'!$A$7:$I$306,COLUMN('Round 3'!$F$7),FALSE))) -> 0 | J16: =IF(ISBLANK($A16),"",IF(ISERROR(VLOOKUP($A16,'Round 1'!$A$7:$I$306,COLUMN('Round 1'!$H$7),FALSE)),0,VLOOKUP($A16,'Round 1'!$A$7:$I$306,COLUMN('Round 1'!$H$7),FALSE))+IF(ISERROR(VLOOKUP($A16,'Round 2'!$A$7:$I$306,COLUMN('Round 2'!$H$7),FALSE)),0,VLOOKUP($A16,'Round 2'!$A$7:$I$306,COLUMN('Round 2'!$H$7),FALSE))+IF(ISERROR(VLOOKUP($A16,'Round 3'!$A$7:$I$306,COLUMN('Round 3'!$H$7),FALSE)),0,VLOOKUP($A16,'Round 3'!$A$7:$I$306,COLUMN('Round 3'!$H$7),FALSE))) -> 60 | K16: =IF(ISBLANK(A16),"",RANK(P16,$P$7:$P$306)) -> 38 | L16: =IF(ISBLANK($G16),IF($K16>5,"",IF(AND(ISNA(MATCH(K16+1,$K$7:$K$306,0)),$K16<$A$4),"TIE","")),"DQ") | N16: =IF(ISBLANK($G16),$R16,"DQ") -> 38 | O16: =IF(ISBLANK(A16),"",$H16*$O$6+$I16) -> 0 | P16: =IF(ISBLANK(A16),"",$O16*10*$P$6+$J16) -> 60 | Q16: =IF(ISBLANK($G16),IF(ISBLANK($A16),-10,$P16*$Q$6+IF($M16>0,$Q$6-1-$M16,0)),-1) -> 180 | R16: =IF(ISBLANK($A16),"",RANK($Q16,$Q$7:$Q$306)) -> 38 | S16: =IF(ISNA(MATCH($R16+1,$R$7:$R$306,0)),IF($R16=MAX($A$7:$A$306),$R16,-1),$R16) -> -1 | T16: =$A16 -> 21 | U16: =IF(N('Final Round'!$J$14)>0,IF(ISBLANK($A16),"",IF($N16>5,$N16,VLOOKUP($A16,'Final Round'!$A$14:$K$18,COLUMN('Final Round'!$J$1),FALSE))),"") -> 38 | V16: =IF(ISNUMBER($U16),$U16,$R16) -> 38 | W16: =IF(ISBLANK($A16),"",($V$6-$V16)*$W$6+$W$6-$A16) -> 189 | X16: =IF(ISBLANK($A16),"",RANK($W16,$W$7:$W$306)) -> 40 | Y16: =$A16 -> 21 | Z16: =IF($U16="",$N16,$U16) -> 38 | AA16: =IF($U16<6,INDEX($AA$1:$AA$5,$Z16)*$Z$2,0) -> 0 | AB16: =IF(ISBLANK($A16),"",5+4*(I16+IF(AA16=0,0,VLOOKUP($A16,'Final Round'!$A$14:$K$18,COLUMN('Final Round'!$G$1),FALSE)))+8*(H16+IF(AA16=0,0,IF(VLOOKUP($A16,'Final Round'!$A$14:$K$18,COLUMN('Final Round'!$J$1),FALSE)=1,1,0)))+$AA16) -> 5
A17: 19 | B17: Joel | C17: Tikkala | E17: 136 | F17: =IF(ISBLANK($A17),"",SUM(IF(ISNA(IF(VLOOKUP($A17,'Round 1'!$A$7:$J$306,COLUMN('Round 1'!$H$7),FALSE),1,NA())),0,1),IF(ISNA(IF(VLOOKUP($A17,'Round 2'!$A$7:$J$306,COLUMN('Round 1'!$H$7),FALSE),1,NA())),0,1),IF(ISNA(IF(VLOOKUP($A17,'Round 3'!$A$7:$J$306,COLUMN('Round 1'!$H$7),FALSE),1,NA())),0,1),IF(ISNA(IF(VLOOKUP($A17,'Final Round'!$A$14:$K$18,1,FALSE),1,NA())),0,1))) -> 3 | H17: =IF(ISBLANK($A17),"",IF(ISERROR(VLOOKUP($A17,'Round 1'!$A$7:$I$306,COLUMN('Round 1'!$G$7),FALSE)),0,VLOOKUP($A17,'Round 1'!$A$7:$I$306,COLUMN('Round 1'!$G$7),FALSE))+IF(ISERROR(VLOOKUP($A17,'Round 2'!$A$7:$I$306,COLUMN('Round 2'!$G$7),FALSE)),0,VLOOKUP($A17,'Round 2'!$A$7:$I$306,COLUMN('Round 2'!$G$7),FALSE))+IF(ISERROR(VLOOKUP($A17,'Round 3'!$A$7:$I$306,COLUMN('Round 3'!$G$7),FALSE)),0,VLOOKUP($A17,'Round 3'!$A$7:$I$306,COLUMN('Round 3'!$G$7),FALSE))) -> 0 | I17: =IF(ISBLANK($A17),"",IF(ISERROR(VLOOKUP($A17,'Round 1'!$A$7:$I$306,COLUMN('Round 1'!$F$7),FALSE)),0,VLOOKUP($A17,'Round 1'!$A$7:$I$306,COLUMN('Round 1'!$F$7),FALSE))+IF(ISERROR(VLOOKUP($A17,'Round 2'!$A$7:$I$306,COLUMN('Round 2'!$F$7),FALSE)),0,VLOOKUP($A17,'Round 2'!$A$7:$I$306,COLUMN('Round 2'!$F$7),FALSE))+IF(ISERROR(VLOOKUP($A17,'Round 3'!$A$7:$I$306,COLUMN('Round 3'!$F$7),FALSE)),0,VLOOKUP($A17,'Round 3'!$A$7:$I$306,COLUMN('Round 3'!$F$7),FALSE))) -> 0 | J17: =IF(ISBLANK($A17),"",IF(ISERROR(VLOOKUP($A17,'Round 1'!$A$7:$I$306,COLUMN('Round 1'!$H$7),FALSE)),0,VLOOKUP($A17,'Round 1'!$A$7:$I$306,COLUMN('Round 1'!$H$7),FALSE))+IF(ISERROR(VLOOKUP($A17,'Round 2'!$A$7:$I$306,COLUMN('Round 2'!$H$7),FALSE)),0,VLOOKUP($A17,'Round 2'!$A$7:$I$306,COLUMN('Round 2'!$H$7),FALSE))+IF(ISERROR(VLOOKUP($A17,'Round 3'!$A$7:$I$306,COLUMN('Round 3'!$H$7),FALSE)),0,VLOOKUP($A17,'Round 3'!$A$7:$I$306,COLUMN('Round 3'!$H$7),FALSE))) -> 66 | K17: =IF(ISBLANK(A17),"",RANK(P17,$P$7:$P$306)) -> 34 | L17: =IF(ISBLANK($G17),IF($K17>5,"",IF(AND(ISNA(MATCH(K17+1,$K$7:$K$306,0)),$K17<$A$4),"TIE","")),"DQ") | N17: =IF(ISBLANK($G17),$R17,"DQ") -> 34 | O17: =IF(ISBLANK(A17),"",$H17*$O$6+$I17) -> 0 | P17: =IF(ISBLANK(A17),"",$O17*10*$P$6+$J17) -> 66 | Q17: =IF(ISBLANK($G17),IF(ISBLANK($A17),-10,$P17*$Q$6+IF($M17>0,$Q$6-1-$M17,0)),-1) -> 198 | R17: =IF(ISBLANK($A17),"",RANK($Q17,$Q$7:$Q$306)) -> 34 | S17: =IF(ISNA(MATCH($R17+1,$R$7:$R$306,0)),IF($R17=MAX($A$7:$A$306),$R17,-1),$R17) -> -1 | T17: =$A17 -> 19 | U17: =IF(N('Final Round'!$J$14)>0,IF(ISBLANK($A17),"",IF($N17>5,$N17,VLOOKUP($A17,'Final Round'!$A$14:$K$18,COLUMN('Final Round'!$J$1),FALSE))),"") -> 34 | V17: =IF(ISNUMBER($U17),$U17,$R17) -> 34 | W17: =IF(ISBLANK($A17),"",($V$6-$V17)*$W$6+$W$6-$A17) -> 359 | X17: =IF(ISBLANK($A17),"",RANK($W17,$W$7:$W$306)) -> 36 | Y17: =$A17 -> 19 | Z17: =IF($U17="",$N17,$U17) -> 34 | AA17: =IF($U17<6,INDEX($AA$1:$AA$5,$Z17)*$Z$2,0) -> 0 | AB17: =IF(ISBLANK($A17),"",5+4*(I17+IF(AA17=0,0,VLOOKUP($A17,'Final Round'!$A$14:$K$18,COLUMN('Final Round'!$G$1),FALSE)))+8*(H17+IF(AA17=0,0,IF(VLOOKUP($A17,'Final Round'!$A$14:$K$18,COLUMN('Final Round'!$J$1),FALSE)=1,1,0)))+$AA17) -> 5
A18: 24 | B18: Jonas | C18: Ståhle | E18: 118 | F18: =IF(ISBLANK($A18),"",SUM(IF(ISNA(IF(VLOOKUP($A18,'Round 1'!$A$7:$J$306,COLUMN('Round 1'!$H$7),FALSE),1,NA())),0,1),IF(ISNA(IF(VLOOKUP($A18,'Round 2'!$A$7:$J$306,COLUMN('Round 1'!$H$7),FALSE),1,NA())),0,1),IF(ISNA(IF(VLOOKUP($A18,'Round 3'!$A$7:$J$306,COLUMN('Round 1'!$H$7),FALSE),1,NA())),0,1),IF(ISNA(IF(VLOOKUP($A18,'Final Round'!$A$14:$K$18,1,FALSE),1,NA())),0,1))) -> 3 | H18: =IF(ISBLANK($A18),"",IF(ISERROR(VLOOKUP($A18,'Round 1'!$A$7:$I$306,COLUMN('Round 1'!$G$7),FALSE)),0,VLOOKUP($A18,'Round 1'!$A$7:$I$306,COLUMN('Round 1'!$G$7),FALSE))+IF(ISERROR(VLOOKUP($A18,'Round 2'!$A$7:$I$306,COLUMN('Round 2'!$G$7),FALSE)),0,VLOOKUP($A18,'Round 2'!$A$7:$I$306,COLUMN('Round 2'!$G$7),FALSE))+IF(ISERROR(VLOOKUP($A18,'Round 3'!$A$7:$I$306,COLUMN('Round 3'!$G$7),FALSE)),0,VLOOKUP($A18,'Round 3'!$A$7:$I$306,COLUMN('Round 3'!$G$7),FALSE))) -> 0 | I18: =IF(ISBLANK($A18),"",IF(ISERROR(VLOOKUP($A18,'Round 1'!$A$7:$I$306,COLUMN('Round 1'!$F$7),FALSE)),0,VLOOKUP($A18,'Round 1'!$A$7:$I$306,COLUMN('Round 1'!$F$7),FALSE))+IF(ISERROR(VLOOKUP($A18,'Round 2'!$A$7:$I$306,COLUMN('Round 2'!$F$7),FALSE)),0,VLOOKUP($A18,'Round 2'!$A$7:$I$306,COLUMN('Round 2'!$F$7),FALSE))+IF(ISERROR(VLOOKUP($A18,'Round 3'!$A$7:$I$306,COLUMN('Round 3'!$F$7),FALSE)),0,VLOOKUP($A18,'Round 3'!$A$7:$I$306,COLUMN('Round 3'!$F$7),FALSE))) -> 3 | J18: =IF(ISBLANK($A18),"",IF(ISERROR(VLOOKUP($A18,'Round 1'!$A$7:$I$306,COLUMN('Round 1'!$H$7),FALSE)),0,VLOOKUP($A18,'Round 1'!$A$7:$I$306,COLUMN('Round 1'!$H$7),FALSE))+IF(ISERROR(VLOOKUP($A18,'Round 2'!$A$7:$I$306,COLUMN('Round 2'!$H$7),FALSE)),0,VLOOKUP($A18,'Round 2'!$A$7:$I$306,COLUMN('Round 2'!$H$7),FALSE))+IF(ISERROR(VLOOKUP($A18,'Round 3'!$A$7:$I$306,COLUMN('Round 3'!$H$7),FALSE)),0,VLOOKUP($A18,'Round 3'!$A$7:$I$306,COLUMN('Round 3'!$H$7),FALSE))) -> 108 | K18: =IF(ISBLANK(A18),"",RANK(P18,$P$7:$P$306)) -> 18 | L18: =IF(ISBLANK($G18),IF($K18>5,"",IF(AND(ISNA(MATCH(K18+1,$K$7:$K$306,0)),$K18<$A$4),"TIE","")),"DQ") | N18: =IF(ISBLANK($G18),$R18,"DQ") -> 18 | O18: =IF(ISBLANK(A18),"",$H18*$O$6+$I18) -> 3 | P18: =IF(ISBLANK(A18),"",$O18*10*$P$6+$J18) -> 5178 | Q18: =IF(ISBLANK($G18),IF(ISBLANK($A18),-10,$P18*$Q$6+IF($M18>0,$Q$6-1-$M18,0)),-1) -> 15534 | R18: =IF(ISBLANK($A18),"",RANK($Q18,$Q$7:$Q$306)) -> 18 | S18: =IF(ISNA(MATCH($R18+1,$R$7:$R$306,0)),IF($R18=MAX($A$7:$A$306),$R18,-1),$R18) -> 18 | T18: =$A18 -> 24 | U18: =IF(N('Final Round'!$J$14)>0,IF(ISBLANK($A18),"",IF($N18>5,$N18,VLOOKUP($A18,'Final Round'!$A$14:$K$18,COLUMN('Final Round'!$J$1),FALSE))),"") -> 18 | V18: =IF(ISNUMBER($U18),$U18,$R18) -> 18 | W18: =IF(ISBLANK($A18),"",($V$6-$V18)*$W$6+$W$6-$A18) -> 1026 | X18: =IF(ISBLANK($A18),"",RANK($W18,$W$7:$W$306)) -> 18 | Y18: =$A18 -> 24 | Z18: =IF($U18="",$N18,$U18) -> 18 | AA18: =IF($U18<6,INDEX($AA$1:$AA$5,$Z18)*$Z$2,0) -> 0 | AB18: =IF(ISBLANK($A18),"",5+4*(I18+IF(AA18=0,0,VLOOKUP($A18,'Final Round'!$A$14:$K$18,COLUMN('Final Round'!$G$1),FALSE)))+8*(H18+IF(AA18=0,0,IF(VLOOKUP($A18,'Final Round'!$A$14:$K$18,COLUMN('Final Round'!$J$1),FALSE)=1,1,0)))+$AA18) -> 17
... A27: 28 | B27: Marko | C27: Saari | E27: 105 | F27: =IF(ISBLANK($A27),"",SUM(IF(ISNA(IF(VLOOKUP($A27,'Round 1'!$A$7:$J$306,COLUMN('Round 1'!$H$7),FALSE),1,NA())),0,1),IF(ISNA(IF(VLOOKUP($A27,'Round 2'!$A$7:$J$306,COLUMN('Round 1'!$H$7),FALSE),1,NA())),0,1),IF(ISNA(IF(VLOOKUP($A27,'Round 3'!$A$7:$J$306,COLUMN('Round 1'!$H$7),FALSE),1,NA())),0,1),IF(ISNA(IF(VLOOKUP($A27,'Final Round'!$A$14:$K$18,1,FALSE),1,NA())),0,1))) -> 4 | H27: =IF(ISBLANK($A27),"",IF(ISERROR(VLOOKUP($A27,'Round 1'!$A$7:$I$306,COLUMN('Round 1'!$G$7),FALSE)),0,VLOOKUP($A27,'Round 1'!$A$7:$I$306,COLUMN('Round 1'!$G$7),FALSE))+IF(ISERROR(VLOOKUP($A27,'Round 2'!$A$7:$I$306,COLUMN('Round 2'!$G$7),FALSE)),0,VLOOKUP($A27,'Round 2'!$A$7:$I$306,COLUMN('Round 2'!$G$7),FALSE))+IF(ISERROR(VLOOKUP($A27,'Round 3'!$A$7:$I$306,COLUMN('Round 3'!$G$7),FALSE)),0,VLOOKUP($A27,'Round 3'!$A$7:$I$306,COLUMN('Round 3'!$G$7),FALSE))) -> 2 | I27: =IF(ISBLANK($A27),"",IF(ISERROR(VLOOKUP($A27,'Round 1'!$A$7:$I$306,COLUMN('Round 1'!$F$7),FALSE)),0,VLOOKUP($A27,'Round 1'!$A$7:$I$306,COLUMN('Round 1'!$F$7),FALSE))+IF(ISERROR(VLOOKUP($A27,'Round 2'!$A$7:$I$306,COLUMN('Round 2'!$F$7),FALSE)),0,VLOOKUP($A27,'Round 2'!$A$7:$I$306,COLUMN('Round 2'!$F$7),FALSE))+IF(ISERROR(VLOOKUP($A27,'Round 3'!$A$7:$I$306,COLUMN('Round 3'!$F$7),FALSE)),0,VLOOKUP($A27,'Round 3'!$A$7:$I$306,COLUMN('Round 3'!$F$7),FALSE))) -> 7 | J27: =IF(ISBLANK($A27),"",IF(ISERROR(VLOOKUP($A27,'Round 1'!$A$7:$I$306,COLUMN('Round 1'!$H$7),FALSE)),0,VLOOKUP($A27,'Round 1'!$A$7:$I$306,COLUMN('Round 1'!$H$7),FALSE))+IF(ISERROR(VLOOKUP($A27,'Round 2'!$A$7:$I$306,COLUMN('Round 2'!$H$7),FALSE)),0,VLOOKUP($A27,'Round 2'!$A$7:$I$306,COLUMN('Round 2'!$H$7),FALSE))+IF(ISERROR(VLOOKUP($A27,'Round 3'!$A$7:$I$306,COLUMN('Round 3'!$H$7),FALSE)),0,VLOOKUP($A27,'Round 3'!$A$7:$I$306,COLUMN('Round 3'!$H$7),FALSE))) -> 162 | K27: =IF(ISBLANK(A27),"",RANK(P27,$P$7:$P$306)) -> 2 | L27: =IF(ISBLANK($G27),IF($K27>5,"",IF(AND(ISNA(MATCH(K27+1,$K$7:$K$306,0)),$K27<$A$4),"TIE","")),"DQ") | N27: =IF(ISBLANK($G27),$R27,"DQ") -> 2 | O27: =IF(ISBLANK(A27),"",$H27*$O$6+$I27) -> 26 | P27: =IF(ISBLANK(A27),"",$O27*10*$P$6+$J27) -> 44102 | Q27: =IF(ISBLANK($G27),IF(ISBLANK($A27),-10,$P27*$Q$6+IF($M27>0,$Q$6-1-$M27,0)),-1) -> 132306 | R27: =IF(ISBLANK($A27),"",RANK($Q27,$Q$7:$Q$306)) -> 2 | S27: =IF(ISNA(MATCH($R27+1,$R$7:$R$306,0)),IF($R27=MAX($A$7:$A$306),$R27,-1),$R27) -> 2 | T27: =$A27 -> 28 | U27: =IF(N('Final Round'!$J$14)>0,IF(ISBLANK($A27),"",IF($N27>5,$N27,VLOOKUP($A27,'Final Round'!$A$14:$K$18,COLUMN('Final Round'!$J$1),FALSE))),"") -> 2 | V27: =IF(ISNUMBER($U27),$U27,$R27) -> 2 | W27: =IF(ISBLANK($A27),"",($V$6-$V27)*$W$6+$W$6-$A27) -> 1694 | X27: =IF(ISBLANK($A27),"",RANK($W27,$W$7:$W$306)) -> 5 | Y27: =$A27 -> 28 | Z27: =IF($U27="",$N27,$U27) -> 2 | AA27: =IF($U27<6,INDEX($AA$1:$AA$5,$Z27)*$Z$2,0) -> 59.778506 | AB27: =IF(ISBLANK($A27),"",5+4*(I27+IF(AA27=0,0,VLOOKUP($A27,'Final Round'!$A$14:$K$18,COLUMN('Final Round'!$G$1),FALSE)))+8*(H27+IF(AA27=0,0,IF(VLOOKUP($A27,'Final Round'!$A$14:$K$18,COLUMN('Final Round'!$J$1),FALSE)=1,1,0)))+$AA27) -> 108.77851
A28: 3 | B28: Michael | C28: Holmström | E28: 102 | F28: =IF(ISBLANK($A28),"",SUM(IF(ISNA(IF(VLOOKUP($A28,'Round 1'!$A$7:$J$306,COLUMN('Round 1'!$H$7),FALSE),1,NA())),0,1),IF(ISNA(IF(VLOOKUP($A28,'Round 2'!$A$7:$J$306,COLUMN('Round 1'!$H$7),FALSE),1,NA())),0,1),IF(ISNA(IF(VLOOKUP($A28,'Round 3'!$A$7:$J$306,COLUMN('Round 1'!$H$7),FALSE),1,NA())),0,1),IF(ISNA(IF(VLOOKUP($A28,'Final Round'!$A$14:$K$18,1,FALSE),1,NA())),0,1))) -> 4 | H28: =IF(ISBLANK($A28),"",IF(ISERROR(VLOOKUP($A28,'Round 1'!$A$7:$I$306,COLUMN('Round 1'!$G$7),FALSE)),0,VLOOKUP($A28,'Round 1'!$A$7:$I$306,COLUMN('Round 1'!$G$7),FALSE))+IF(ISERROR(VLOOKUP($A28,'Round 2'!$A$7:$I$306,COLUMN('Round 2'!$G$7),FALSE)),0,VLOOKUP($A28,'Round 2'!$A$7:$I$306,COLUMN('Round 2'!$G$7),FALSE))+IF(ISERROR(VLOOKUP($A28,'Round 3'!$A$7:$I$306,COLUMN('Round 3'!$G$7),FALSE)),0,VLOOKUP($A28,'Round 3'!$A$7:$I$306,COLUMN('Round 3'!$G$7),FALSE))) -> 2 | I28: =IF(ISBLANK($A28),"",IF(ISERROR(VLOOKUP($A28,'Round 1'!$A$7:$I$306,COLUMN('Round 1'!$F$7),FALSE)),0,VLOOKUP($A28,'Round 1'!$A$7:$I$306,COLUMN('Round 1'!$F$7),FALSE))+IF(ISERROR(VLOOKUP($A28,'Round 2'!$A$7:$I$306,COLUMN('Round 2'!$F$7),FALSE)),0,VLOOKUP($A28,'Round 2'!$A$7:$I$306,COLUMN('Round 2'!$F$7),FALSE))+IF(ISERROR(VLOOKUP($A28,'Round 3'!$A$7:$I$306,COLUMN('Round 3'!$F$7),FALSE)),0,VLOOKUP($A28,'Round 3'!$A$7:$I$306,COLUMN('Round 3'!$F$7),FALSE))) -> 6.5 | J28: =IF(ISBLANK($A28),"",IF(ISERROR(VLOOKUP($A28,'Round 1'!$A$7:$I$306,COLUMN('Round 1'!$H$7),FALSE)),0,VLOOKUP($A28,'Round 1'!$A$7:$I$306,COLUMN('Round 1'!$H$7),FALSE))+IF(ISERROR(VLOOKUP($A28,'Round 2'!$A$7:$I$306,COLUMN('Round 2'!$H$7),FALSE)),0,VLOOKUP($A28,'Round 2'!$A$7:$I$306,COLUMN('Round 2'!$H$7),FALSE))+IF(ISERROR(VLOOKUP($A28,'Round 3'!$A$7:$I$306,COLUMN('Round 3'!$H$7),FALSE)),0,VLOOKUP($A28,'Round 3'!$A$7:$I$306,COLUMN('Round 3'!$H$7),FALSE))) -> 156 | K28: =IF(ISBLANK(A28),"",RANK(P28,$P$7:$P$306)) -> 3 | L28: =IF(ISBLANK($G28),IF($K28>5,"",IF(AND(ISNA(MATCH(K28+1,$K$7:$K$306,0)),$K28<$A$4),"TIE","")),"DQ") -> TIE | M28: 2 | N28: =IF(ISBLANK($G28),$R28,"DQ") -> 4 | O28: =IF(ISBLANK(A28),"",$H28*$O$6+$I28) -> 25.5 | P28: =IF(ISBLANK(A28),"",$O28*10*$P$6+$J28) -> 43251 | Q28: =IF(ISBLANK($G28),IF(ISBLANK($A28),-10,$P28*$Q$6+IF($M28>0,$Q$6-1-$M28,0)),-1) -> 129753 | R28: =IF(ISBLANK($A28),"",RANK($Q28,$Q$7:$Q$306)) -> 4 | S28: =IF(ISNA(MATCH($R28+1,$R$7:$R$306,0)),IF($R28=MAX($A$7:$A$306),$R28,-1),$R28) -> 4 | T28: =$A28 -> 3 | U28: =IF(N('Final Round'!$J$14)>0,IF(ISBLANK($A28),"",IF($N28>5,$N28,VLOOKUP($A28,'Final Round'!$A$14:$K$18,COLUMN('Final Round'!$J$1),FALSE))),"") -> 2 | V28: =IF(ISNUMBER($U28),$U28,$R28) -> 2 | W28: =IF(ISBLANK($A28),"",($V$6-$V28)*$W$6+$W$6-$A28) -> 1719 | X28: =IF(ISBLANK($A28),"",RANK($W28,$W$7:$W$306)) -> 2 | Y28: =$A28 -> 3 | Z28: =IF($U28="",$N28,$U28) -> 2 | AA28: =IF($U28<6,INDEX($AA$1:$AA$5,$Z28)*$Z$2,0) -> 59.778506 | AB28: =IF(ISBLANK($A28),"",5+4*(I28+IF(AA28=0,0,VLOOKUP($A28,'Final Round'!$A$14:$K$18,COLUMN('Final Round'!$G$1),FALSE)))+8*(H28+IF(AA28=0,0,IF(VLOOKUP($A28,'Final Round'!$A$14:$K$18,COLUMN('Final Round'!$J$1),FALSE)=1,1,0)))+$AA28) -> 112.77851
A29: 32 | B29: Mika | C29: Alanen | E29: 130 | F29: =IF(ISBLANK($A29),"",SUM(IF(ISNA(IF(VLOOKUP($A29,'Round 1'!$A$7:$J$306,COLUMN('Round 1'!$H$7),FALSE),1,NA())),0,1),IF(ISNA(IF(VLOOKUP($A29,'Round 2'!$A$7:$J$306,COLUMN('Round 1'!$H$7),FALSE),1,NA())),0,1),IF(ISNA(IF(VLOOKUP($A29,'Round 3'!$A$7:$J$306,COLUMN('Round 1'!$H$7),FALSE),1,NA())),0,1),IF(ISNA(IF(VLOOKUP($A29,'Final Round'!$A$14:$K$18,1,FALSE),1,NA())),0,1))) -> 3 | H29: =IF(ISBLANK($A29),"",IF(ISERROR(VLOOKUP($A29,'Round 1'!$A$7:$I$306,COLUMN('Round 1'!$G$7),FALSE)),0,VLOOKUP($A29,'Round 1'!$A$7:$I$306,COLUMN('Round 1'!$G$7),FALSE))+IF(ISERROR(VLOOKUP($A29,'Round 2'!$A$7:$I$306,COLUMN('Round 2'!$G$7),FALSE)),0,VLOOKUP($A29,'Round 2'!$A$7:$I$306,COLUMN('Round 2'!$G$7),FALSE))+IF(ISERROR(VLOOKUP($A29,'Round 3'!$A$7:$I$306,COLUMN('Round 3'!$G$7),FALSE)),0,VLOOKUP($A29,'Round 3'!$A$7:$I$306,COLUMN('Round 3'!$G$7),FALSE))) -> 0 | I29: =IF(ISBLANK($A29),"",IF(ISERROR(VLOOKUP($A29,'Round 1'!$A$7:$I$306,COLUMN('Round 1'!$F$7),FALSE)),0,VLOOKUP($A29,'Round 1'!$A$7:$I$306,COLUMN('Round 1'!$F$7),FALSE))+IF(ISERROR(VLOOKUP($A29,'Round 2'!$A$7:$I$306,COLUMN('Round 2'!$F$7),FALSE)),0,VLOOKUP($A29,'Round 2'!$A$7:$I$306,COLUMN('Round 2'!$F$7),FALSE))+IF(ISERROR(VLOOKUP($A29,'Round 3'!$A$7:$I$306,COLUMN('Round 3'!$F$7),FALSE)),0,VLOOKUP($A29,'Round 3'!$A$7:$I$306,COLUMN('Round 3'!$F$7),FALSE))) -> 0.5 | J29: =IF(ISBLANK($A29),"",IF(ISERROR(VLOOKUP($A29,'Round 1'!$A$7:$I$306,COLUMN('Round 1'!$H$7),FALSE)),0,VLOOKUP($A29,'Round 1'!$A$7:$I$306,COLUMN('Round 1'!$H$7),FALSE))+IF(ISERROR(VLOOKUP($A29,'Round 2'!$A$7:$I$306,COLUMN('Round 2'!$H$7),FALSE)),0,VLOOKUP($A29,'Round 2'!$A$7:$I$306,COLUMN('Round 2'!$H$7),FALSE))+IF(ISERROR(VLOOKUP($A29,'Round 3'!$A$7:$I$306,COLUMN('Round 3'!$H$7),FALSE)),0,VLOOKUP($A29,'Round 3'!$A$7:$I$306,COLUMN('Round 3'!$H$7),FALSE))) -> 82 | K29: =IF(ISBLANK(A29),"",RANK(P29,$P$7:$P$306)) -> 30 | L29: =IF(ISBLANK($G29),IF($K29>5,"",IF(AND(ISNA(MATCH(K29+1,$K$7:$K$306,0)),$K29<$A$4),"TIE","")),"DQ") | N29: =IF(ISBLANK($G29),$R29,"DQ") -> 30 | O29: =IF(ISBLANK(A29),"",$H29*$O$6+$I29) -> 0.5 | P29: =IF(ISBLANK(A29),"",$O29*10*$P$6+$J29) -> 927 | Q29: =IF(ISBLANK($G29),IF(ISBLANK($A29),-10,$P29*$Q$6+IF($M29>0,$Q$6-1-$M29,0)),-1) -> 2781 | R29: =IF(ISBLANK($A29),"",RANK($Q29,$Q$7:$Q$306)) -> 30 | S29: =IF(ISNA(MATCH($R29+1,$R$7:$R$306,0)),IF($R29=MAX($A$7:$A$306),$R29,-1),$R29) -> 30 | T29: =$A29 -> 32 | U29: =IF(N('Final Round'!$J$14)>0,IF(ISBLANK($A29),"",IF($N29>5,$N29,VLOOKUP($A29,'Final Round'!$A$14:$K$18,COLUMN('Final Round'!$J$1),FALSE))),"") -> 30 | V29: =IF(ISNUMBER($U29),$U29,$R29) -> 30 | W29: =IF(ISBLANK($A29),"",($V$6-$V29)*$W$6+$W$6-$A29) -> 514 | X29: =IF(ISBLANK($A29),"",RANK($W29,$W$7:$W$306)) -> 30 | Y29: =$A29 -> 32 | Z29: =IF($U29="",$N29,$U29) -> 30 | AA29: =IF($U29<6,INDEX($AA$1:$AA$5,$Z29)*$Z$2,0) -> 0 | AB29: =IF(ISBLANK($A29),"",5+4*(I29+IF(AA29=0,0,VLOOKUP($A29,'Final Round'!$A$14:$K$18,COLUMN('Final Round'!$G$1),FALSE)))+8*(H29+IF(AA29=0,0,IF(VLOOKUP($A29,'Final Round'!$A$14:$K$18,COLUMN('Final Round'!$J$1),FALSE)=1,1,0)))+$AA29) -> 7
A30: 4 | B30: Motiejus | C30: Simonis | E30: 124 | F30: =IF(ISBLANK($A30),"",SUM(IF(ISNA(IF(VLOOKUP($A30,'Round 1'!$A$7:$J$306,COLUMN('Round 1'!$H$7),FALSE),1,NA())),0,1),IF(ISNA(IF(VLOOKUP($A30,'Round 2'!$A$7:$J$306,COLUMN('Round 1'!$H$7),FALSE),1,NA())),0,1),IF(ISNA(IF(VLOOKUP($A30,'Round 3'!$A$7:$J$306,COLUMN('Round 1'!$H$7),FALSE),1,NA())),0,1),IF(ISNA(IF(VLOOKUP($A30,'Final Round'!$A$14:$K$18,1,FALSE),1,NA())),0,1))) -> 3 | H30: =IF(ISBLANK($A30),"",IF(ISERROR(VLOOKUP($A30,'Round 1'!$A$7:$I$306,COLUMN('Round 1'!$G$7),FALSE)),0,VLOOKUP($A30,'Round 1'!$A$7:$I$306,COLUMN('Round 1'!$G$7),FALSE))+IF(ISERROR(VLOOKUP($A30,'Round 2'!$A$7:$I$306,COLUMN('Round 2'!$G$7),FALSE)),0,VLOOKUP($A30,'Round 2'!$A$7:$I$306,COLUMN('Round 2'!$G$7),FALSE))+IF(ISERROR(VLOOKUP($A30,'Round 3'!$A$7:$I$306,COLUMN('Round 3'!$G$7),FALSE)),0,VLOOKUP($A30,'Round 3'!$A$7:$I$306,COLUMN('Round 3'!$G$7),FALSE))) -> 0 | I30: =IF(ISBLANK($A30),"",IF(ISERROR(VLOOKUP($A30,'Round 1'!$A$7:$I$306,COLUMN('Round 1'!$F$7),FALSE)),0,VLOOKUP($A30,'Round 1'!$A$7:$I$306,COLUMN('Round 1'!$F$7),FALSE))+IF(ISERROR(VLOOKUP($A30,'Round 2'!$A$7:$I$306,COLUMN('Round 2'!$F$7),FALSE)),0,VLOOKUP($A30,'Round 2'!$A$7:$I$306,COLUMN('Round 2'!$F$7),FALSE))+IF(ISERROR(VLOOKUP($A30,'Round 3'!$A$7:$I$306,COLUMN('Round 3'!$F$7),FALSE)),0,VLOOKUP($A30,'Round 3'!$A$7:$I$306,COLUMN('Round 3'!$F$7),FALSE))) -> 1.5 | J30: =IF(ISBLANK($A30),"",IF(ISERROR(VLOOKUP($A30,'Round 1'!$A$7:$I$306,COLUMN('Round 1'!$H$7),FALSE)),0,VLOOKUP($A30,'Round 1'!$A$7:$I$306,COLUMN('Round 1'!$H$7),FALSE))+IF(ISERROR(VLOOKUP($A30,'Round 2'!$A$7:$I$306,COLUMN('Round 2'!$H$7),FALSE)),0,VLOOKUP($A30,'Round 2'!$A$7:$I$306,COLUMN('Round 2'!$H$7),FALSE))+IF(ISERROR(VLOOKUP($A30,'Round 3'!$A$7:$I$306,COLUMN('Round 3'!$H$7),FALSE)),0,VLOOKUP($A30,'Round 3'!$A$7:$I$306,COLUMN('Round 3'!$H$7),FALSE))) -> 112 | K30: =IF(ISBLANK(A30),"",RANK(P30,$P$7:$P$306)) -> 24 | L30: =IF(ISBLANK($G30),IF($K30>5,"",IF(AND(ISNA(MATCH(K30+1,$K$7:$K$306,0)),$K30<$A$4),"TIE","")),"DQ") | N30: =IF(ISBLANK($G30),$R30,"DQ") -> 24 | O30: =IF(ISBLANK(A30),"",$H30*$O$6+$I30) -> 1.5 | P30: =IF(ISBLANK(A30),"",$O30*10*$P$6+$J30) -> 2647 | Q30: =IF(ISBLANK($G30),IF(ISBLANK($A30),-10,$P30*$Q$6+IF($M30>0,$Q$6-1-$M30,0)),-1) -> 7941 | R30: =IF(ISBLANK($A30),"",RANK($Q30,$Q$7:$Q$306)) -> 24 | S30: =IF(ISNA(MATCH($R30+1,$R$7:$R$306,0)),IF($R30=MAX($A$7:$A$306),$R30,-1),$R30) -> -1 | T30: =$A30 -> 4 | U30: =IF(N('Final Round'!$J$14)>0,IF(ISBLANK($A30),"",IF($N30>5,$N30,VLOOKUP($A30,'Final Round'!$A$14:$K$18,COLUMN('Final Round'!$J$1),FALSE))),"") -> 24 | V30: =IF(ISNUMBER($U30),$U30,$R30) -> 24 | W30: =IF(ISBLANK($A30),"",($V$6-$V30)*$W$6+$W$6-$A30) -> 794 | X30: =IF(ISBLANK($A30),"",RANK($W30,$W$7:$W$306)) -> 24 | Y30: =$A30 -> 4 | Z30: =IF($U30="",$N30,$U30) -> 24 | AA30: =IF($U30<6,INDEX($AA$1:$AA$5,$Z30)*$Z$2,0) -> 0 | AB30: =IF(ISBLANK($A30),"",5+4*(I30+IF(AA30=0,0,VLOOKUP($A30,'Final Round'!$A$14:$K$18,COLUMN('Final Round'!$G$1),FALSE)))+8*(H30+IF(AA30=0,0,IF(VLOOKUP($A30,'Final Round'!$A$14:$K$18,COLUMN('Final Round'!$J$1),FALSE)=1,1,0)))+$AA30) -> 11
